2024-04-25 18:00:38,321 __main__ (lichess-bot.py:1051) INFO 
    .   _/|
    .  // o\
    .  || ._)  lichess-bot 2024.3.21.1
    .  //__\
    .  )___(   Play on Lichess with a bot
    
2024-04-25 18:00:38,349 lib.config (config.py:262) DEBUG Config:
token: logger
url: https://lichess.org/
engine:
  dir: ./engines/
  name: ExampleEngine
  working_dir: ''
  protocol: homemade
  ponder: true
  polyglot:
    enabled: false
    book:
      standard:
      - engines/book1.bin
      - engines/book2.bin
    min_weight: 1
    selection: weighted_random
    max_depth: 20
  draw_or_resign:
    resign_enabled: false
    resign_score: -1000
    resign_for_egtb_minus_two: true
    resign_moves: 3
    offer_draw_enabled: true
    offer_draw_score: 0
    offer_draw_for_egtb_zero: true
    offer_draw_moves: 10
    offer_draw_pieces: 10
  online_moves:
    max_out_of_book_moves: 10
    max_retries: 2
    chessdb_book:
      enabled: false
      min_time: 20
      move_quality: good
      min_depth: 20
    lichess_cloud_analysis:
      enabled: false
      min_time: 20
      move_quality: best
      max_score_difference: 50
      min_depth: 20
      min_knodes: 0
    lichess_opening_explorer:
      enabled: false
      min_time: 20
      source: masters
      player_name: ''
      sort: winrate
      min_games: 10
    online_egtb:
      enabled: false
      min_time: 20
      max_pieces: 7
      source: lichess
      move_quality: best
  lichess_bot_tbs:
    syzygy:
      enabled: false
      paths:
      - engines/syzygy
      max_pieces: 7
      move_quality: best
    gaviota:
      enabled: false
      paths:
      - engines/gaviota
      max_pieces: 5
      min_dtm_to_consider_as_wdl_1: 120
      move_quality: best
  homemade_options: null
  uci_options:
    Move Overhead: 100
    Threads: 4
    Hash: 512
    SyzygyPath: ./syzygy/
    UCI_ShowWDL: true
  silence_stderr: false
abort_time: 30
fake_think_time: false
rate_limiting_delay: 0
move_overhead: 2000
quit_after_all_games_finish: false
correspondence:
  move_time: 60
  checkin_period: 300
  disconnect_time: 150
  ponder: false
challenge:
  concurrency: 5
  sort_by: first
  accept_bot: true
  only_bot: false
  max_increment: 20
  min_increment: 0
  max_base: 1800
  min_base: 0
  max_days: 14
  min_days: 1
  variants:
  - standard
  time_controls:
  - bullet
  - blitz
  - rapid
  - classical
  modes:
  - casual
  - rated
  bullet_requires_increment: false
greeting:
  hello: Hi! I'm Kyle's Chess AI. Good luck!
  goodbye: Good game, thanks for playing! If you haven't read the paper yet, please
    consider giving it a read.
  hello_spectators: Hi! I'm {me}. Type !help for a list of commands I can respond
    to.
  goodbye_spectators: Thanks for watching!
matchmaking:
  allow_matchmaking: false
  allow_during_games: false
  challenge_variant: random
  challenge_timeout: 30
  challenge_initial_time:
  - 60
  - 180
  challenge_increment:
  - 1
  - 2
  rating_preference: none
  opponent_allow_tos_violation: false
  challenge_mode: random
  challenge_filter: none

2024-04-25 18:00:38,351 lib.config (config.py:263) DEBUG ====================
2024-04-25 18:00:38,353 lib.config (config.py:262) DEBUG Config:
token: logger
url: https://lichess.org/
engine:
  dir: ./engines/
  name: ExampleEngine
  working_dir: C:\Users\Kyle_Remote\Documents\Programs\DS3ML3_Final_Project\lichess-bot
  protocol: homemade
  ponder: true
  polyglot:
    enabled: false
    book:
      standard:
      - engines/book1.bin
      - engines/book2.bin
    min_weight: 1
    selection: weighted_random
    max_depth: 20
  draw_or_resign:
    resign_enabled: false
    resign_score: -1000
    resign_for_egtb_minus_two: true
    resign_moves: 3
    offer_draw_enabled: true
    offer_draw_score: 0
    offer_draw_for_egtb_zero: true
    offer_draw_moves: 10
    offer_draw_pieces: 10
  online_moves:
    max_out_of_book_moves: 10
    max_retries: 2
    chessdb_book:
      enabled: false
      min_time: 20
      move_quality: good
      min_depth: 20
    lichess_cloud_analysis:
      enabled: false
      min_time: 20
      move_quality: best
      max_score_difference: 50
      min_depth: 20
      min_knodes: 0
    lichess_opening_explorer:
      enabled: false
      min_time: 20
      source: masters
      player_name: ''
      sort: winrate
      min_games: 10
    online_egtb:
      enabled: false
      min_time: 20
      max_pieces: 7
      source: lichess
      move_quality: best
    max_depth: .inf
  lichess_bot_tbs:
    syzygy:
      enabled: false
      paths:
      - engines/syzygy
      max_pieces: 7
      move_quality: best
    gaviota:
      enabled: false
      paths:
      - engines/gaviota
      max_pieces: 5
      min_dtm_to_consider_as_wdl_1: 120
      move_quality: best
  homemade_options: null
  uci_options:
    Move Overhead: 100
    Threads: 4
    Hash: 512
    SyzygyPath: ./syzygy/
    UCI_ShowWDL: true
  silence_stderr: false
  uci_ponder: false
abort_time: 30
fake_think_time: false
rate_limiting_delay: 0
move_overhead: 2000
quit_after_all_games_finish: false
correspondence:
  move_time: 60
  checkin_period: 300
  disconnect_time: 150
  ponder: false
  uci_ponder: false
challenge:
  concurrency: 5
  sort_by: first
  accept_bot: true
  only_bot: false
  max_increment: 20
  min_increment: 0
  max_base: 1800
  min_base: 0
  max_days: 14
  min_days: 1
  variants:
  - standard
  time_controls:
  - bullet
  - blitz
  - rapid
  - classical
  modes:
  - casual
  - rated
  bullet_requires_increment: false
  block_list: []
  allow_list: []
greeting:
  hello: Hi! I'm Kyle's Chess AI. Good luck!
  goodbye: Good game, thanks for playing! If you haven't read the paper yet, please
    consider giving it a read.
  hello_spectators: Hi! I'm {me}. Type !help for a list of commands I can respond
    to.
  goodbye_spectators: Thanks for watching!
matchmaking:
  allow_matchmaking: false
  allow_during_games: false
  challenge_variant: random
  challenge_timeout: 30
  challenge_initial_time:
  - 60
  - 180
  challenge_increment:
  - 1
  - 2
  rating_preference: none
  opponent_allow_tos_violation: false
  challenge_mode: random
  challenge_filter: none
  block_list: []
  challenge_days:
  - null
  opponent_min_rating: 600
  opponent_max_rating: 4000
  overrides: {}
pgn_file_grouping: game

2024-04-25 18:00:38,353 lib.config (config.py:263) DEBUG ====================
2024-04-25 18:00:38,354 __main__ (lichess-bot.py:1054) INFO Checking engine configuration ...
2024-04-25 18:00:38,357 lib.engine_wrapper (engine_wrapper.py:68) DEBUG Starting engine: ['C:\\Users\\Kyle_Remote\\Documents\\Programs\\DS3ML3_Final_Project\\lichess-bot\\engines\\ExampleEngine']
2024-04-25 18:00:38,357 __main__ (lichess-bot.py:1057) INFO Engine configuration OK
2024-04-25 18:00:38,360 urllib3.connectionpool (connectionpool.py:1055) DEBUG Starting new HTTPS connection (1): lichess.org:443
2024-04-25 18:00:38,666 lib.lichess (lichess.py:63) DEBUG Backing off 0.1 seconds after 1 tries calling function <function Lichess.api_post at 0x000001E0C5D53BA0> with args (<lib.lichess.Lichess object at 0x000001E0E7F33B50>, 'token_test') and kwargs {'data': 'lip_r4E9TokqtbYPQx8ElZQ4'}
2024-04-25 18:00:38,678 lib.lichess (lichess.py:65) DEBUG Exception: Traceback (most recent call last):
  File "C:\Users\Kyle_Remote\Documents\Programs\DS3ML3_Final_Project\.venv\Lib\site-packages\urllib3\connectionpool.py", line 793, in urlopen
    response = self._make_request(
               ^^^^^^^^^^^^^^^^^^^
  File "C:\Users\Kyle_Remote\Documents\Programs\DS3ML3_Final_Project\.venv\Lib\site-packages\urllib3\connectionpool.py", line 491, in _make_request
    raise new_e
  File "C:\Users\Kyle_Remote\Documents\Programs\DS3ML3_Final_Project\.venv\Lib\site-packages\urllib3\connectionpool.py", line 467, in _make_request
    self._validate_conn(conn)
  File "C:\Users\Kyle_Remote\Documents\Programs\DS3ML3_Final_Project\.venv\Lib\site-packages\urllib3\connectionpool.py", line 1099, in _validate_conn
    conn.connect()
  File "C:\Users\Kyle_Remote\Documents\Programs\DS3ML3_Final_Project\.venv\Lib\site-packages\urllib3\connection.py", line 653, in connect
    sock_and_verified = _ssl_wrap_socket_and_match_hostname(
                        ^^^^^^^^^^^^^^^^^^^^^^^^^^^^^^^^^^^^
  File "C:\Users\Kyle_Remote\Documents\Programs\DS3ML3_Final_Project\.venv\Lib\site-packages\urllib3\connection.py", line 806, in _ssl_wrap_socket_and_match_hostname
    ssl_sock = ssl_wrap_socket(
               ^^^^^^^^^^^^^^^^
  File "C:\Users\Kyle_Remote\Documents\Programs\DS3ML3_Final_Project\.venv\Lib\site-packages\urllib3\util\ssl_.py", line 465, in ssl_wrap_socket
    ssl_sock = _ssl_wrap_socket_impl(sock, context, tls_in_tls, server_hostname)
               ^^^^^^^^^^^^^^^^^^^^^^^^^^^^^^^^^^^^^^^^^^^^^^^^^^^^^^^^^^^^^^^^^
  File "C:\Users\Kyle_Remote\Documents\Programs\DS3ML3_Final_Project\.venv\Lib\site-packages\urllib3\util\ssl_.py", line 509, in _ssl_wrap_socket_impl
    return ssl_context.wrap_socket(sock, server_hostname=server_hostname)
           ^^^^^^^^^^^^^^^^^^^^^^^^^^^^^^^^^^^^^^^^^^^^^^^^^^^^^^^^^^^^^^
  File "C:\Users\Kyle_Remote\AppData\Local\Programs\Python\Python311\Lib\ssl.py", line 517, in wrap_socket
    return self.sslsocket_class._create(
           ^^^^^^^^^^^^^^^^^^^^^^^^^^^^^
  File "C:\Users\Kyle_Remote\AppData\Local\Programs\Python\Python311\Lib\ssl.py", line 1108, in _create
    self.do_handshake()
  File "C:\Users\Kyle_Remote\AppData\Local\Programs\Python\Python311\Lib\ssl.py", line 1379, in do_handshake
    self._sslobj.do_handshake()
ConnectionResetError: [WinError 10054] An existing connection was forcibly closed by the remote host

During handling of the above exception, another exception occurred:

Traceback (most recent call last):
  File "C:\Users\Kyle_Remote\Documents\Programs\DS3ML3_Final_Project\.venv\Lib\site-packages\requests\adapters.py", line 486, in send
    resp = conn.urlopen(
           ^^^^^^^^^^^^^
  File "C:\Users\Kyle_Remote\Documents\Programs\DS3ML3_Final_Project\.venv\Lib\site-packages\urllib3\connectionpool.py", line 847, in urlopen
    retries = retries.increment(
              ^^^^^^^^^^^^^^^^^^
  File "C:\Users\Kyle_Remote\Documents\Programs\DS3ML3_Final_Project\.venv\Lib\site-packages\urllib3\util\retry.py", line 470, in increment
    raise reraise(type(error), error, _stacktrace)
          ^^^^^^^^^^^^^^^^^^^^^^^^^^^^^^^^^^^^^^^^
  File "C:\Users\Kyle_Remote\Documents\Programs\DS3ML3_Final_Project\.venv\Lib\site-packages\urllib3\util\util.py", line 38, in reraise
    raise value.with_traceback(tb)
  File "C:\Users\Kyle_Remote\Documents\Programs\DS3ML3_Final_Project\.venv\Lib\site-packages\urllib3\connectionpool.py", line 793, in urlopen
    response = self._make_request(
               ^^^^^^^^^^^^^^^^^^^
  File "C:\Users\Kyle_Remote\Documents\Programs\DS3ML3_Final_Project\.venv\Lib\site-packages\urllib3\connectionpool.py", line 491, in _make_request
    raise new_e
  File "C:\Users\Kyle_Remote\Documents\Programs\DS3ML3_Final_Project\.venv\Lib\site-packages\urllib3\connectionpool.py", line 467, in _make_request
    self._validate_conn(conn)
  File "C:\Users\Kyle_Remote\Documents\Programs\DS3ML3_Final_Project\.venv\Lib\site-packages\urllib3\connectionpool.py", line 1099, in _validate_conn
    conn.connect()
  File "C:\Users\Kyle_Remote\Documents\Programs\DS3ML3_Final_Project\.venv\Lib\site-packages\urllib3\connection.py", line 653, in connect
    sock_and_verified = _ssl_wrap_socket_and_match_hostname(
                        ^^^^^^^^^^^^^^^^^^^^^^^^^^^^^^^^^^^^
  File "C:\Users\Kyle_Remote\Documents\Programs\DS3ML3_Final_Project\.venv\Lib\site-packages\urllib3\connection.py", line 806, in _ssl_wrap_socket_and_match_hostname
    ssl_sock = ssl_wrap_socket(
               ^^^^^^^^^^^^^^^^
  File "C:\Users\Kyle_Remote\Documents\Programs\DS3ML3_Final_Project\.venv\Lib\site-packages\urllib3\util\ssl_.py", line 465, in ssl_wrap_socket
    ssl_sock = _ssl_wrap_socket_impl(sock, context, tls_in_tls, server_hostname)
               ^^^^^^^^^^^^^^^^^^^^^^^^^^^^^^^^^^^^^^^^^^^^^^^^^^^^^^^^^^^^^^^^^
  File "C:\Users\Kyle_Remote\Documents\Programs\DS3ML3_Final_Project\.venv\Lib\site-packages\urllib3\util\ssl_.py", line 509, in _ssl_wrap_socket_impl
    return ssl_context.wrap_socket(sock, server_hostname=server_hostname)
           ^^^^^^^^^^^^^^^^^^^^^^^^^^^^^^^^^^^^^^^^^^^^^^^^^^^^^^^^^^^^^^
  File "C:\Users\Kyle_Remote\AppData\Local\Programs\Python\Python311\Lib\ssl.py", line 517, in wrap_socket
    return self.sslsocket_class._create(
           ^^^^^^^^^^^^^^^^^^^^^^^^^^^^^
  File "C:\Users\Kyle_Remote\AppData\Local\Programs\Python\Python311\Lib\ssl.py", line 1108, in _create
    self.do_handshake()
  File "C:\Users\Kyle_Remote\AppData\Local\Programs\Python\Python311\Lib\ssl.py", line 1379, in do_handshake
    self._sslobj.do_handshake()
urllib3.exceptions.ProtocolError: ('Connection aborted.', ConnectionResetError(10054, 'An existing connection was forcibly closed by the remote host', None, 10054, None))

During handling of the above exception, another exception occurred:

Traceback (most recent call last):
  File "C:\Users\Kyle_Remote\Documents\Programs\DS3ML3_Final_Project\.venv\Lib\site-packages\backoff\_sync.py", line 105, in retry
    ret = target(*args, **kwargs)
          ^^^^^^^^^^^^^^^^^^^^^^^
  File "C:\Users\Kyle_Remote\Documents\Programs\DS3ML3_Final_Project\lichess-bot\lib\lichess.py", line 214, in api_post
    response = self.session.post(url, data=data, headers=headers, params=params, json=payload, timeout=2)
               ^^^^^^^^^^^^^^^^^^^^^^^^^^^^^^^^^^^^^^^^^^^^^^^^^^^^^^^^^^^^^^^^^^^^^^^^^^^^^^^^^^^^^^^^^^
  File "C:\Users\Kyle_Remote\Documents\Programs\DS3ML3_Final_Project\.venv\Lib\site-packages\requests\sessions.py", line 637, in post
    return self.request("POST", url, data=data, json=json, **kwargs)
           ^^^^^^^^^^^^^^^^^^^^^^^^^^^^^^^^^^^^^^^^^^^^^^^^^^^^^^^^^
  File "C:\Users\Kyle_Remote\Documents\Programs\DS3ML3_Final_Project\.venv\Lib\site-packages\requests\sessions.py", line 589, in request
    resp = self.send(prep, **send_kwargs)
           ^^^^^^^^^^^^^^^^^^^^^^^^^^^^^^
  File "C:\Users\Kyle_Remote\Documents\Programs\DS3ML3_Final_Project\.venv\Lib\site-packages\requests\sessions.py", line 703, in send
    r = adapter.send(request, **kwargs)
        ^^^^^^^^^^^^^^^^^^^^^^^^^^^^^^^
  File "C:\Users\Kyle_Remote\Documents\Programs\DS3ML3_Final_Project\.venv\Lib\site-packages\requests\adapters.py", line 501, in send
    raise ConnectionError(err, request=request)
requests.exceptions.ConnectionError: ('Connection aborted.', ConnectionResetError(10054, 'An existing connection was forcibly closed by the remote host', None, 10054, None))

2024-04-25 18:00:38,765 urllib3.connectionpool (connectionpool.py:1055) DEBUG Starting new HTTPS connection (2): lichess.org:443
2024-04-25 18:00:39,013 lib.lichess (lichess.py:63) DEBUG Backing off 0.1 seconds after 2 tries calling function <function Lichess.api_post at 0x000001E0C5D53BA0> with args (<lib.lichess.Lichess object at 0x000001E0E7F33B50>, 'token_test') and kwargs {'data': 'lip_r4E9TokqtbYPQx8ElZQ4'}
2024-04-25 18:00:39,015 lib.lichess (lichess.py:65) DEBUG Exception: Traceback (most recent call last):
  File "C:\Users\Kyle_Remote\Documents\Programs\DS3ML3_Final_Project\.venv\Lib\site-packages\urllib3\connectionpool.py", line 793, in urlopen
    response = self._make_request(
               ^^^^^^^^^^^^^^^^^^^
  File "C:\Users\Kyle_Remote\Documents\Programs\DS3ML3_Final_Project\.venv\Lib\site-packages\urllib3\connectionpool.py", line 491, in _make_request
    raise new_e
  File "C:\Users\Kyle_Remote\Documents\Programs\DS3ML3_Final_Project\.venv\Lib\site-packages\urllib3\connectionpool.py", line 467, in _make_request
    self._validate_conn(conn)
  File "C:\Users\Kyle_Remote\Documents\Programs\DS3ML3_Final_Project\.venv\Lib\site-packages\urllib3\connectionpool.py", line 1099, in _validate_conn
    conn.connect()
  File "C:\Users\Kyle_Remote\Documents\Programs\DS3ML3_Final_Project\.venv\Lib\site-packages\urllib3\connection.py", line 653, in connect
    sock_and_verified = _ssl_wrap_socket_and_match_hostname(
                        ^^^^^^^^^^^^^^^^^^^^^^^^^^^^^^^^^^^^
  File "C:\Users\Kyle_Remote\Documents\Programs\DS3ML3_Final_Project\.venv\Lib\site-packages\urllib3\connection.py", line 806, in _ssl_wrap_socket_and_match_hostname
    ssl_sock = ssl_wrap_socket(
               ^^^^^^^^^^^^^^^^
  File "C:\Users\Kyle_Remote\Documents\Programs\DS3ML3_Final_Project\.venv\Lib\site-packages\urllib3\util\ssl_.py", line 465, in ssl_wrap_socket
    ssl_sock = _ssl_wrap_socket_impl(sock, context, tls_in_tls, server_hostname)
               ^^^^^^^^^^^^^^^^^^^^^^^^^^^^^^^^^^^^^^^^^^^^^^^^^^^^^^^^^^^^^^^^^
  File "C:\Users\Kyle_Remote\Documents\Programs\DS3ML3_Final_Project\.venv\Lib\site-packages\urllib3\util\ssl_.py", line 509, in _ssl_wrap_socket_impl
    return ssl_context.wrap_socket(sock, server_hostname=server_hostname)
           ^^^^^^^^^^^^^^^^^^^^^^^^^^^^^^^^^^^^^^^^^^^^^^^^^^^^^^^^^^^^^^
  File "C:\Users\Kyle_Remote\AppData\Local\Programs\Python\Python311\Lib\ssl.py", line 517, in wrap_socket
    return self.sslsocket_class._create(
           ^^^^^^^^^^^^^^^^^^^^^^^^^^^^^
  File "C:\Users\Kyle_Remote\AppData\Local\Programs\Python\Python311\Lib\ssl.py", line 1108, in _create
    self.do_handshake()
  File "C:\Users\Kyle_Remote\AppData\Local\Programs\Python\Python311\Lib\ssl.py", line 1379, in do_handshake
    self._sslobj.do_handshake()
ConnectionResetError: [WinError 10054] An existing connection was forcibly closed by the remote host

During handling of the above exception, another exception occurred:

Traceback (most recent call last):
  File "C:\Users\Kyle_Remote\Documents\Programs\DS3ML3_Final_Project\.venv\Lib\site-packages\requests\adapters.py", line 486, in send
    resp = conn.urlopen(
           ^^^^^^^^^^^^^
  File "C:\Users\Kyle_Remote\Documents\Programs\DS3ML3_Final_Project\.venv\Lib\site-packages\urllib3\connectionpool.py", line 847, in urlopen
    retries = retries.increment(
              ^^^^^^^^^^^^^^^^^^
  File "C:\Users\Kyle_Remote\Documents\Programs\DS3ML3_Final_Project\.venv\Lib\site-packages\urllib3\util\retry.py", line 470, in increment
    raise reraise(type(error), error, _stacktrace)
          ^^^^^^^^^^^^^^^^^^^^^^^^^^^^^^^^^^^^^^^^
  File "C:\Users\Kyle_Remote\Documents\Programs\DS3ML3_Final_Project\.venv\Lib\site-packages\urllib3\util\util.py", line 38, in reraise
    raise value.with_traceback(tb)
  File "C:\Users\Kyle_Remote\Documents\Programs\DS3ML3_Final_Project\.venv\Lib\site-packages\urllib3\connectionpool.py", line 793, in urlopen
    response = self._make_request(
               ^^^^^^^^^^^^^^^^^^^
  File "C:\Users\Kyle_Remote\Documents\Programs\DS3ML3_Final_Project\.venv\Lib\site-packages\urllib3\connectionpool.py", line 491, in _make_request
    raise new_e
  File "C:\Users\Kyle_Remote\Documents\Programs\DS3ML3_Final_Project\.venv\Lib\site-packages\urllib3\connectionpool.py", line 467, in _make_request
    self._validate_conn(conn)
  File "C:\Users\Kyle_Remote\Documents\Programs\DS3ML3_Final_Project\.venv\Lib\site-packages\urllib3\connectionpool.py", line 1099, in _validate_conn
    conn.connect()
  File "C:\Users\Kyle_Remote\Documents\Programs\DS3ML3_Final_Project\.venv\Lib\site-packages\urllib3\connection.py", line 653, in connect
    sock_and_verified = _ssl_wrap_socket_and_match_hostname(
                        ^^^^^^^^^^^^^^^^^^^^^^^^^^^^^^^^^^^^
  File "C:\Users\Kyle_Remote\Documents\Programs\DS3ML3_Final_Project\.venv\Lib\site-packages\urllib3\connection.py", line 806, in _ssl_wrap_socket_and_match_hostname
    ssl_sock = ssl_wrap_socket(
               ^^^^^^^^^^^^^^^^
  File "C:\Users\Kyle_Remote\Documents\Programs\DS3ML3_Final_Project\.venv\Lib\site-packages\urllib3\util\ssl_.py", line 465, in ssl_wrap_socket
    ssl_sock = _ssl_wrap_socket_impl(sock, context, tls_in_tls, server_hostname)
               ^^^^^^^^^^^^^^^^^^^^^^^^^^^^^^^^^^^^^^^^^^^^^^^^^^^^^^^^^^^^^^^^^
  File "C:\Users\Kyle_Remote\Documents\Programs\DS3ML3_Final_Project\.venv\Lib\site-packages\urllib3\util\ssl_.py", line 509, in _ssl_wrap_socket_impl
    return ssl_context.wrap_socket(sock, server_hostname=server_hostname)
           ^^^^^^^^^^^^^^^^^^^^^^^^^^^^^^^^^^^^^^^^^^^^^^^^^^^^^^^^^^^^^^
  File "C:\Users\Kyle_Remote\AppData\Local\Programs\Python\Python311\Lib\ssl.py", line 517, in wrap_socket
    return self.sslsocket_class._create(
           ^^^^^^^^^^^^^^^^^^^^^^^^^^^^^
  File "C:\Users\Kyle_Remote\AppData\Local\Programs\Python\Python311\Lib\ssl.py", line 1108, in _create
    self.do_handshake()
  File "C:\Users\Kyle_Remote\AppData\Local\Programs\Python\Python311\Lib\ssl.py", line 1379, in do_handshake
    self._sslobj.do_handshake()
urllib3.exceptions.ProtocolError: ('Connection aborted.', ConnectionResetError(10054, 'An existing connection was forcibly closed by the remote host', None, 10054, None))

During handling of the above exception, another exception occurred:

Traceback (most recent call last):
  File "C:\Users\Kyle_Remote\Documents\Programs\DS3ML3_Final_Project\.venv\Lib\site-packages\backoff\_sync.py", line 105, in retry
    ret = target(*args, **kwargs)
          ^^^^^^^^^^^^^^^^^^^^^^^
  File "C:\Users\Kyle_Remote\Documents\Programs\DS3ML3_Final_Project\lichess-bot\lib\lichess.py", line 214, in api_post
    response = self.session.post(url, data=data, headers=headers, params=params, json=payload, timeout=2)
               ^^^^^^^^^^^^^^^^^^^^^^^^^^^^^^^^^^^^^^^^^^^^^^^^^^^^^^^^^^^^^^^^^^^^^^^^^^^^^^^^^^^^^^^^^^
  File "C:\Users\Kyle_Remote\Documents\Programs\DS3ML3_Final_Project\.venv\Lib\site-packages\requests\sessions.py", line 637, in post
    return self.request("POST", url, data=data, json=json, **kwargs)
           ^^^^^^^^^^^^^^^^^^^^^^^^^^^^^^^^^^^^^^^^^^^^^^^^^^^^^^^^^
  File "C:\Users\Kyle_Remote\Documents\Programs\DS3ML3_Final_Project\.venv\Lib\site-packages\requests\sessions.py", line 589, in request
    resp = self.send(prep, **send_kwargs)
           ^^^^^^^^^^^^^^^^^^^^^^^^^^^^^^
  File "C:\Users\Kyle_Remote\Documents\Programs\DS3ML3_Final_Project\.venv\Lib\site-packages\requests\sessions.py", line 703, in send
    r = adapter.send(request, **kwargs)
        ^^^^^^^^^^^^^^^^^^^^^^^^^^^^^^^
  File "C:\Users\Kyle_Remote\Documents\Programs\DS3ML3_Final_Project\.venv\Lib\site-packages\requests\adapters.py", line 501, in send
    raise ConnectionError(err, request=request)
requests.exceptions.ConnectionError: ('Connection aborted.', ConnectionResetError(10054, 'An existing connection was forcibly closed by the remote host', None, 10054, None))

2024-04-25 18:00:39,080 urllib3.connectionpool (connectionpool.py:1055) DEBUG Starting new HTTPS connection (3): lichess.org:443
2024-04-25 18:00:39,632 urllib3.connectionpool (connectionpool.py:549) DEBUG https://lichess.org:443 "POST /api/token/test HTTP/1.1" 200 None
2024-04-25 18:00:39,741 urllib3.connectionpool (connectionpool.py:549) DEBUG https://lichess.org:443 "GET /api/account HTTP/1.1" 200 None
2024-04-25 18:00:39,742 __main__ (lichess-bot.py:1066) INFO Welcome KS_ChessAI!
2024-04-25 18:00:39,747 __main__ (lichess-bot.py:225) INFO You're now connected to https://lichess.org/ and awaiting challenges.
2024-04-25 18:00:40,572 urllib3.connectionpool (connectionpool.py:549) DEBUG https://lichess.org:443 "GET /api/account/playing HTTP/1.1" 200 17
2024-04-25 18:05:41,004 __main__ (lichess-bot.py:404) DEBUG Event: {'type': 'correspondence_ping'}
2024-04-25 18:10:41,005 __main__ (lichess-bot.py:404) DEBUG Event: {'type': 'correspondence_ping'}
2024-04-25 18:15:41,005 __main__ (lichess-bot.py:404) DEBUG Event: {'type': 'correspondence_ping'}
2024-04-25 18:20:41,005 __main__ (lichess-bot.py:404) DEBUG Event: {'type': 'correspondence_ping'}
2024-04-25 18:25:41,006 __main__ (lichess-bot.py:404) DEBUG Event: {'type': 'correspondence_ping'}
2024-04-25 18:30:41,006 __main__ (lichess-bot.py:404) DEBUG Event: {'type': 'correspondence_ping'}
2024-04-25 18:35:41,006 __main__ (lichess-bot.py:404) DEBUG Event: {'type': 'correspondence_ping'}
2024-04-25 18:40:41,007 __main__ (lichess-bot.py:404) DEBUG Event: {'type': 'correspondence_ping'}
2024-04-25 18:45:41,008 __main__ (lichess-bot.py:404) DEBUG Event: {'type': 'correspondence_ping'}
2024-04-25 18:50:41,007 __main__ (lichess-bot.py:404) DEBUG Event: {'type': 'correspondence_ping'}
2024-04-25 18:55:41,008 __main__ (lichess-bot.py:404) DEBUG Event: {'type': 'correspondence_ping'}
2024-04-25 19:00:41,010 __main__ (lichess-bot.py:404) DEBUG Event: {'type': 'correspondence_ping'}
2024-04-25 19:00:41,014 urllib3.connectionpool (connectionpool.py:292) DEBUG Resetting dropped connection: lichess.org
2024-04-25 19:00:41,636 urllib3.connectionpool (connectionpool.py:549) DEBUG https://lichess.org:443 "GET /api/users/status?ids=ks_chessai HTTP/1.1" 200 None
2024-04-25 19:05:41,010 __main__ (lichess-bot.py:404) DEBUG Event: {'type': 'correspondence_ping'}
2024-04-25 19:10:41,011 __main__ (lichess-bot.py:404) DEBUG Event: {'type': 'correspondence_ping'}
2024-04-25 19:15:41,011 __main__ (lichess-bot.py:404) DEBUG Event: {'type': 'correspondence_ping'}
2024-04-25 19:20:41,011 __main__ (lichess-bot.py:404) DEBUG Event: {'type': 'correspondence_ping'}
2024-04-25 19:25:41,013 __main__ (lichess-bot.py:404) DEBUG Event: {'type': 'correspondence_ping'}
2024-04-25 19:30:41,012 __main__ (lichess-bot.py:404) DEBUG Event: {'type': 'correspondence_ping'}
2024-04-25 19:35:41,013 __main__ (lichess-bot.py:404) DEBUG Event: {'type': 'correspondence_ping'}
2024-04-25 19:40:41,014 __main__ (lichess-bot.py:404) DEBUG Event: {'type': 'correspondence_ping'}
2024-04-25 19:45:41,014 __main__ (lichess-bot.py:404) DEBUG Event: {'type': 'correspondence_ping'}
2024-04-25 19:50:41,014 __main__ (lichess-bot.py:404) DEBUG Event: {'type': 'correspondence_ping'}
2024-04-25 19:55:41,015 __main__ (lichess-bot.py:404) DEBUG Event: {'type': 'correspondence_ping'}
2024-04-25 20:00:41,015 __main__ (lichess-bot.py:404) DEBUG Event: {'type': 'correspondence_ping'}
2024-04-25 20:00:44,100 urllib3.connectionpool (connectionpool.py:292) DEBUG Resetting dropped connection: lichess.org
2024-04-25 20:00:44,709 urllib3.connectionpool (connectionpool.py:549) DEBUG https://lichess.org:443 "GET /api/users/status?ids=ks_chessai HTTP/1.1" 200 None
2024-04-25 20:05:41,015 __main__ (lichess-bot.py:404) DEBUG Event: {'type': 'correspondence_ping'}
2024-04-25 20:10:41,015 __main__ (lichess-bot.py:404) DEBUG Event: {'type': 'correspondence_ping'}
2024-04-25 20:15:41,016 __main__ (lichess-bot.py:404) DEBUG Event: {'type': 'correspondence_ping'}
2024-04-25 20:20:41,015 __main__ (lichess-bot.py:404) DEBUG Event: {'type': 'correspondence_ping'}
2024-04-25 20:25:41,015 __main__ (lichess-bot.py:404) DEBUG Event: {'type': 'correspondence_ping'}
2024-04-25 20:30:41,016 __main__ (lichess-bot.py:404) DEBUG Event: {'type': 'correspondence_ping'}
2024-04-25 20:35:41,016 __main__ (lichess-bot.py:404) DEBUG Event: {'type': 'correspondence_ping'}
2024-04-25 20:40:41,016 __main__ (lichess-bot.py:404) DEBUG Event: {'type': 'correspondence_ping'}
2024-04-25 20:45:41,017 __main__ (lichess-bot.py:404) DEBUG Event: {'type': 'correspondence_ping'}
2024-04-25 20:50:41,017 __main__ (lichess-bot.py:404) DEBUG Event: {'type': 'correspondence_ping'}
2024-04-25 20:55:41,017 __main__ (lichess-bot.py:404) DEBUG Event: {'type': 'correspondence_ping'}
2024-04-25 21:00:41,017 __main__ (lichess-bot.py:404) DEBUG Event: {'type': 'correspondence_ping'}
2024-04-25 21:00:49,056 urllib3.connectionpool (connectionpool.py:292) DEBUG Resetting dropped connection: lichess.org
2024-04-25 21:00:49,669 urllib3.connectionpool (connectionpool.py:549) DEBUG https://lichess.org:443 "GET /api/users/status?ids=ks_chessai HTTP/1.1" 200 None
2024-04-25 21:05:41,017 __main__ (lichess-bot.py:404) DEBUG Event: {'type': 'correspondence_ping'}
2024-04-25 21:10:41,017 __main__ (lichess-bot.py:404) DEBUG Event: {'type': 'correspondence_ping'}
2024-04-25 21:15:41,017 __main__ (lichess-bot.py:404) DEBUG Event: {'type': 'correspondence_ping'}
2024-04-25 21:20:41,017 __main__ (lichess-bot.py:404) DEBUG Event: {'type': 'correspondence_ping'}
2024-04-25 21:25:41,018 __main__ (lichess-bot.py:404) DEBUG Event: {'type': 'correspondence_ping'}
2024-04-25 21:30:41,018 __main__ (lichess-bot.py:404) DEBUG Event: {'type': 'correspondence_ping'}
2024-04-25 21:35:41,018 __main__ (lichess-bot.py:404) DEBUG Event: {'type': 'correspondence_ping'}
2024-04-25 21:40:41,018 __main__ (lichess-bot.py:404) DEBUG Event: {'type': 'correspondence_ping'}
2024-04-25 21:45:41,018 __main__ (lichess-bot.py:404) DEBUG Event: {'type': 'correspondence_ping'}
2024-04-25 21:50:41,019 __main__ (lichess-bot.py:404) DEBUG Event: {'type': 'correspondence_ping'}
2024-04-25 21:55:41,018 __main__ (lichess-bot.py:404) DEBUG Event: {'type': 'correspondence_ping'}
2024-04-25 22:00:41,019 __main__ (lichess-bot.py:404) DEBUG Event: {'type': 'correspondence_ping'}
2024-04-25 22:00:54,008 urllib3.connectionpool (connectionpool.py:292) DEBUG Resetting dropped connection: lichess.org
2024-04-25 22:00:54,610 urllib3.connectionpool (connectionpool.py:549) DEBUG https://lichess.org:443 "GET /api/users/status?ids=ks_chessai HTTP/1.1" 200 None
2024-04-25 22:05:41,019 __main__ (lichess-bot.py:404) DEBUG Event: {'type': 'correspondence_ping'}
2024-04-25 22:10:41,019 __main__ (lichess-bot.py:404) DEBUG Event: {'type': 'correspondence_ping'}
2024-04-25 22:15:41,020 __main__ (lichess-bot.py:404) DEBUG Event: {'type': 'correspondence_ping'}
2024-04-25 22:20:41,021 __main__ (lichess-bot.py:404) DEBUG Event: {'type': 'correspondence_ping'}
2024-04-25 22:25:41,022 __main__ (lichess-bot.py:404) DEBUG Event: {'type': 'correspondence_ping'}
2024-04-25 22:30:41,024 __main__ (lichess-bot.py:404) DEBUG Event: {'type': 'correspondence_ping'}
2024-04-25 22:35:41,025 __main__ (lichess-bot.py:404) DEBUG Event: {'type': 'correspondence_ping'}
2024-04-25 22:40:41,026 __main__ (lichess-bot.py:404) DEBUG Event: {'type': 'correspondence_ping'}
2024-04-25 22:45:41,027 __main__ (lichess-bot.py:404) DEBUG Event: {'type': 'correspondence_ping'}
2024-04-25 22:50:41,030 __main__ (lichess-bot.py:404) DEBUG Event: {'type': 'correspondence_ping'}
2024-04-25 22:55:41,030 __main__ (lichess-bot.py:404) DEBUG Event: {'type': 'correspondence_ping'}
2024-04-25 23:00:41,031 __main__ (lichess-bot.py:404) DEBUG Event: {'type': 'correspondence_ping'}
2024-04-25 23:00:58,835 urllib3.connectionpool (connectionpool.py:292) DEBUG Resetting dropped connection: lichess.org
2024-04-25 23:00:59,371 urllib3.connectionpool (connectionpool.py:549) DEBUG https://lichess.org:443 "GET /api/users/status?ids=ks_chessai HTTP/1.1" 200 None
2024-04-25 23:05:41,033 __main__ (lichess-bot.py:404) DEBUG Event: {'type': 'correspondence_ping'}
2024-04-25 23:10:41,034 __main__ (lichess-bot.py:404) DEBUG Event: {'type': 'correspondence_ping'}
2024-04-25 23:15:41,034 __main__ (lichess-bot.py:404) DEBUG Event: {'type': 'correspondence_ping'}
2024-04-25 23:17:16,839 __main__ (lichess-bot.py:404) DEBUG Event: {'type': 'terminated', 'error': 'Traceback (most recent call last):\n  File "C:\\Users\\Kyle_Remote\\Documents\\Programs\\DS3ML3_Final_Project\\.venv\\Lib\\site-packages\\urllib3\\response.py", line 737, in _error_catcher\n    yield\n  File "C:\\Users\\Kyle_Remote\\Documents\\Programs\\DS3ML3_Final_Project\\.venv\\Lib\\site-packages\\urllib3\\response.py", line 1184, in read_chunked\n    self._update_chunk_length()\n  File "C:\\Users\\Kyle_Remote\\Documents\\Programs\\DS3ML3_Final_Project\\.venv\\Lib\\site-packages\\urllib3\\response.py", line 1108, in _update_chunk_length\n    line = self._fp.fp.readline()  # type: ignore[union-attr]\n           ^^^^^^^^^^^^^^^^^^^^^^\n  File "C:\\Users\\Kyle_Remote\\AppData\\Local\\Programs\\Python\\Python311\\Lib\\socket.py", line 706, in readinto\n    return self._sock.recv_into(b)\n           ^^^^^^^^^^^^^^^^^^^^^^^\n  File "C:\\Users\\Kyle_Remote\\AppData\\Local\\Programs\\Python\\Python311\\Lib\\ssl.py", line 1311, in recv_into\n    return self.read(nbytes, buffer)\n           ^^^^^^^^^^^^^^^^^^^^^^^^^\n  File "C:\\Users\\Kyle_Remote\\AppData\\Local\\Programs\\Python\\Python311\\Lib\\ssl.py", line 1167, in read\n    return self._sslobj.read(len, buffer)\n           ^^^^^^^^^^^^^^^^^^^^^^^^^^^^^^\nTimeoutError: The read operation timed out\n\nThe above exception was the direct cause of the following exception:\n\nTraceback (most recent call last):\n  File "C:\\Users\\Kyle_Remote\\Documents\\Programs\\DS3ML3_Final_Project\\.venv\\Lib\\site-packages\\requests\\models.py", line 816, in generate\n    yield from self.raw.stream(chunk_size, decode_content=True)\n  File "C:\\Users\\Kyle_Remote\\Documents\\Programs\\DS3ML3_Final_Project\\.venv\\Lib\\site-packages\\urllib3\\response.py", line 1040, in stream\n    yield from self.read_chunked(amt, decode_content=decode_content)\n  File "C:\\Users\\Kyle_Remote\\Documents\\Programs\\DS3ML3_Final_Project\\.venv\\Lib\\site-packages\\urllib3\\response.py", line 1172, in read_chunked\n    with self._error_catcher():\n  File "C:\\Users\\Kyle_Remote\\AppData\\Local\\Programs\\Python\\Python311\\Lib\\contextlib.py", line 155, in __exit__\n    self.gen.throw(typ, value, traceback)\n  File "C:\\Users\\Kyle_Remote\\Documents\\Programs\\DS3ML3_Final_Project\\.venv\\Lib\\site-packages\\urllib3\\response.py", line 742, in _error_catcher\n    raise ReadTimeoutError(self._pool, None, "Read timed out.") from e  # type: ignore[arg-type]\n    ^^^^^^^^^^^^^^^^^^^^^^^^^^^^^^^^^^^^^^^^^^^^^^^^^^^^^^^^^^^^^^^^^^\nurllib3.exceptions.ReadTimeoutError: HTTPSConnectionPool(host=\'lichess.org\', port=443): Read timed out.\n\nDuring handling of the above exception, another exception occurred:\n\nTraceback (most recent call last):\n  File "C:\\Users\\Kyle_Remote\\Documents\\Programs\\DS3ML3_Final_Project\\lichess-bot\\lichess-bot.py", line 98, in watch_control_stream\n    for line in lines:\n  File "C:\\Users\\Kyle_Remote\\Documents\\Programs\\DS3ML3_Final_Project\\.venv\\Lib\\site-packages\\requests\\models.py", line 865, in iter_lines\n    for chunk in self.iter_content(\n  File "C:\\Users\\Kyle_Remote\\Documents\\Programs\\DS3ML3_Final_Project\\.venv\\Lib\\site-packages\\requests\\models.py", line 822, in generate\n    raise ConnectionError(e)\nrequests.exceptions.ConnectionError: HTTPSConnectionPool(host=\'lichess.org\', port=443): Read timed out.\n'}
2024-04-25 23:17:16,840 __main__ (lichess-bot.py:338) DEBUG Terminating exception:
Traceback (most recent call last):
  File "C:\Users\Kyle_Remote\Documents\Programs\DS3ML3_Final_Project\.venv\Lib\site-packages\urllib3\response.py", line 737, in _error_catcher
    yield
  File "C:\Users\Kyle_Remote\Documents\Programs\DS3ML3_Final_Project\.venv\Lib\site-packages\urllib3\response.py", line 1184, in read_chunked
    self._update_chunk_length()
  File "C:\Users\Kyle_Remote\Documents\Programs\DS3ML3_Final_Project\.venv\Lib\site-packages\urllib3\response.py", line 1108, in _update_chunk_length
    line = self._fp.fp.readline()  # type: ignore[union-attr]
           ^^^^^^^^^^^^^^^^^^^^^^
  File "C:\Users\Kyle_Remote\AppData\Local\Programs\Python\Python311\Lib\socket.py", line 706, in readinto
    return self._sock.recv_into(b)
           ^^^^^^^^^^^^^^^^^^^^^^^
  File "C:\Users\Kyle_Remote\AppData\Local\Programs\Python\Python311\Lib\ssl.py", line 1311, in recv_into
    return self.read(nbytes, buffer)
           ^^^^^^^^^^^^^^^^^^^^^^^^^
  File "C:\Users\Kyle_Remote\AppData\Local\Programs\Python\Python311\Lib\ssl.py", line 1167, in read
    return self._sslobj.read(len, buffer)
           ^^^^^^^^^^^^^^^^^^^^^^^^^^^^^^
TimeoutError: The read operation timed out

The above exception was the direct cause of the following exception:

Traceback (most recent call last):
  File "C:\Users\Kyle_Remote\Documents\Programs\DS3ML3_Final_Project\.venv\Lib\site-packages\requests\models.py", line 816, in generate
    yield from self.raw.stream(chunk_size, decode_content=True)
  File "C:\Users\Kyle_Remote\Documents\Programs\DS3ML3_Final_Project\.venv\Lib\site-packages\urllib3\response.py", line 1040, in stream
    yield from self.read_chunked(amt, decode_content=decode_content)
  File "C:\Users\Kyle_Remote\Documents\Programs\DS3ML3_Final_Project\.venv\Lib\site-packages\urllib3\response.py", line 1172, in read_chunked
    with self._error_catcher():
  File "C:\Users\Kyle_Remote\AppData\Local\Programs\Python\Python311\Lib\contextlib.py", line 155, in __exit__
    self.gen.throw(typ, value, traceback)
  File "C:\Users\Kyle_Remote\Documents\Programs\DS3ML3_Final_Project\.venv\Lib\site-packages\urllib3\response.py", line 742, in _error_catcher
    raise ReadTimeoutError(self._pool, None, "Read timed out.") from e  # type: ignore[arg-type]
    ^^^^^^^^^^^^^^^^^^^^^^^^^^^^^^^^^^^^^^^^^^^^^^^^^^^^^^^^^^^^^^^^^^
urllib3.exceptions.ReadTimeoutError: HTTPSConnectionPool(host='lichess.org', port=443): Read timed out.

During handling of the above exception, another exception occurred:

Traceback (most recent call last):
  File "C:\Users\Kyle_Remote\Documents\Programs\DS3ML3_Final_Project\lichess-bot\lichess-bot.py", line 98, in watch_control_stream
    for line in lines:
  File "C:\Users\Kyle_Remote\Documents\Programs\DS3ML3_Final_Project\.venv\Lib\site-packages\requests\models.py", line 865, in iter_lines
    for chunk in self.iter_content(
  File "C:\Users\Kyle_Remote\Documents\Programs\DS3ML3_Final_Project\.venv\Lib\site-packages\requests\models.py", line 822, in generate
    raise ConnectionError(e)
requests.exceptions.ConnectionError: HTTPSConnectionPool(host='lichess.org', port=443): Read timed out.

