2024-04-20 11:20:05,439 __main__ (lichess-bot.py:1051) INFO 
    .   _/|
    .  // o\
    .  || ._)  lichess-bot 2024.3.21.1
    .  //__\
    .  )___(   Play on Lichess with a bot
    
2024-04-20 11:20:05,455 lib.config (config.py:262) DEBUG Config:
token: logger
url: https://lichess.org/
engine:
  dir: ./engines/
  name: ExampleEngine
  working_dir: ''
  protocol: homemade
  ponder: true
  polyglot:
    enabled: false
    book:
      standard:
      - engines/book1.bin
      - engines/book2.bin
    min_weight: 1
    selection: weighted_random
    max_depth: 20
  draw_or_resign:
    resign_enabled: false
    resign_score: -1000
    resign_for_egtb_minus_two: true
    resign_moves: 3
    offer_draw_enabled: true
    offer_draw_score: 0
    offer_draw_for_egtb_zero: true
    offer_draw_moves: 10
    offer_draw_pieces: 10
  online_moves:
    max_out_of_book_moves: 10
    max_retries: 2
    chessdb_book:
      enabled: false
      min_time: 20
      move_quality: good
      min_depth: 20
    lichess_cloud_analysis:
      enabled: false
      min_time: 20
      move_quality: best
      max_score_difference: 50
      min_depth: 20
      min_knodes: 0
    lichess_opening_explorer:
      enabled: false
      min_time: 20
      source: masters
      player_name: ''
      sort: winrate
      min_games: 10
    online_egtb:
      enabled: false
      min_time: 20
      max_pieces: 7
      source: lichess
      move_quality: best
  lichess_bot_tbs:
    syzygy:
      enabled: false
      paths:
      - engines/syzygy
      max_pieces: 7
      move_quality: best
    gaviota:
      enabled: false
      paths:
      - engines/gaviota
      max_pieces: 5
      min_dtm_to_consider_as_wdl_1: 120
      move_quality: best
  homemade_options: null
  uci_options:
    Move Overhead: 100
    Threads: 4
    Hash: 512
    SyzygyPath: ./syzygy/
    UCI_ShowWDL: true
  silence_stderr: false
abort_time: 30
fake_think_time: false
rate_limiting_delay: 0
move_overhead: 2000
quit_after_all_games_finish: false
correspondence:
  move_time: 60
  checkin_period: 300
  disconnect_time: 150
  ponder: false
challenge:
  concurrency: 5
  sort_by: first
  accept_bot: true
  only_bot: false
  max_increment: 20
  min_increment: 0
  max_base: 1800
  min_base: 0
  max_days: 14
  min_days: 1
  variants:
  - standard
  time_controls:
  - bullet
  - blitz
  - rapid
  - classical
  modes:
  - casual
  - rated
  bullet_requires_increment: false
greeting:
  hello: Hi! I'm Kyle's Chess AI. Good luck!
  goodbye: Good game, thanks for playing! If you haven't read the paper yet, please
    consider giving it a read.
  hello_spectators: Hi! I'm {me}. Type !help for a list of commands I can respond
    to.
  goodbye_spectators: Thanks for watching!
matchmaking:
  allow_matchmaking: false
  allow_during_games: false
  challenge_variant: random
  challenge_timeout: 30
  challenge_initial_time:
  - 60
  - 180
  challenge_increment:
  - 1
  - 2
  rating_preference: none
  opponent_allow_tos_violation: false
  challenge_mode: random
  challenge_filter: none

2024-04-20 11:20:05,455 lib.config (config.py:263) DEBUG ====================
2024-04-20 11:20:05,458 lib.config (config.py:262) DEBUG Config:
token: logger
url: https://lichess.org/
engine:
  dir: ./engines/
  name: ExampleEngine
  working_dir: C:\Users\Kyle_Remote\Documents\Programs\DS3ML3_Final_Project\lichess-bot
  protocol: homemade
  ponder: true
  polyglot:
    enabled: false
    book:
      standard:
      - engines/book1.bin
      - engines/book2.bin
    min_weight: 1
    selection: weighted_random
    max_depth: 20
  draw_or_resign:
    resign_enabled: false
    resign_score: -1000
    resign_for_egtb_minus_two: true
    resign_moves: 3
    offer_draw_enabled: true
    offer_draw_score: 0
    offer_draw_for_egtb_zero: true
    offer_draw_moves: 10
    offer_draw_pieces: 10
  online_moves:
    max_out_of_book_moves: 10
    max_retries: 2
    chessdb_book:
      enabled: false
      min_time: 20
      move_quality: good
      min_depth: 20
    lichess_cloud_analysis:
      enabled: false
      min_time: 20
      move_quality: best
      max_score_difference: 50
      min_depth: 20
      min_knodes: 0
    lichess_opening_explorer:
      enabled: false
      min_time: 20
      source: masters
      player_name: ''
      sort: winrate
      min_games: 10
    online_egtb:
      enabled: false
      min_time: 20
      max_pieces: 7
      source: lichess
      move_quality: best
    max_depth: .inf
  lichess_bot_tbs:
    syzygy:
      enabled: false
      paths:
      - engines/syzygy
      max_pieces: 7
      move_quality: best
    gaviota:
      enabled: false
      paths:
      - engines/gaviota
      max_pieces: 5
      min_dtm_to_consider_as_wdl_1: 120
      move_quality: best
  homemade_options: null
  uci_options:
    Move Overhead: 100
    Threads: 4
    Hash: 512
    SyzygyPath: ./syzygy/
    UCI_ShowWDL: true
  silence_stderr: false
  uci_ponder: false
abort_time: 30
fake_think_time: false
rate_limiting_delay: 0
move_overhead: 2000
quit_after_all_games_finish: false
correspondence:
  move_time: 60
  checkin_period: 300
  disconnect_time: 150
  ponder: false
  uci_ponder: false
challenge:
  concurrency: 5
  sort_by: first
  accept_bot: true
  only_bot: false
  max_increment: 20
  min_increment: 0
  max_base: 1800
  min_base: 0
  max_days: 14
  min_days: 1
  variants:
  - standard
  time_controls:
  - bullet
  - blitz
  - rapid
  - classical
  modes:
  - casual
  - rated
  bullet_requires_increment: false
  block_list: []
  allow_list: []
greeting:
  hello: Hi! I'm Kyle's Chess AI. Good luck!
  goodbye: Good game, thanks for playing! If you haven't read the paper yet, please
    consider giving it a read.
  hello_spectators: Hi! I'm {me}. Type !help for a list of commands I can respond
    to.
  goodbye_spectators: Thanks for watching!
matchmaking:
  allow_matchmaking: false
  allow_during_games: false
  challenge_variant: random
  challenge_timeout: 30
  challenge_initial_time:
  - 60
  - 180
  challenge_increment:
  - 1
  - 2
  rating_preference: none
  opponent_allow_tos_violation: false
  challenge_mode: random
  challenge_filter: none
  block_list: []
  challenge_days:
  - null
  opponent_min_rating: 600
  opponent_max_rating: 4000
  overrides: {}
pgn_file_grouping: game

2024-04-20 11:20:05,458 lib.config (config.py:263) DEBUG ====================
2024-04-20 11:20:05,459 __main__ (lichess-bot.py:1054) INFO Checking engine configuration ...
2024-04-20 11:20:05,808 matplotlib (__init__.py:350) DEBUG matplotlib data path: C:\Users\Kyle_Remote\Documents\Programs\DS3ML3_Final_Project\.venv\Lib\site-packages\matplotlib\mpl-data
2024-04-20 11:20:05,813 matplotlib (__init__.py:350) DEBUG CONFIGDIR=C:\Users\Kyle_Remote\.matplotlib
2024-04-20 11:20:05,814 matplotlib (__init__.py:1511) DEBUG interactive is False
2024-04-20 11:20:05,814 matplotlib (__init__.py:1512) DEBUG platform is win32
2024-04-20 11:20:05,861 matplotlib (__init__.py:350) DEBUG CACHEDIR=C:\Users\Kyle_Remote\.matplotlib
2024-04-20 11:20:05,864 matplotlib.font_manager (font_manager.py:1574) DEBUG Using fontManager instance from C:\Users\Kyle_Remote\.matplotlib\fontlist-v330.json
2024-04-20 11:20:10,143 lib.engine_wrapper (engine_wrapper.py:68) DEBUG Starting engine: ['C:\\Users\\Kyle_Remote\\Documents\\Programs\\DS3ML3_Final_Project\\lichess-bot\\engines\\ExampleEngine']
2024-04-20 11:20:10,143 __main__ (lichess-bot.py:1057) INFO Engine configuration OK
2024-04-20 11:20:10,147 urllib3.connectionpool (connectionpool.py:1055) DEBUG Starting new HTTPS connection (1): lichess.org:443
2024-04-20 11:20:10,810 urllib3.connectionpool (connectionpool.py:549) DEBUG https://lichess.org:443 "POST /api/token/test HTTP/1.1" 200 None
2024-04-20 11:20:10,914 urllib3.connectionpool (connectionpool.py:549) DEBUG https://lichess.org:443 "GET /api/account HTTP/1.1" 200 None
2024-04-20 11:20:10,914 __main__ (lichess-bot.py:1066) INFO Welcome KS_ChessAI!
2024-04-20 11:20:10,915 __main__ (lichess-bot.py:225) INFO You're now connected to https://lichess.org/ and awaiting challenges.
2024-04-20 11:20:11,408 urllib3.connectionpool (connectionpool.py:549) DEBUG https://lichess.org:443 "GET /api/account/playing HTTP/1.1" 200 17
2024-04-20 11:25:11,743 __main__ (lichess-bot.py:404) DEBUG Event: {'type': 'correspondence_ping'}
2024-04-20 11:30:11,744 __main__ (lichess-bot.py:404) DEBUG Event: {'type': 'correspondence_ping'}
2024-04-20 11:35:11,745 __main__ (lichess-bot.py:404) DEBUG Event: {'type': 'correspondence_ping'}
2024-04-20 11:40:11,746 __main__ (lichess-bot.py:404) DEBUG Event: {'type': 'correspondence_ping'}
2024-04-20 11:45:11,746 __main__ (lichess-bot.py:404) DEBUG Event: {'type': 'correspondence_ping'}
2024-04-20 11:50:11,747 __main__ (lichess-bot.py:404) DEBUG Event: {'type': 'correspondence_ping'}
2024-04-20 11:55:11,747 __main__ (lichess-bot.py:404) DEBUG Event: {'type': 'correspondence_ping'}
2024-04-20 12:00:11,747 __main__ (lichess-bot.py:404) DEBUG Event: {'type': 'correspondence_ping'}
2024-04-20 12:05:11,748 __main__ (lichess-bot.py:404) DEBUG Event: {'type': 'correspondence_ping'}
2024-04-20 12:10:11,748 __main__ (lichess-bot.py:404) DEBUG Event: {'type': 'correspondence_ping'}
2024-04-20 12:15:11,749 __main__ (lichess-bot.py:404) DEBUG Event: {'type': 'correspondence_ping'}
2024-04-20 12:20:11,750 __main__ (lichess-bot.py:404) DEBUG Event: {'type': 'correspondence_ping'}
2024-04-20 12:20:11,751 urllib3.connectionpool (connectionpool.py:292) DEBUG Resetting dropped connection: lichess.org
2024-04-20 12:20:12,257 urllib3.connectionpool (connectionpool.py:549) DEBUG https://lichess.org:443 "GET /api/users/status?ids=ks_chessai HTTP/1.1" 200 None
2024-04-20 12:25:11,750 __main__ (lichess-bot.py:404) DEBUG Event: {'type': 'correspondence_ping'}
2024-04-20 12:30:11,751 __main__ (lichess-bot.py:404) DEBUG Event: {'type': 'correspondence_ping'}
2024-04-20 12:35:11,751 __main__ (lichess-bot.py:404) DEBUG Event: {'type': 'correspondence_ping'}
2024-04-20 12:40:11,752 __main__ (lichess-bot.py:404) DEBUG Event: {'type': 'correspondence_ping'}
2024-04-20 12:45:11,752 __main__ (lichess-bot.py:404) DEBUG Event: {'type': 'correspondence_ping'}
2024-04-20 12:50:11,753 __main__ (lichess-bot.py:404) DEBUG Event: {'type': 'correspondence_ping'}
2024-04-20 12:55:11,754 __main__ (lichess-bot.py:404) DEBUG Event: {'type': 'correspondence_ping'}
2024-04-20 13:00:11,754 __main__ (lichess-bot.py:404) DEBUG Event: {'type': 'correspondence_ping'}
2024-04-20 13:05:11,755 __main__ (lichess-bot.py:404) DEBUG Event: {'type': 'correspondence_ping'}
2024-04-20 13:10:11,755 __main__ (lichess-bot.py:404) DEBUG Event: {'type': 'correspondence_ping'}
2024-04-20 13:15:11,755 __main__ (lichess-bot.py:404) DEBUG Event: {'type': 'correspondence_ping'}
2024-04-20 13:20:11,756 __main__ (lichess-bot.py:404) DEBUG Event: {'type': 'correspondence_ping'}
2024-04-20 13:20:16,916 urllib3.connectionpool (connectionpool.py:292) DEBUG Resetting dropped connection: lichess.org
2024-04-20 13:20:17,440 urllib3.connectionpool (connectionpool.py:549) DEBUG https://lichess.org:443 "GET /api/users/status?ids=ks_chessai HTTP/1.1" 200 None
2024-04-20 13:25:11,756 __main__ (lichess-bot.py:404) DEBUG Event: {'type': 'correspondence_ping'}
2024-04-20 13:30:11,756 __main__ (lichess-bot.py:404) DEBUG Event: {'type': 'correspondence_ping'}
2024-04-20 13:35:11,757 __main__ (lichess-bot.py:404) DEBUG Event: {'type': 'correspondence_ping'}
2024-04-20 13:40:11,758 __main__ (lichess-bot.py:404) DEBUG Event: {'type': 'correspondence_ping'}
2024-04-20 13:45:11,758 __main__ (lichess-bot.py:404) DEBUG Event: {'type': 'correspondence_ping'}
2024-04-20 13:50:11,759 __main__ (lichess-bot.py:404) DEBUG Event: {'type': 'correspondence_ping'}
2024-04-20 13:55:11,759 __main__ (lichess-bot.py:404) DEBUG Event: {'type': 'correspondence_ping'}
2024-04-20 14:00:11,760 __main__ (lichess-bot.py:404) DEBUG Event: {'type': 'correspondence_ping'}
2024-04-20 14:05:11,760 __main__ (lichess-bot.py:404) DEBUG Event: {'type': 'correspondence_ping'}
2024-04-20 14:10:11,760 __main__ (lichess-bot.py:404) DEBUG Event: {'type': 'correspondence_ping'}
2024-04-20 14:15:11,761 __main__ (lichess-bot.py:404) DEBUG Event: {'type': 'correspondence_ping'}
2024-04-20 14:20:11,762 __main__ (lichess-bot.py:404) DEBUG Event: {'type': 'correspondence_ping'}
2024-04-20 14:20:19,000 urllib3.connectionpool (connectionpool.py:292) DEBUG Resetting dropped connection: lichess.org
2024-04-20 14:20:19,587 urllib3.connectionpool (connectionpool.py:549) DEBUG https://lichess.org:443 "GET /api/users/status?ids=ks_chessai HTTP/1.1" 200 None
2024-04-20 14:25:11,762 __main__ (lichess-bot.py:404) DEBUG Event: {'type': 'correspondence_ping'}
2024-04-20 14:30:11,763 __main__ (lichess-bot.py:404) DEBUG Event: {'type': 'correspondence_ping'}
2024-04-20 14:35:11,764 __main__ (lichess-bot.py:404) DEBUG Event: {'type': 'correspondence_ping'}
2024-04-20 14:40:11,764 __main__ (lichess-bot.py:404) DEBUG Event: {'type': 'correspondence_ping'}
2024-04-20 14:45:11,765 __main__ (lichess-bot.py:404) DEBUG Event: {'type': 'correspondence_ping'}
2024-04-20 14:50:11,765 __main__ (lichess-bot.py:404) DEBUG Event: {'type': 'correspondence_ping'}
2024-04-20 14:55:11,766 __main__ (lichess-bot.py:404) DEBUG Event: {'type': 'correspondence_ping'}
2024-04-20 15:00:11,764 __main__ (lichess-bot.py:404) DEBUG Event: {'type': 'correspondence_ping'}
2024-04-20 15:05:11,689 __main__ (lichess-bot.py:404) DEBUG Event: {'type': 'correspondence_ping'}
2024-04-20 15:10:11,613 __main__ (lichess-bot.py:404) DEBUG Event: {'type': 'correspondence_ping'}
2024-04-20 15:15:11,538 __main__ (lichess-bot.py:404) DEBUG Event: {'type': 'correspondence_ping'}
2024-04-20 15:20:11,475 __main__ (lichess-bot.py:404) DEBUG Event: {'type': 'correspondence_ping'}
2024-04-20 15:20:21,197 urllib3.connectionpool (connectionpool.py:292) DEBUG Resetting dropped connection: lichess.org
2024-04-20 15:20:21,739 urllib3.connectionpool (connectionpool.py:549) DEBUG https://lichess.org:443 "GET /api/users/status?ids=ks_chessai HTTP/1.1" 200 None
2024-04-20 15:25:11,421 __main__ (lichess-bot.py:404) DEBUG Event: {'type': 'correspondence_ping'}
2024-04-20 15:30:11,367 __main__ (lichess-bot.py:404) DEBUG Event: {'type': 'correspondence_ping'}
2024-04-20 15:35:11,316 __main__ (lichess-bot.py:404) DEBUG Event: {'type': 'correspondence_ping'}
2024-04-20 15:40:11,277 __main__ (lichess-bot.py:404) DEBUG Event: {'type': 'correspondence_ping'}
2024-04-20 15:45:11,239 __main__ (lichess-bot.py:404) DEBUG Event: {'type': 'correspondence_ping'}
2024-04-20 15:50:11,200 __main__ (lichess-bot.py:404) DEBUG Event: {'type': 'correspondence_ping'}
2024-04-20 15:55:11,171 __main__ (lichess-bot.py:404) DEBUG Event: {'type': 'correspondence_ping'}
2024-04-20 16:00:11,143 __main__ (lichess-bot.py:404) DEBUG Event: {'type': 'correspondence_ping'}
2024-04-20 16:05:11,116 __main__ (lichess-bot.py:404) DEBUG Event: {'type': 'correspondence_ping'}
2024-04-20 16:10:11,092 __main__ (lichess-bot.py:404) DEBUG Event: {'type': 'correspondence_ping'}
2024-04-20 16:15:11,072 __main__ (lichess-bot.py:404) DEBUG Event: {'type': 'correspondence_ping'}
2024-04-20 16:20:11,053 __main__ (lichess-bot.py:404) DEBUG Event: {'type': 'correspondence_ping'}
2024-04-20 16:20:23,620 urllib3.connectionpool (connectionpool.py:292) DEBUG Resetting dropped connection: lichess.org
2024-04-20 16:20:24,167 urllib3.connectionpool (connectionpool.py:549) DEBUG https://lichess.org:443 "GET /api/users/status?ids=ks_chessai HTTP/1.1" 200 None
2024-04-20 16:25:11,033 __main__ (lichess-bot.py:404) DEBUG Event: {'type': 'correspondence_ping'}
2024-04-20 16:30:11,019 __main__ (lichess-bot.py:404) DEBUG Event: {'type': 'correspondence_ping'}
2024-04-20 16:35:11,006 __main__ (lichess-bot.py:404) DEBUG Event: {'type': 'correspondence_ping'}
2024-04-20 16:40:10,992 __main__ (lichess-bot.py:404) DEBUG Event: {'type': 'correspondence_ping'}
2024-04-20 16:45:10,981 __main__ (lichess-bot.py:404) DEBUG Event: {'type': 'correspondence_ping'}
2024-04-20 16:50:10,971 __main__ (lichess-bot.py:404) DEBUG Event: {'type': 'correspondence_ping'}
2024-04-20 16:55:10,961 __main__ (lichess-bot.py:404) DEBUG Event: {'type': 'correspondence_ping'}
2024-04-20 17:00:10,952 __main__ (lichess-bot.py:404) DEBUG Event: {'type': 'correspondence_ping'}
2024-04-20 17:05:10,945 __main__ (lichess-bot.py:404) DEBUG Event: {'type': 'correspondence_ping'}
2024-04-20 17:10:10,939 __main__ (lichess-bot.py:404) DEBUG Event: {'type': 'correspondence_ping'}
2024-04-20 17:15:10,932 __main__ (lichess-bot.py:404) DEBUG Event: {'type': 'correspondence_ping'}
2024-04-20 17:20:10,927 __main__ (lichess-bot.py:404) DEBUG Event: {'type': 'correspondence_ping'}
2024-04-20 17:20:26,537 urllib3.connectionpool (connectionpool.py:292) DEBUG Resetting dropped connection: lichess.org
2024-04-20 17:20:27,079 urllib3.connectionpool (connectionpool.py:549) DEBUG https://lichess.org:443 "GET /api/users/status?ids=ks_chessai HTTP/1.1" 200 None
2024-04-20 17:25:10,922 __main__ (lichess-bot.py:404) DEBUG Event: {'type': 'correspondence_ping'}
2024-04-20 17:30:10,917 __main__ (lichess-bot.py:404) DEBUG Event: {'type': 'correspondence_ping'}
2024-04-20 17:35:10,913 __main__ (lichess-bot.py:404) DEBUG Event: {'type': 'correspondence_ping'}
2024-04-20 17:40:10,910 __main__ (lichess-bot.py:404) DEBUG Event: {'type': 'correspondence_ping'}
2024-04-20 17:45:10,907 __main__ (lichess-bot.py:404) DEBUG Event: {'type': 'correspondence_ping'}
2024-04-20 17:50:10,904 __main__ (lichess-bot.py:404) DEBUG Event: {'type': 'correspondence_ping'}
2024-04-20 17:55:10,902 __main__ (lichess-bot.py:404) DEBUG Event: {'type': 'correspondence_ping'}
2024-04-20 18:00:10,900 __main__ (lichess-bot.py:404) DEBUG Event: {'type': 'correspondence_ping'}
2024-04-20 18:05:10,898 __main__ (lichess-bot.py:404) DEBUG Event: {'type': 'correspondence_ping'}
2024-04-20 18:10:10,896 __main__ (lichess-bot.py:404) DEBUG Event: {'type': 'correspondence_ping'}
2024-04-20 18:15:10,894 __main__ (lichess-bot.py:404) DEBUG Event: {'type': 'correspondence_ping'}
2024-04-20 18:20:10,893 __main__ (lichess-bot.py:404) DEBUG Event: {'type': 'correspondence_ping'}
2024-04-20 18:20:30,238 urllib3.connectionpool (connectionpool.py:292) DEBUG Resetting dropped connection: lichess.org
2024-04-20 18:20:30,764 urllib3.connectionpool (connectionpool.py:549) DEBUG https://lichess.org:443 "GET /api/users/status?ids=ks_chessai HTTP/1.1" 200 None
2024-04-20 18:25:10,891 __main__ (lichess-bot.py:404) DEBUG Event: {'type': 'correspondence_ping'}
2024-04-20 18:30:10,890 __main__ (lichess-bot.py:404) DEBUG Event: {'type': 'correspondence_ping'}
2024-04-20 18:35:10,890 __main__ (lichess-bot.py:404) DEBUG Event: {'type': 'correspondence_ping'}
2024-04-20 18:40:10,888 __main__ (lichess-bot.py:404) DEBUG Event: {'type': 'correspondence_ping'}
2024-04-20 18:45:10,888 __main__ (lichess-bot.py:404) DEBUG Event: {'type': 'correspondence_ping'}
2024-04-20 18:50:10,887 __main__ (lichess-bot.py:404) DEBUG Event: {'type': 'correspondence_ping'}
2024-04-20 18:55:10,886 __main__ (lichess-bot.py:404) DEBUG Event: {'type': 'correspondence_ping'}
2024-04-20 19:00:10,886 __main__ (lichess-bot.py:404) DEBUG Event: {'type': 'correspondence_ping'}
2024-04-20 19:05:10,886 __main__ (lichess-bot.py:404) DEBUG Event: {'type': 'correspondence_ping'}
2024-04-20 19:10:10,886 __main__ (lichess-bot.py:404) DEBUG Event: {'type': 'correspondence_ping'}
2024-04-20 19:15:10,886 __main__ (lichess-bot.py:404) DEBUG Event: {'type': 'correspondence_ping'}
2024-04-20 19:20:10,886 __main__ (lichess-bot.py:404) DEBUG Event: {'type': 'correspondence_ping'}
2024-04-20 19:20:34,529 urllib3.connectionpool (connectionpool.py:292) DEBUG Resetting dropped connection: lichess.org
2024-04-20 19:20:35,082 urllib3.connectionpool (connectionpool.py:549) DEBUG https://lichess.org:443 "GET /api/users/status?ids=ks_chessai HTTP/1.1" 200 None
2024-04-20 19:25:10,886 __main__ (lichess-bot.py:404) DEBUG Event: {'type': 'correspondence_ping'}
2024-04-20 19:30:10,886 __main__ (lichess-bot.py:404) DEBUG Event: {'type': 'correspondence_ping'}
2024-04-20 19:35:10,885 __main__ (lichess-bot.py:404) DEBUG Event: {'type': 'correspondence_ping'}
2024-04-20 19:40:10,886 __main__ (lichess-bot.py:404) DEBUG Event: {'type': 'correspondence_ping'}
2024-04-20 19:45:10,886 __main__ (lichess-bot.py:404) DEBUG Event: {'type': 'correspondence_ping'}
2024-04-20 19:50:10,886 __main__ (lichess-bot.py:404) DEBUG Event: {'type': 'correspondence_ping'}
2024-04-20 19:55:10,887 __main__ (lichess-bot.py:404) DEBUG Event: {'type': 'correspondence_ping'}
2024-04-20 20:00:10,887 __main__ (lichess-bot.py:404) DEBUG Event: {'type': 'correspondence_ping'}
2024-04-20 20:05:10,887 __main__ (lichess-bot.py:404) DEBUG Event: {'type': 'correspondence_ping'}
2024-04-20 20:10:10,887 __main__ (lichess-bot.py:404) DEBUG Event: {'type': 'correspondence_ping'}
2024-04-20 20:15:10,888 __main__ (lichess-bot.py:404) DEBUG Event: {'type': 'correspondence_ping'}
2024-04-20 20:20:10,888 __main__ (lichess-bot.py:404) DEBUG Event: {'type': 'correspondence_ping'}
2024-04-20 20:20:39,195 urllib3.connectionpool (connectionpool.py:292) DEBUG Resetting dropped connection: lichess.org
2024-04-20 20:20:39,761 urllib3.connectionpool (connectionpool.py:549) DEBUG https://lichess.org:443 "GET /api/users/status?ids=ks_chessai HTTP/1.1" 200 None
2024-04-20 20:25:10,888 __main__ (lichess-bot.py:404) DEBUG Event: {'type': 'correspondence_ping'}
2024-04-20 20:30:10,889 __main__ (lichess-bot.py:404) DEBUG Event: {'type': 'correspondence_ping'}
2024-04-20 20:35:10,889 __main__ (lichess-bot.py:404) DEBUG Event: {'type': 'correspondence_ping'}
2024-04-20 20:40:10,889 __main__ (lichess-bot.py:404) DEBUG Event: {'type': 'correspondence_ping'}
2024-04-20 20:45:10,890 __main__ (lichess-bot.py:404) DEBUG Event: {'type': 'correspondence_ping'}
2024-04-20 20:50:10,891 __main__ (lichess-bot.py:404) DEBUG Event: {'type': 'correspondence_ping'}
2024-04-20 20:55:10,891 __main__ (lichess-bot.py:404) DEBUG Event: {'type': 'correspondence_ping'}
2024-04-20 21:00:10,892 __main__ (lichess-bot.py:404) DEBUG Event: {'type': 'correspondence_ping'}
2024-04-20 21:05:10,892 __main__ (lichess-bot.py:404) DEBUG Event: {'type': 'correspondence_ping'}
2024-04-20 21:10:10,893 __main__ (lichess-bot.py:404) DEBUG Event: {'type': 'correspondence_ping'}
2024-04-20 21:15:10,893 __main__ (lichess-bot.py:404) DEBUG Event: {'type': 'correspondence_ping'}
2024-04-20 21:20:10,894 __main__ (lichess-bot.py:404) DEBUG Event: {'type': 'correspondence_ping'}
2024-04-20 21:20:43,104 urllib3.connectionpool (connectionpool.py:292) DEBUG Resetting dropped connection: lichess.org
2024-04-20 21:20:43,647 urllib3.connectionpool (connectionpool.py:549) DEBUG https://lichess.org:443 "GET /api/users/status?ids=ks_chessai HTTP/1.1" 200 None
2024-04-20 21:25:10,894 __main__ (lichess-bot.py:404) DEBUG Event: {'type': 'correspondence_ping'}
2024-04-20 21:30:10,895 __main__ (lichess-bot.py:404) DEBUG Event: {'type': 'correspondence_ping'}
2024-04-20 21:35:10,896 __main__ (lichess-bot.py:404) DEBUG Event: {'type': 'correspondence_ping'}
2024-04-20 21:40:10,896 __main__ (lichess-bot.py:404) DEBUG Event: {'type': 'correspondence_ping'}
2024-04-20 21:45:10,897 __main__ (lichess-bot.py:404) DEBUG Event: {'type': 'correspondence_ping'}
2024-04-20 21:50:10,897 __main__ (lichess-bot.py:404) DEBUG Event: {'type': 'correspondence_ping'}
2024-04-20 21:55:10,898 __main__ (lichess-bot.py:404) DEBUG Event: {'type': 'correspondence_ping'}
2024-04-20 22:00:10,899 __main__ (lichess-bot.py:404) DEBUG Event: {'type': 'correspondence_ping'}
2024-04-20 22:05:10,899 __main__ (lichess-bot.py:404) DEBUG Event: {'type': 'correspondence_ping'}
2024-04-20 22:10:10,899 __main__ (lichess-bot.py:404) DEBUG Event: {'type': 'correspondence_ping'}
2024-04-20 22:15:10,900 __main__ (lichess-bot.py:404) DEBUG Event: {'type': 'correspondence_ping'}
2024-04-20 22:20:10,900 __main__ (lichess-bot.py:404) DEBUG Event: {'type': 'correspondence_ping'}
2024-04-20 22:20:48,087 urllib3.connectionpool (connectionpool.py:292) DEBUG Resetting dropped connection: lichess.org
2024-04-20 22:20:48,669 urllib3.connectionpool (connectionpool.py:549) DEBUG https://lichess.org:443 "GET /api/users/status?ids=ks_chessai HTTP/1.1" 200 None
2024-04-20 22:25:10,901 __main__ (lichess-bot.py:404) DEBUG Event: {'type': 'correspondence_ping'}
2024-04-20 22:30:10,902 __main__ (lichess-bot.py:404) DEBUG Event: {'type': 'correspondence_ping'}
2024-04-20 22:35:10,902 __main__ (lichess-bot.py:404) DEBUG Event: {'type': 'correspondence_ping'}
2024-04-20 22:40:10,902 __main__ (lichess-bot.py:404) DEBUG Event: {'type': 'correspondence_ping'}
2024-04-20 22:45:10,903 __main__ (lichess-bot.py:404) DEBUG Event: {'type': 'correspondence_ping'}
2024-04-20 22:50:10,903 __main__ (lichess-bot.py:404) DEBUG Event: {'type': 'correspondence_ping'}
2024-04-20 22:55:10,903 __main__ (lichess-bot.py:404) DEBUG Event: {'type': 'correspondence_ping'}
2024-04-20 23:00:10,904 __main__ (lichess-bot.py:404) DEBUG Event: {'type': 'correspondence_ping'}
2024-04-20 23:05:10,905 __main__ (lichess-bot.py:404) DEBUG Event: {'type': 'correspondence_ping'}
2024-04-20 23:10:10,905 __main__ (lichess-bot.py:404) DEBUG Event: {'type': 'correspondence_ping'}
2024-04-20 23:15:10,905 __main__ (lichess-bot.py:404) DEBUG Event: {'type': 'correspondence_ping'}
2024-04-20 23:20:10,906 __main__ (lichess-bot.py:404) DEBUG Event: {'type': 'correspondence_ping'}
2024-04-20 23:20:53,348 urllib3.connectionpool (connectionpool.py:292) DEBUG Resetting dropped connection: lichess.org
2024-04-20 23:20:53,929 urllib3.connectionpool (connectionpool.py:549) DEBUG https://lichess.org:443 "GET /api/users/status?ids=ks_chessai HTTP/1.1" 200 None
2024-04-20 23:25:10,906 __main__ (lichess-bot.py:404) DEBUG Event: {'type': 'correspondence_ping'}
2024-04-20 23:30:10,907 __main__ (lichess-bot.py:404) DEBUG Event: {'type': 'correspondence_ping'}
2024-04-20 23:35:10,907 __main__ (lichess-bot.py:404) DEBUG Event: {'type': 'correspondence_ping'}
2024-04-20 23:40:10,908 __main__ (lichess-bot.py:404) DEBUG Event: {'type': 'correspondence_ping'}
2024-04-20 23:45:10,909 __main__ (lichess-bot.py:404) DEBUG Event: {'type': 'correspondence_ping'}
2024-04-20 23:50:10,909 __main__ (lichess-bot.py:404) DEBUG Event: {'type': 'correspondence_ping'}
2024-04-20 23:55:10,908 __main__ (lichess-bot.py:404) DEBUG Event: {'type': 'correspondence_ping'}
2024-04-21 00:00:10,907 __main__ (lichess-bot.py:404) DEBUG Event: {'type': 'correspondence_ping'}
2024-04-21 00:05:10,906 __main__ (lichess-bot.py:404) DEBUG Event: {'type': 'correspondence_ping'}
2024-04-21 00:10:10,905 __main__ (lichess-bot.py:404) DEBUG Event: {'type': 'correspondence_ping'}
2024-04-21 00:15:10,904 __main__ (lichess-bot.py:404) DEBUG Event: {'type': 'correspondence_ping'}
2024-04-21 00:20:10,904 __main__ (lichess-bot.py:404) DEBUG Event: {'type': 'correspondence_ping'}
2024-04-21 00:20:58,944 urllib3.connectionpool (connectionpool.py:292) DEBUG Resetting dropped connection: lichess.org
2024-04-21 00:20:59,530 urllib3.connectionpool (connectionpool.py:549) DEBUG https://lichess.org:443 "GET /api/users/status?ids=ks_chessai HTTP/1.1" 200 None
2024-04-21 00:25:10,903 __main__ (lichess-bot.py:404) DEBUG Event: {'type': 'correspondence_ping'}
2024-04-21 00:30:10,902 __main__ (lichess-bot.py:404) DEBUG Event: {'type': 'correspondence_ping'}
2024-04-21 00:35:10,902 __main__ (lichess-bot.py:404) DEBUG Event: {'type': 'correspondence_ping'}
2024-04-21 00:40:10,901 __main__ (lichess-bot.py:404) DEBUG Event: {'type': 'correspondence_ping'}
2024-04-21 00:45:10,901 __main__ (lichess-bot.py:404) DEBUG Event: {'type': 'correspondence_ping'}
2024-04-21 00:50:10,901 __main__ (lichess-bot.py:404) DEBUG Event: {'type': 'correspondence_ping'}
2024-04-21 00:55:10,901 __main__ (lichess-bot.py:404) DEBUG Event: {'type': 'correspondence_ping'}
2024-04-21 01:00:10,901 __main__ (lichess-bot.py:404) DEBUG Event: {'type': 'correspondence_ping'}
2024-04-21 01:05:10,901 __main__ (lichess-bot.py:404) DEBUG Event: {'type': 'correspondence_ping'}
2024-04-21 01:10:10,901 __main__ (lichess-bot.py:404) DEBUG Event: {'type': 'correspondence_ping'}
2024-04-21 01:15:10,901 __main__ (lichess-bot.py:404) DEBUG Event: {'type': 'correspondence_ping'}
2024-04-21 01:20:10,902 __main__ (lichess-bot.py:404) DEBUG Event: {'type': 'correspondence_ping'}
2024-04-21 01:21:04,028 urllib3.connectionpool (connectionpool.py:292) DEBUG Resetting dropped connection: lichess.org
2024-04-21 01:21:04,600 urllib3.connectionpool (connectionpool.py:549) DEBUG https://lichess.org:443 "GET /api/users/status?ids=ks_chessai HTTP/1.1" 200 None
2024-04-21 01:25:10,907 __main__ (lichess-bot.py:404) DEBUG Event: {'type': 'correspondence_ping'}
2024-04-21 01:30:10,905 __main__ (lichess-bot.py:404) DEBUG Event: {'type': 'correspondence_ping'}
2024-04-21 01:35:10,906 __main__ (lichess-bot.py:404) DEBUG Event: {'type': 'correspondence_ping'}
2024-04-21 01:40:10,914 __main__ (lichess-bot.py:404) DEBUG Event: {'type': 'correspondence_ping'}
2024-04-21 01:45:10,913 __main__ (lichess-bot.py:404) DEBUG Event: {'type': 'correspondence_ping'}
2024-04-21 01:50:10,913 __main__ (lichess-bot.py:404) DEBUG Event: {'type': 'correspondence_ping'}
2024-04-21 01:55:10,913 __main__ (lichess-bot.py:404) DEBUG Event: {'type': 'correspondence_ping'}
2024-04-21 02:00:10,913 __main__ (lichess-bot.py:404) DEBUG Event: {'type': 'correspondence_ping'}
2024-04-21 02:05:10,914 __main__ (lichess-bot.py:404) DEBUG Event: {'type': 'correspondence_ping'}
2024-04-21 02:10:10,914 __main__ (lichess-bot.py:404) DEBUG Event: {'type': 'correspondence_ping'}
2024-04-21 02:15:10,914 __main__ (lichess-bot.py:404) DEBUG Event: {'type': 'correspondence_ping'}
2024-04-21 02:20:10,917 __main__ (lichess-bot.py:404) DEBUG Event: {'type': 'correspondence_ping'}
2024-04-21 02:21:08,714 urllib3.connectionpool (connectionpool.py:292) DEBUG Resetting dropped connection: lichess.org
2024-04-21 02:21:09,292 urllib3.connectionpool (connectionpool.py:549) DEBUG https://lichess.org:443 "GET /api/users/status?ids=ks_chessai HTTP/1.1" 200 None
2024-04-21 02:25:10,917 __main__ (lichess-bot.py:404) DEBUG Event: {'type': 'correspondence_ping'}
2024-04-21 02:30:10,917 __main__ (lichess-bot.py:404) DEBUG Event: {'type': 'correspondence_ping'}
2024-04-21 02:35:10,918 __main__ (lichess-bot.py:404) DEBUG Event: {'type': 'correspondence_ping'}
2024-04-21 02:40:10,918 __main__ (lichess-bot.py:404) DEBUG Event: {'type': 'correspondence_ping'}
2024-04-21 02:45:10,919 __main__ (lichess-bot.py:404) DEBUG Event: {'type': 'correspondence_ping'}
2024-04-21 02:50:10,919 __main__ (lichess-bot.py:404) DEBUG Event: {'type': 'correspondence_ping'}
2024-04-21 02:55:10,920 __main__ (lichess-bot.py:404) DEBUG Event: {'type': 'correspondence_ping'}
2024-04-21 03:00:10,920 __main__ (lichess-bot.py:404) DEBUG Event: {'type': 'correspondence_ping'}
2024-04-21 03:05:10,921 __main__ (lichess-bot.py:404) DEBUG Event: {'type': 'correspondence_ping'}
2024-04-21 03:10:10,921 __main__ (lichess-bot.py:404) DEBUG Event: {'type': 'correspondence_ping'}
2024-04-21 03:15:10,921 __main__ (lichess-bot.py:404) DEBUG Event: {'type': 'correspondence_ping'}
2024-04-21 03:20:10,922 __main__ (lichess-bot.py:404) DEBUG Event: {'type': 'correspondence_ping'}
2024-04-21 03:21:13,128 urllib3.connectionpool (connectionpool.py:292) DEBUG Resetting dropped connection: lichess.org
2024-04-21 03:21:13,699 urllib3.connectionpool (connectionpool.py:549) DEBUG https://lichess.org:443 "GET /api/users/status?ids=ks_chessai HTTP/1.1" 200 None
2024-04-21 03:25:10,922 __main__ (lichess-bot.py:404) DEBUG Event: {'type': 'correspondence_ping'}
2024-04-21 03:30:10,923 __main__ (lichess-bot.py:404) DEBUG Event: {'type': 'correspondence_ping'}
2024-04-21 03:35:10,923 __main__ (lichess-bot.py:404) DEBUG Event: {'type': 'correspondence_ping'}
2024-04-21 03:40:10,924 __main__ (lichess-bot.py:404) DEBUG Event: {'type': 'correspondence_ping'}
2024-04-21 03:45:10,924 __main__ (lichess-bot.py:404) DEBUG Event: {'type': 'correspondence_ping'}
2024-04-21 03:50:10,925 __main__ (lichess-bot.py:404) DEBUG Event: {'type': 'correspondence_ping'}
2024-04-21 03:55:10,925 __main__ (lichess-bot.py:404) DEBUG Event: {'type': 'correspondence_ping'}
2024-04-21 04:00:10,926 __main__ (lichess-bot.py:404) DEBUG Event: {'type': 'correspondence_ping'}
2024-04-21 04:05:10,926 __main__ (lichess-bot.py:404) DEBUG Event: {'type': 'correspondence_ping'}
2024-04-21 04:10:10,927 __main__ (lichess-bot.py:404) DEBUG Event: {'type': 'correspondence_ping'}
2024-04-21 04:15:10,927 __main__ (lichess-bot.py:404) DEBUG Event: {'type': 'correspondence_ping'}
2024-04-21 04:20:10,928 __main__ (lichess-bot.py:404) DEBUG Event: {'type': 'correspondence_ping'}
2024-04-21 04:21:17,089 urllib3.connectionpool (connectionpool.py:292) DEBUG Resetting dropped connection: lichess.org
2024-04-21 04:21:17,708 urllib3.connectionpool (connectionpool.py:549) DEBUG https://lichess.org:443 "GET /api/users/status?ids=ks_chessai HTTP/1.1" 200 None
2024-04-21 04:25:10,929 __main__ (lichess-bot.py:404) DEBUG Event: {'type': 'correspondence_ping'}
2024-04-21 04:30:10,929 __main__ (lichess-bot.py:404) DEBUG Event: {'type': 'correspondence_ping'}
2024-04-21 04:35:10,930 __main__ (lichess-bot.py:404) DEBUG Event: {'type': 'correspondence_ping'}
2024-04-21 04:40:10,931 __main__ (lichess-bot.py:404) DEBUG Event: {'type': 'correspondence_ping'}
2024-04-21 04:45:10,932 __main__ (lichess-bot.py:404) DEBUG Event: {'type': 'correspondence_ping'}
2024-04-21 04:50:10,932 __main__ (lichess-bot.py:404) DEBUG Event: {'type': 'correspondence_ping'}
2024-04-21 04:55:10,932 __main__ (lichess-bot.py:404) DEBUG Event: {'type': 'correspondence_ping'}
2024-04-21 05:00:10,933 __main__ (lichess-bot.py:404) DEBUG Event: {'type': 'correspondence_ping'}
2024-04-21 05:05:10,934 __main__ (lichess-bot.py:404) DEBUG Event: {'type': 'correspondence_ping'}
2024-04-21 05:10:10,934 __main__ (lichess-bot.py:404) DEBUG Event: {'type': 'correspondence_ping'}
2024-04-21 05:15:10,935 __main__ (lichess-bot.py:404) DEBUG Event: {'type': 'correspondence_ping'}
2024-04-21 05:20:10,935 __main__ (lichess-bot.py:404) DEBUG Event: {'type': 'correspondence_ping'}
2024-04-21 05:21:20,369 urllib3.connectionpool (connectionpool.py:292) DEBUG Resetting dropped connection: lichess.org
2024-04-21 05:21:20,958 urllib3.connectionpool (connectionpool.py:549) DEBUG https://lichess.org:443 "GET /api/users/status?ids=ks_chessai HTTP/1.1" 200 None
2024-04-21 05:25:10,936 __main__ (lichess-bot.py:404) DEBUG Event: {'type': 'correspondence_ping'}
2024-04-21 05:30:10,936 __main__ (lichess-bot.py:404) DEBUG Event: {'type': 'correspondence_ping'}
2024-04-21 05:35:10,936 __main__ (lichess-bot.py:404) DEBUG Event: {'type': 'correspondence_ping'}
2024-04-21 05:40:10,937 __main__ (lichess-bot.py:404) DEBUG Event: {'type': 'correspondence_ping'}
2024-04-21 05:45:10,937 __main__ (lichess-bot.py:404) DEBUG Event: {'type': 'correspondence_ping'}
2024-04-21 05:50:10,938 __main__ (lichess-bot.py:404) DEBUG Event: {'type': 'correspondence_ping'}
2024-04-21 05:55:10,939 __main__ (lichess-bot.py:404) DEBUG Event: {'type': 'correspondence_ping'}
2024-04-21 06:00:10,939 __main__ (lichess-bot.py:404) DEBUG Event: {'type': 'correspondence_ping'}
2024-04-21 06:05:10,940 __main__ (lichess-bot.py:404) DEBUG Event: {'type': 'correspondence_ping'}
2024-04-21 06:10:10,941 __main__ (lichess-bot.py:404) DEBUG Event: {'type': 'correspondence_ping'}
2024-04-21 06:15:10,941 __main__ (lichess-bot.py:404) DEBUG Event: {'type': 'correspondence_ping'}
2024-04-21 06:20:10,942 __main__ (lichess-bot.py:404) DEBUG Event: {'type': 'correspondence_ping'}
2024-04-21 06:21:24,259 urllib3.connectionpool (connectionpool.py:292) DEBUG Resetting dropped connection: lichess.org
2024-04-21 06:21:24,837 urllib3.connectionpool (connectionpool.py:549) DEBUG https://lichess.org:443 "GET /api/users/status?ids=ks_chessai HTTP/1.1" 200 None
2024-04-21 06:25:10,942 __main__ (lichess-bot.py:404) DEBUG Event: {'type': 'correspondence_ping'}
2024-04-21 06:30:10,943 __main__ (lichess-bot.py:404) DEBUG Event: {'type': 'correspondence_ping'}
2024-04-21 06:35:10,943 __main__ (lichess-bot.py:404) DEBUG Event: {'type': 'correspondence_ping'}
2024-04-21 06:40:10,944 __main__ (lichess-bot.py:404) DEBUG Event: {'type': 'correspondence_ping'}
2024-04-21 06:45:10,945 __main__ (lichess-bot.py:404) DEBUG Event: {'type': 'correspondence_ping'}
2024-04-21 06:50:10,945 __main__ (lichess-bot.py:404) DEBUG Event: {'type': 'correspondence_ping'}
2024-04-21 06:55:10,946 __main__ (lichess-bot.py:404) DEBUG Event: {'type': 'correspondence_ping'}
2024-04-21 07:00:10,946 __main__ (lichess-bot.py:404) DEBUG Event: {'type': 'correspondence_ping'}
2024-04-21 07:05:10,947 __main__ (lichess-bot.py:404) DEBUG Event: {'type': 'correspondence_ping'}
2024-04-21 07:10:10,947 __main__ (lichess-bot.py:404) DEBUG Event: {'type': 'correspondence_ping'}
2024-04-21 07:15:10,948 __main__ (lichess-bot.py:404) DEBUG Event: {'type': 'correspondence_ping'}
2024-04-21 07:20:10,948 __main__ (lichess-bot.py:404) DEBUG Event: {'type': 'correspondence_ping'}
2024-04-21 07:21:27,392 urllib3.connectionpool (connectionpool.py:292) DEBUG Resetting dropped connection: lichess.org
2024-04-21 07:21:27,950 urllib3.connectionpool (connectionpool.py:549) DEBUG https://lichess.org:443 "GET /api/users/status?ids=ks_chessai HTTP/1.1" 200 None
2024-04-21 07:25:10,949 __main__ (lichess-bot.py:404) DEBUG Event: {'type': 'correspondence_ping'}
2024-04-21 07:30:10,950 __main__ (lichess-bot.py:404) DEBUG Event: {'type': 'correspondence_ping'}
2024-04-21 07:35:10,950 __main__ (lichess-bot.py:404) DEBUG Event: {'type': 'correspondence_ping'}
2024-04-21 07:40:10,951 __main__ (lichess-bot.py:404) DEBUG Event: {'type': 'correspondence_ping'}
2024-04-21 07:45:10,951 __main__ (lichess-bot.py:404) DEBUG Event: {'type': 'correspondence_ping'}
2024-04-21 07:50:10,952 __main__ (lichess-bot.py:404) DEBUG Event: {'type': 'correspondence_ping'}
2024-04-21 07:55:10,953 __main__ (lichess-bot.py:404) DEBUG Event: {'type': 'correspondence_ping'}
2024-04-21 08:00:10,953 __main__ (lichess-bot.py:404) DEBUG Event: {'type': 'correspondence_ping'}
2024-04-21 08:05:10,953 __main__ (lichess-bot.py:404) DEBUG Event: {'type': 'correspondence_ping'}
2024-04-21 08:10:10,954 __main__ (lichess-bot.py:404) DEBUG Event: {'type': 'correspondence_ping'}
2024-04-21 08:15:10,954 __main__ (lichess-bot.py:404) DEBUG Event: {'type': 'correspondence_ping'}
2024-04-21 08:20:10,955 __main__ (lichess-bot.py:404) DEBUG Event: {'type': 'correspondence_ping'}
2024-04-21 08:21:31,294 urllib3.connectionpool (connectionpool.py:292) DEBUG Resetting dropped connection: lichess.org
2024-04-21 08:21:31,904 urllib3.connectionpool (connectionpool.py:549) DEBUG https://lichess.org:443 "GET /api/users/status?ids=ks_chessai HTTP/1.1" 200 None
2024-04-21 08:25:10,955 __main__ (lichess-bot.py:404) DEBUG Event: {'type': 'correspondence_ping'}
2024-04-21 08:30:10,956 __main__ (lichess-bot.py:404) DEBUG Event: {'type': 'correspondence_ping'}
2024-04-21 08:35:10,957 __main__ (lichess-bot.py:404) DEBUG Event: {'type': 'correspondence_ping'}
2024-04-21 08:40:10,958 __main__ (lichess-bot.py:404) DEBUG Event: {'type': 'correspondence_ping'}
2024-04-21 08:45:10,958 __main__ (lichess-bot.py:404) DEBUG Event: {'type': 'correspondence_ping'}
2024-04-21 08:50:10,959 __main__ (lichess-bot.py:404) DEBUG Event: {'type': 'correspondence_ping'}
2024-04-21 08:55:10,959 __main__ (lichess-bot.py:404) DEBUG Event: {'type': 'correspondence_ping'}
2024-04-21 09:00:10,958 __main__ (lichess-bot.py:404) DEBUG Event: {'type': 'correspondence_ping'}
2024-04-21 09:05:10,958 __main__ (lichess-bot.py:404) DEBUG Event: {'type': 'correspondence_ping'}
2024-04-21 09:10:10,957 __main__ (lichess-bot.py:404) DEBUG Event: {'type': 'correspondence_ping'}
2024-04-21 09:15:10,956 __main__ (lichess-bot.py:404) DEBUG Event: {'type': 'correspondence_ping'}
2024-04-21 09:20:10,956 __main__ (lichess-bot.py:404) DEBUG Event: {'type': 'correspondence_ping'}
2024-04-21 09:21:34,609 urllib3.connectionpool (connectionpool.py:292) DEBUG Resetting dropped connection: lichess.org
2024-04-21 09:21:35,197 urllib3.connectionpool (connectionpool.py:549) DEBUG https://lichess.org:443 "GET /api/users/status?ids=ks_chessai HTTP/1.1" 200 None
2024-04-21 09:25:10,955 __main__ (lichess-bot.py:404) DEBUG Event: {'type': 'correspondence_ping'}
2024-04-21 09:30:10,955 __main__ (lichess-bot.py:404) DEBUG Event: {'type': 'correspondence_ping'}
2024-04-21 09:35:10,954 __main__ (lichess-bot.py:404) DEBUG Event: {'type': 'correspondence_ping'}
2024-04-21 09:40:10,954 __main__ (lichess-bot.py:404) DEBUG Event: {'type': 'correspondence_ping'}
2024-04-21 09:45:10,954 __main__ (lichess-bot.py:404) DEBUG Event: {'type': 'correspondence_ping'}
2024-04-21 09:50:10,954 __main__ (lichess-bot.py:404) DEBUG Event: {'type': 'correspondence_ping'}
2024-04-21 09:55:10,954 __main__ (lichess-bot.py:404) DEBUG Event: {'type': 'correspondence_ping'}
2024-04-21 10:00:10,953 __main__ (lichess-bot.py:404) DEBUG Event: {'type': 'correspondence_ping'}
2024-04-21 10:05:10,954 __main__ (lichess-bot.py:404) DEBUG Event: {'type': 'correspondence_ping'}
2024-04-21 10:10:10,954 __main__ (lichess-bot.py:404) DEBUG Event: {'type': 'correspondence_ping'}
2024-04-21 10:15:10,954 __main__ (lichess-bot.py:404) DEBUG Event: {'type': 'correspondence_ping'}
2024-04-21 10:20:10,954 __main__ (lichess-bot.py:404) DEBUG Event: {'type': 'correspondence_ping'}
2024-04-21 10:21:38,598 urllib3.connectionpool (connectionpool.py:292) DEBUG Resetting dropped connection: lichess.org
2024-04-21 10:21:39,171 urllib3.connectionpool (connectionpool.py:549) DEBUG https://lichess.org:443 "GET /api/users/status?ids=ks_chessai HTTP/1.1" 200 None
2024-04-21 10:25:10,954 __main__ (lichess-bot.py:404) DEBUG Event: {'type': 'correspondence_ping'}
2024-04-21 10:30:10,954 __main__ (lichess-bot.py:404) DEBUG Event: {'type': 'correspondence_ping'}
2024-04-21 10:35:10,955 __main__ (lichess-bot.py:404) DEBUG Event: {'type': 'correspondence_ping'}
2024-04-21 10:40:10,955 __main__ (lichess-bot.py:404) DEBUG Event: {'type': 'correspondence_ping'}
2024-04-21 10:45:10,955 __main__ (lichess-bot.py:404) DEBUG Event: {'type': 'correspondence_ping'}
2024-04-21 10:50:10,955 __main__ (lichess-bot.py:404) DEBUG Event: {'type': 'correspondence_ping'}
2024-04-21 10:55:10,955 __main__ (lichess-bot.py:404) DEBUG Event: {'type': 'correspondence_ping'}
2024-04-21 10:59:39,883 __main__ (lichess-bot.py:404) DEBUG Event: {'type': 'challenge', 'challenge': {'id': 'IPPi87y5', 'url': 'https://lichess.org/IPPi87y5', 'status': 'created', 'challenger': {'id': 'checkyle', 'name': 'ChecKyle', 'rating': 1410, 'title': None, 'provisional': True, 'online': True, 'lag': 4}, 'destUser': {'id': 'ks_chessai', 'name': 'KS_ChessAI', 'rating': 2000, 'title': 'BOT', 'provisional': True, 'online': True}, 'variant': {'key': 'standard', 'name': 'Standard', 'short': 'Std'}, 'rated': False, 'speed': 'blitz', 'timeControl': {'type': 'clock', 'limit': 300, 'increment': 1, 'show': '5+1'}, 'color': 'random', 'finalColor': 'black', 'perf': {'icon': '\ue01d', 'name': 'Blitz'}}, 'compat': {'bot': True, 'board': True}}
2024-04-21 10:59:39,926 __main__ (lichess-bot.py:455) INFO Accept Blitz casual challenge from ChecKyle (1410?) (IPPi87y5)
2024-04-21 10:59:39,930 urllib3.connectionpool (connectionpool.py:292) DEBUG Resetting dropped connection: lichess.org
2024-04-21 10:59:40,462 urllib3.connectionpool (connectionpool.py:549) DEBUG https://lichess.org:443 "POST /api/challenge/IPPi87y5/accept HTTP/1.1" 200 11
2024-04-21 10:59:40,465 __main__ (lichess-bot.py:274) INFO --- Process Queued. Count: 1. IDs: {'IPPi87y5'}
2024-04-21 10:59:40,466 __main__ (lichess-bot.py:404) DEBUG Event: {'type': 'gameStart', 'game': {'fullId': 'IPPi87y5tcrF', 'gameId': 'IPPi87y5', 'fen': 'rnbqkbnr/pppppppp/8/8/8/8/PPPPPPPP/RNBQKBNR w KQkq - 0 1', 'color': 'white', 'lastMove': '', 'source': 'friend', 'status': {'id': 20, 'name': 'started'}, 'variant': {'key': 'standard', 'name': 'Standard'}, 'speed': 'blitz', 'perf': 'blitz', 'rated': False, 'hasMoved': False, 'opponent': {'id': 'checkyle', 'username': 'ChecKyle', 'rating': 1410}, 'isMyTurn': True, 'secondsLeft': 300, 'compat': {'bot': True, 'board': True}, 'id': 'IPPi87y5'}}
2024-04-21 10:59:40,468 __main__ (lichess-bot.py:274) INFO --- Process Used. Count: 1. IDs: {'IPPi87y5'}
2024-04-21 10:59:40,694 urllib3.connectionpool (connectionpool.py:1055) DEBUG Starting new HTTPS connection (1): lichess.org:443
2024-04-21 10:59:41,246 urllib3.connectionpool (connectionpool.py:549) DEBUG https://lichess.org:443 "GET /api/bot/game/stream/IPPi87y5 HTTP/1.1" 200 None
2024-04-21 10:59:41,247 __mp_main__ (lichess-bot.py:605) DEBUG Initial state: {'id': 'IPPi87y5', 'variant': {'key': 'standard', 'name': 'Standard', 'short': 'Std'}, 'speed': 'blitz', 'perf': {'name': 'Blitz'}, 'rated': False, 'createdAt': 1713711580395, 'white': {'id': 'ks_chessai', 'name': 'KS_ChessAI', 'title': 'BOT', 'rating': 2000, 'provisional': True}, 'black': {'id': 'checkyle', 'name': 'ChecKyle', 'title': None, 'rating': 1410, 'provisional': True}, 'initialFen': 'startpos', 'clock': {'initial': 300000, 'increment': 1000}, 'type': 'gameFull', 'state': {'type': 'gameState', 'moves': '', 'wtime': 300000, 'btime': 300000, 'winc': 1000, 'binc': 1000, 'status': 'started'}}
2024-04-21 10:59:41,712 matplotlib (__init__.py:350) DEBUG matplotlib data path: C:\Users\Kyle_Remote\Documents\Programs\DS3ML3_Final_Project\.venv\Lib\site-packages\matplotlib\mpl-data
2024-04-21 10:59:41,718 matplotlib (__init__.py:350) DEBUG CONFIGDIR=C:\Users\Kyle_Remote\.matplotlib
2024-04-21 10:59:41,719 matplotlib (__init__.py:1511) DEBUG interactive is False
2024-04-21 10:59:41,719 matplotlib (__init__.py:1512) DEBUG platform is win32
2024-04-21 10:59:41,770 matplotlib (__init__.py:350) DEBUG CACHEDIR=C:\Users\Kyle_Remote\.matplotlib
2024-04-21 10:59:41,774 matplotlib.font_manager (font_manager.py:1574) DEBUG Using fontManager instance from C:\Users\Kyle_Remote\.matplotlib\fontlist-v330.json
2024-04-21 10:59:46,526 backoff (_common.py:105) INFO Backing off play_game(...) for 0.4s (ModuleNotFoundError: No module named 'chess_SL_E5_lib')
2024-04-21 10:59:46,527 lib.lichess (lichess.py:63) DEBUG Backing off 0.4 seconds after 1 tries calling function <function play_game at 0x0000017FA1C28680> with args () and kwargs {'li': <lib.lichess.Lichess object at 0x0000017FA1C26950>, 'control_queue': <AutoProxy[Queue] object, typeid 'Queue' at 0x17fa1c80690>, 'user_profile': {'id': 'ks_chessai', 'username': 'KS_ChessAI', 'perfs': {'bullet': {'games': 0, 'rating': 2000, 'rd': 500, 'prog': 0, 'prov': True}, 'blitz': {'games': 0, 'rating': 2000, 'rd': 500, 'prog': 0, 'prov': True}, 'rapid': {'games': 0, 'rating': 2000, 'rd': 500, 'prog': 0, 'prov': True}, 'classical': {'games': 0, 'rating': 2000, 'rd': 500, 'prog': 0, 'prov': True}, 'correspondence': {'games': 0, 'rating': 2000, 'rd': 500, 'prog': 0, 'prov': True}}, 'title': 'BOT', 'createdAt': 1711486329716, 'seenAt': 1713625564792, 'playTime': {'total': 15628, 'tv': 0}, 'url': 'https://lichess.org/@/KS_ChessAI', 'count': {'all': 113, 'rated': 0, 'ai': 0, 'draw': 11, 'drawH': 11, 'loss': 89, 'lossH': 89, 'win': 13, 'winH': 13, 'bookmark': 0, 'playing': 0, 'import': 0, 'me': 0}, 'followable': True, 'following': False, 'blocking': False, 'followsYou': False}, 'config': <lib.config.Configuration object at 0x0000017FA1C81F10>, 'challenge_queue': <ListProxy object, typeid 'list' at 0x17fa1c88550>, 'correspondence_queue': <AutoProxy[Queue] object, typeid 'Queue' at 0x17fa1c88790>, 'logging_queue': <AutoProxy[Queue] object, typeid 'Queue' at 0x17fa1c889d0>, 'game_id': 'IPPi87y5'}
2024-04-21 10:59:46,532 lib.lichess (lichess.py:65) DEBUG Exception: Traceback (most recent call last):
  File "C:\Users\Kyle_Remote\Documents\Programs\DS3ML3_Final_Project\.venv\Lib\site-packages\backoff\_sync.py", line 105, in retry
    ret = target(*args, **kwargs)
          ^^^^^^^^^^^^^^^^^^^^^^^
  File "C:\Users\Kyle_Remote\Documents\Programs\DS3ML3_Final_Project\lichess-bot\lichess-bot.py", line 609, in play_game
    with engine_wrapper.create_engine(config, game) as engine:
         ^^^^^^^^^^^^^^^^^^^^^^^^^^^^^^^^^^^^^^^^^^
  File "C:\Users\Kyle_Remote\Documents\Programs\DS3ML3_Final_Project\lichess-bot\lib\engine_wrapper.py", line 63, in create_engine
    Engine = getHomemadeEngine(cfg.name)
             ^^^^^^^^^^^^^^^^^^^^^^^^^^^
  File "C:\Users\Kyle_Remote\Documents\Programs\DS3ML3_Final_Project\lichess-bot\lib\engine_wrapper.py", line 620, in getHomemadeEngine
    import homemade
  File "C:\Users\Kyle_Remote\Documents\Programs\DS3ML3_Final_Project\lichess-bot\homemade.py", line 27, in <module>
    model_loaded = torch.load('../models_EL/model_E7-2.pth', map_location=device)
                   ^^^^^^^^^^^^^^^^^^^^^^^^^^^^^^^^^^^^^^^^^^^^^^^^^^^^^^^^^^^^^^
  File "C:\Users\Kyle_Remote\Documents\Programs\DS3ML3_Final_Project\.venv\Lib\site-packages\torch\serialization.py", line 1026, in load
    return _load(opened_zipfile,
           ^^^^^^^^^^^^^^^^^^^^^
  File "C:\Users\Kyle_Remote\Documents\Programs\DS3ML3_Final_Project\.venv\Lib\site-packages\torch\serialization.py", line 1438, in _load
    result = unpickler.load()
             ^^^^^^^^^^^^^^^^
  File "C:\Users\Kyle_Remote\Documents\Programs\DS3ML3_Final_Project\.venv\Lib\site-packages\torch\serialization.py", line 1431, in find_class
    return super().find_class(mod_name, name)
           ^^^^^^^^^^^^^^^^^^^^^^^^^^^^^^^^^^
ModuleNotFoundError: No module named 'chess_SL_E5_lib'

2024-04-21 10:59:46,918 urllib3.connectionpool (connectionpool.py:1055) DEBUG Starting new HTTPS connection (2): lichess.org:443
2024-04-21 10:59:47,451 urllib3.connectionpool (connectionpool.py:549) DEBUG https://lichess.org:443 "GET /api/bot/game/stream/IPPi87y5 HTTP/1.1" 200 None
2024-04-21 10:59:47,452 __mp_main__ (lichess-bot.py:605) DEBUG Initial state: {'id': 'IPPi87y5', 'variant': {'key': 'standard', 'name': 'Standard', 'short': 'Std'}, 'speed': 'blitz', 'perf': {'name': 'Blitz'}, 'rated': False, 'createdAt': 1713711580395, 'white': {'id': 'ks_chessai', 'name': 'KS_ChessAI', 'title': 'BOT', 'rating': 2000, 'provisional': True}, 'black': {'id': 'checkyle', 'name': 'ChecKyle', 'title': None, 'rating': 1410, 'provisional': True}, 'initialFen': 'startpos', 'clock': {'initial': 300000, 'increment': 1000}, 'type': 'gameFull', 'state': {'type': 'gameState', 'moves': '', 'wtime': 300000, 'btime': 300000, 'winc': 1000, 'binc': 1000, 'status': 'started'}}
2024-04-21 10:59:47,453 backoff (_common.py:105) INFO Backing off play_game(...) for 1.1s (ModuleNotFoundError: No module named 'chess_SL_E5_lib')
2024-04-21 10:59:47,454 lib.lichess (lichess.py:63) DEBUG Backing off 1.1 seconds after 2 tries calling function <function play_game at 0x0000017FA1C28680> with args () and kwargs {'li': <lib.lichess.Lichess object at 0x0000017FA1C26950>, 'control_queue': <AutoProxy[Queue] object, typeid 'Queue' at 0x17fa1c80690>, 'user_profile': {'id': 'ks_chessai', 'username': 'KS_ChessAI', 'perfs': {'bullet': {'games': 0, 'rating': 2000, 'rd': 500, 'prog': 0, 'prov': True}, 'blitz': {'games': 0, 'rating': 2000, 'rd': 500, 'prog': 0, 'prov': True}, 'rapid': {'games': 0, 'rating': 2000, 'rd': 500, 'prog': 0, 'prov': True}, 'classical': {'games': 0, 'rating': 2000, 'rd': 500, 'prog': 0, 'prov': True}, 'correspondence': {'games': 0, 'rating': 2000, 'rd': 500, 'prog': 0, 'prov': True}}, 'title': 'BOT', 'createdAt': 1711486329716, 'seenAt': 1713625564792, 'playTime': {'total': 15628, 'tv': 0}, 'url': 'https://lichess.org/@/KS_ChessAI', 'count': {'all': 113, 'rated': 0, 'ai': 0, 'draw': 11, 'drawH': 11, 'loss': 89, 'lossH': 89, 'win': 13, 'winH': 13, 'bookmark': 0, 'playing': 0, 'import': 0, 'me': 0}, 'followable': True, 'following': False, 'blocking': False, 'followsYou': False}, 'config': <lib.config.Configuration object at 0x0000017FA1C81F10>, 'challenge_queue': <ListProxy object, typeid 'list' at 0x17fa1c88550>, 'correspondence_queue': <AutoProxy[Queue] object, typeid 'Queue' at 0x17fa1c88790>, 'logging_queue': <AutoProxy[Queue] object, typeid 'Queue' at 0x17fa1c889d0>, 'game_id': 'IPPi87y5'}
2024-04-21 10:59:47,456 lib.lichess (lichess.py:65) DEBUG Exception: Traceback (most recent call last):
  File "C:\Users\Kyle_Remote\Documents\Programs\DS3ML3_Final_Project\.venv\Lib\site-packages\backoff\_sync.py", line 105, in retry
    ret = target(*args, **kwargs)
          ^^^^^^^^^^^^^^^^^^^^^^^
  File "C:\Users\Kyle_Remote\Documents\Programs\DS3ML3_Final_Project\lichess-bot\lichess-bot.py", line 609, in play_game
    with engine_wrapper.create_engine(config, game) as engine:
         ^^^^^^^^^^^^^^^^^^^^^^^^^^^^^^^^^^^^^^^^^^
  File "C:\Users\Kyle_Remote\Documents\Programs\DS3ML3_Final_Project\lichess-bot\lib\engine_wrapper.py", line 63, in create_engine
    Engine = getHomemadeEngine(cfg.name)
             ^^^^^^^^^^^^^^^^^^^^^^^^^^^
  File "C:\Users\Kyle_Remote\Documents\Programs\DS3ML3_Final_Project\lichess-bot\lib\engine_wrapper.py", line 620, in getHomemadeEngine
    import homemade
  File "C:\Users\Kyle_Remote\Documents\Programs\DS3ML3_Final_Project\lichess-bot\homemade.py", line 27, in <module>
    model_loaded = torch.load('../models_EL/model_E7-2.pth', map_location=device)
                   ^^^^^^^^^^^^^^^^^^^^^^^^^^^^^^^^^^^^^^^^^^^^^^^^^^^^^^^^^^^^^^
  File "C:\Users\Kyle_Remote\Documents\Programs\DS3ML3_Final_Project\.venv\Lib\site-packages\torch\serialization.py", line 1026, in load
    return _load(opened_zipfile,
           ^^^^^^^^^^^^^^^^^^^^^
  File "C:\Users\Kyle_Remote\Documents\Programs\DS3ML3_Final_Project\.venv\Lib\site-packages\torch\serialization.py", line 1438, in _load
    result = unpickler.load()
             ^^^^^^^^^^^^^^^^
  File "C:\Users\Kyle_Remote\Documents\Programs\DS3ML3_Final_Project\.venv\Lib\site-packages\torch\serialization.py", line 1431, in find_class
    return super().find_class(mod_name, name)
           ^^^^^^^^^^^^^^^^^^^^^^^^^^^^^^^^^^
ModuleNotFoundError: No module named 'chess_SL_E5_lib'

2024-04-21 10:59:48,565 urllib3.connectionpool (connectionpool.py:292) DEBUG Resetting dropped connection: lichess.org
2024-04-21 10:59:49,102 urllib3.connectionpool (connectionpool.py:549) DEBUG https://lichess.org:443 "GET /api/bot/game/stream/IPPi87y5 HTTP/1.1" 200 None
2024-04-21 10:59:49,103 __mp_main__ (lichess-bot.py:605) DEBUG Initial state: {'id': 'IPPi87y5', 'variant': {'key': 'standard', 'name': 'Standard', 'short': 'Std'}, 'speed': 'blitz', 'perf': {'name': 'Blitz'}, 'rated': False, 'createdAt': 1713711580395, 'white': {'id': 'ks_chessai', 'name': 'KS_ChessAI', 'title': 'BOT', 'rating': 2000, 'provisional': True}, 'black': {'id': 'checkyle', 'name': 'ChecKyle', 'title': None, 'rating': 1410, 'provisional': True}, 'initialFen': 'startpos', 'clock': {'initial': 300000, 'increment': 1000}, 'type': 'gameFull', 'state': {'type': 'gameState', 'moves': '', 'wtime': 300000, 'btime': 300000, 'winc': 1000, 'binc': 1000, 'status': 'started'}}
2024-04-21 10:59:49,105 backoff (_common.py:105) INFO Backing off play_game(...) for 3.7s (ModuleNotFoundError: No module named 'chess_SL_E5_lib')
2024-04-21 10:59:49,105 lib.lichess (lichess.py:63) DEBUG Backing off 3.7 seconds after 3 tries calling function <function play_game at 0x0000017FA1C28680> with args () and kwargs {'li': <lib.lichess.Lichess object at 0x0000017FA1C26950>, 'control_queue': <AutoProxy[Queue] object, typeid 'Queue' at 0x17fa1c80690>, 'user_profile': {'id': 'ks_chessai', 'username': 'KS_ChessAI', 'perfs': {'bullet': {'games': 0, 'rating': 2000, 'rd': 500, 'prog': 0, 'prov': True}, 'blitz': {'games': 0, 'rating': 2000, 'rd': 500, 'prog': 0, 'prov': True}, 'rapid': {'games': 0, 'rating': 2000, 'rd': 500, 'prog': 0, 'prov': True}, 'classical': {'games': 0, 'rating': 2000, 'rd': 500, 'prog': 0, 'prov': True}, 'correspondence': {'games': 0, 'rating': 2000, 'rd': 500, 'prog': 0, 'prov': True}}, 'title': 'BOT', 'createdAt': 1711486329716, 'seenAt': 1713625564792, 'playTime': {'total': 15628, 'tv': 0}, 'url': 'https://lichess.org/@/KS_ChessAI', 'count': {'all': 113, 'rated': 0, 'ai': 0, 'draw': 11, 'drawH': 11, 'loss': 89, 'lossH': 89, 'win': 13, 'winH': 13, 'bookmark': 0, 'playing': 0, 'import': 0, 'me': 0}, 'followable': True, 'following': False, 'blocking': False, 'followsYou': False}, 'config': <lib.config.Configuration object at 0x0000017FA1C81F10>, 'challenge_queue': <ListProxy object, typeid 'list' at 0x17fa1c88550>, 'correspondence_queue': <AutoProxy[Queue] object, typeid 'Queue' at 0x17fa1c88790>, 'logging_queue': <AutoProxy[Queue] object, typeid 'Queue' at 0x17fa1c889d0>, 'game_id': 'IPPi87y5'}
2024-04-21 10:59:49,106 lib.lichess (lichess.py:65) DEBUG Exception: Traceback (most recent call last):
  File "C:\Users\Kyle_Remote\Documents\Programs\DS3ML3_Final_Project\.venv\Lib\site-packages\backoff\_sync.py", line 105, in retry
    ret = target(*args, **kwargs)
          ^^^^^^^^^^^^^^^^^^^^^^^
  File "C:\Users\Kyle_Remote\Documents\Programs\DS3ML3_Final_Project\lichess-bot\lichess-bot.py", line 609, in play_game
    with engine_wrapper.create_engine(config, game) as engine:
         ^^^^^^^^^^^^^^^^^^^^^^^^^^^^^^^^^^^^^^^^^^
  File "C:\Users\Kyle_Remote\Documents\Programs\DS3ML3_Final_Project\lichess-bot\lib\engine_wrapper.py", line 63, in create_engine
    Engine = getHomemadeEngine(cfg.name)
             ^^^^^^^^^^^^^^^^^^^^^^^^^^^
  File "C:\Users\Kyle_Remote\Documents\Programs\DS3ML3_Final_Project\lichess-bot\lib\engine_wrapper.py", line 620, in getHomemadeEngine
    import homemade
  File "C:\Users\Kyle_Remote\Documents\Programs\DS3ML3_Final_Project\lichess-bot\homemade.py", line 27, in <module>
    model_loaded = torch.load('../models_EL/model_E7-2.pth', map_location=device)
                   ^^^^^^^^^^^^^^^^^^^^^^^^^^^^^^^^^^^^^^^^^^^^^^^^^^^^^^^^^^^^^^
  File "C:\Users\Kyle_Remote\Documents\Programs\DS3ML3_Final_Project\.venv\Lib\site-packages\torch\serialization.py", line 1026, in load
    return _load(opened_zipfile,
           ^^^^^^^^^^^^^^^^^^^^^
  File "C:\Users\Kyle_Remote\Documents\Programs\DS3ML3_Final_Project\.venv\Lib\site-packages\torch\serialization.py", line 1438, in _load
    result = unpickler.load()
             ^^^^^^^^^^^^^^^^
  File "C:\Users\Kyle_Remote\Documents\Programs\DS3ML3_Final_Project\.venv\Lib\site-packages\torch\serialization.py", line 1431, in find_class
    return super().find_class(mod_name, name)
           ^^^^^^^^^^^^^^^^^^^^^^^^^^^^^^^^^^
ModuleNotFoundError: No module named 'chess_SL_E5_lib'

2024-04-21 10:59:52,845 urllib3.connectionpool (connectionpool.py:292) DEBUG Resetting dropped connection: lichess.org
2024-04-21 10:59:53,484 urllib3.connectionpool (connectionpool.py:549) DEBUG https://lichess.org:443 "GET /api/bot/game/stream/IPPi87y5 HTTP/1.1" 200 None
2024-04-21 10:59:53,485 __mp_main__ (lichess-bot.py:605) DEBUG Initial state: {'id': 'IPPi87y5', 'variant': {'key': 'standard', 'name': 'Standard', 'short': 'Std'}, 'speed': 'blitz', 'perf': {'name': 'Blitz'}, 'rated': False, 'createdAt': 1713711580395, 'white': {'id': 'ks_chessai', 'name': 'KS_ChessAI', 'title': 'BOT', 'rating': 2000, 'provisional': True}, 'black': {'id': 'checkyle', 'name': 'ChecKyle', 'title': None, 'rating': 1410, 'provisional': True}, 'initialFen': 'startpos', 'clock': {'initial': 300000, 'increment': 1000}, 'type': 'gameFull', 'state': {'type': 'gameState', 'moves': '', 'wtime': 300000, 'btime': 300000, 'winc': 1000, 'binc': 1000, 'status': 'started'}}
2024-04-21 10:59:53,487 backoff (_common.py:105) INFO Backing off play_game(...) for 6.5s (ModuleNotFoundError: No module named 'chess_SL_E5_lib')
2024-04-21 10:59:53,487 lib.lichess (lichess.py:63) DEBUG Backing off 6.5 seconds after 4 tries calling function <function play_game at 0x0000017FA1C28680> with args () and kwargs {'li': <lib.lichess.Lichess object at 0x0000017FA1C26950>, 'control_queue': <AutoProxy[Queue] object, typeid 'Queue' at 0x17fa1c80690>, 'user_profile': {'id': 'ks_chessai', 'username': 'KS_ChessAI', 'perfs': {'bullet': {'games': 0, 'rating': 2000, 'rd': 500, 'prog': 0, 'prov': True}, 'blitz': {'games': 0, 'rating': 2000, 'rd': 500, 'prog': 0, 'prov': True}, 'rapid': {'games': 0, 'rating': 2000, 'rd': 500, 'prog': 0, 'prov': True}, 'classical': {'games': 0, 'rating': 2000, 'rd': 500, 'prog': 0, 'prov': True}, 'correspondence': {'games': 0, 'rating': 2000, 'rd': 500, 'prog': 0, 'prov': True}}, 'title': 'BOT', 'createdAt': 1711486329716, 'seenAt': 1713625564792, 'playTime': {'total': 15628, 'tv': 0}, 'url': 'https://lichess.org/@/KS_ChessAI', 'count': {'all': 113, 'rated': 0, 'ai': 0, 'draw': 11, 'drawH': 11, 'loss': 89, 'lossH': 89, 'win': 13, 'winH': 13, 'bookmark': 0, 'playing': 0, 'import': 0, 'me': 0}, 'followable': True, 'following': False, 'blocking': False, 'followsYou': False}, 'config': <lib.config.Configuration object at 0x0000017FA1C81F10>, 'challenge_queue': <ListProxy object, typeid 'list' at 0x17fa1c88550>, 'correspondence_queue': <AutoProxy[Queue] object, typeid 'Queue' at 0x17fa1c88790>, 'logging_queue': <AutoProxy[Queue] object, typeid 'Queue' at 0x17fa1c889d0>, 'game_id': 'IPPi87y5'}
2024-04-21 10:59:53,488 lib.lichess (lichess.py:65) DEBUG Exception: Traceback (most recent call last):
  File "C:\Users\Kyle_Remote\Documents\Programs\DS3ML3_Final_Project\.venv\Lib\site-packages\backoff\_sync.py", line 105, in retry
    ret = target(*args, **kwargs)
          ^^^^^^^^^^^^^^^^^^^^^^^
  File "C:\Users\Kyle_Remote\Documents\Programs\DS3ML3_Final_Project\lichess-bot\lichess-bot.py", line 609, in play_game
    with engine_wrapper.create_engine(config, game) as engine:
         ^^^^^^^^^^^^^^^^^^^^^^^^^^^^^^^^^^^^^^^^^^
  File "C:\Users\Kyle_Remote\Documents\Programs\DS3ML3_Final_Project\lichess-bot\lib\engine_wrapper.py", line 63, in create_engine
    Engine = getHomemadeEngine(cfg.name)
             ^^^^^^^^^^^^^^^^^^^^^^^^^^^
  File "C:\Users\Kyle_Remote\Documents\Programs\DS3ML3_Final_Project\lichess-bot\lib\engine_wrapper.py", line 620, in getHomemadeEngine
    import homemade
  File "C:\Users\Kyle_Remote\Documents\Programs\DS3ML3_Final_Project\lichess-bot\homemade.py", line 27, in <module>
    model_loaded = torch.load('../models_EL/model_E7-2.pth', map_location=device)
                   ^^^^^^^^^^^^^^^^^^^^^^^^^^^^^^^^^^^^^^^^^^^^^^^^^^^^^^^^^^^^^^
  File "C:\Users\Kyle_Remote\Documents\Programs\DS3ML3_Final_Project\.venv\Lib\site-packages\torch\serialization.py", line 1026, in load
    return _load(opened_zipfile,
           ^^^^^^^^^^^^^^^^^^^^^
  File "C:\Users\Kyle_Remote\Documents\Programs\DS3ML3_Final_Project\.venv\Lib\site-packages\torch\serialization.py", line 1438, in _load
    result = unpickler.load()
             ^^^^^^^^^^^^^^^^
  File "C:\Users\Kyle_Remote\Documents\Programs\DS3ML3_Final_Project\.venv\Lib\site-packages\torch\serialization.py", line 1431, in find_class
    return super().find_class(mod_name, name)
           ^^^^^^^^^^^^^^^^^^^^^^^^^^^^^^^^^^
ModuleNotFoundError: No module named 'chess_SL_E5_lib'

2024-04-21 10:59:59,949 urllib3.connectionpool (connectionpool.py:292) DEBUG Resetting dropped connection: lichess.org
2024-04-21 11:00:00,589 urllib3.connectionpool (connectionpool.py:549) DEBUG https://lichess.org:443 "GET /api/bot/game/stream/IPPi87y5 HTTP/1.1" 200 None
2024-04-21 11:00:00,590 __mp_main__ (lichess-bot.py:605) DEBUG Initial state: {'id': 'IPPi87y5', 'variant': {'key': 'standard', 'name': 'Standard', 'short': 'Std'}, 'speed': 'blitz', 'perf': {'name': 'Blitz'}, 'rated': False, 'createdAt': 1713711580395, 'white': {'id': 'ks_chessai', 'name': 'KS_ChessAI', 'title': 'BOT', 'rating': 2000, 'provisional': True}, 'black': {'id': 'checkyle', 'name': 'ChecKyle', 'title': None, 'rating': 1410, 'provisional': True}, 'initialFen': 'startpos', 'clock': {'initial': 300000, 'increment': 1000}, 'type': 'gameFull', 'state': {'type': 'gameState', 'moves': '', 'wtime': 300000, 'btime': 300000, 'winc': 1000, 'binc': 1000, 'status': 'started'}}
2024-04-21 11:00:00,592 backoff (_common.py:105) INFO Backing off play_game(...) for 3.3s (ModuleNotFoundError: No module named 'chess_SL_E5_lib')
2024-04-21 11:00:00,592 lib.lichess (lichess.py:63) DEBUG Backing off 3.3 seconds after 5 tries calling function <function play_game at 0x0000017FA1C28680> with args () and kwargs {'li': <lib.lichess.Lichess object at 0x0000017FA1C26950>, 'control_queue': <AutoProxy[Queue] object, typeid 'Queue' at 0x17fa1c80690>, 'user_profile': {'id': 'ks_chessai', 'username': 'KS_ChessAI', 'perfs': {'bullet': {'games': 0, 'rating': 2000, 'rd': 500, 'prog': 0, 'prov': True}, 'blitz': {'games': 0, 'rating': 2000, 'rd': 500, 'prog': 0, 'prov': True}, 'rapid': {'games': 0, 'rating': 2000, 'rd': 500, 'prog': 0, 'prov': True}, 'classical': {'games': 0, 'rating': 2000, 'rd': 500, 'prog': 0, 'prov': True}, 'correspondence': {'games': 0, 'rating': 2000, 'rd': 500, 'prog': 0, 'prov': True}}, 'title': 'BOT', 'createdAt': 1711486329716, 'seenAt': 1713625564792, 'playTime': {'total': 15628, 'tv': 0}, 'url': 'https://lichess.org/@/KS_ChessAI', 'count': {'all': 113, 'rated': 0, 'ai': 0, 'draw': 11, 'drawH': 11, 'loss': 89, 'lossH': 89, 'win': 13, 'winH': 13, 'bookmark': 0, 'playing': 0, 'import': 0, 'me': 0}, 'followable': True, 'following': False, 'blocking': False, 'followsYou': False}, 'config': <lib.config.Configuration object at 0x0000017FA1C81F10>, 'challenge_queue': <ListProxy object, typeid 'list' at 0x17fa1c88550>, 'correspondence_queue': <AutoProxy[Queue] object, typeid 'Queue' at 0x17fa1c88790>, 'logging_queue': <AutoProxy[Queue] object, typeid 'Queue' at 0x17fa1c889d0>, 'game_id': 'IPPi87y5'}
2024-04-21 11:00:00,593 lib.lichess (lichess.py:65) DEBUG Exception: Traceback (most recent call last):
  File "C:\Users\Kyle_Remote\Documents\Programs\DS3ML3_Final_Project\.venv\Lib\site-packages\backoff\_sync.py", line 105, in retry
    ret = target(*args, **kwargs)
          ^^^^^^^^^^^^^^^^^^^^^^^
  File "C:\Users\Kyle_Remote\Documents\Programs\DS3ML3_Final_Project\lichess-bot\lichess-bot.py", line 609, in play_game
    with engine_wrapper.create_engine(config, game) as engine:
         ^^^^^^^^^^^^^^^^^^^^^^^^^^^^^^^^^^^^^^^^^^
  File "C:\Users\Kyle_Remote\Documents\Programs\DS3ML3_Final_Project\lichess-bot\lib\engine_wrapper.py", line 63, in create_engine
    Engine = getHomemadeEngine(cfg.name)
             ^^^^^^^^^^^^^^^^^^^^^^^^^^^
  File "C:\Users\Kyle_Remote\Documents\Programs\DS3ML3_Final_Project\lichess-bot\lib\engine_wrapper.py", line 620, in getHomemadeEngine
    import homemade
  File "C:\Users\Kyle_Remote\Documents\Programs\DS3ML3_Final_Project\lichess-bot\homemade.py", line 27, in <module>
    model_loaded = torch.load('../models_EL/model_E7-2.pth', map_location=device)
                   ^^^^^^^^^^^^^^^^^^^^^^^^^^^^^^^^^^^^^^^^^^^^^^^^^^^^^^^^^^^^^^
  File "C:\Users\Kyle_Remote\Documents\Programs\DS3ML3_Final_Project\.venv\Lib\site-packages\torch\serialization.py", line 1026, in load
    return _load(opened_zipfile,
           ^^^^^^^^^^^^^^^^^^^^^
  File "C:\Users\Kyle_Remote\Documents\Programs\DS3ML3_Final_Project\.venv\Lib\site-packages\torch\serialization.py", line 1438, in _load
    result = unpickler.load()
             ^^^^^^^^^^^^^^^^
  File "C:\Users\Kyle_Remote\Documents\Programs\DS3ML3_Final_Project\.venv\Lib\site-packages\torch\serialization.py", line 1431, in find_class
    return super().find_class(mod_name, name)
           ^^^^^^^^^^^^^^^^^^^^^^^^^^^^^^^^^^
ModuleNotFoundError: No module named 'chess_SL_E5_lib'

2024-04-21 11:00:03,881 urllib3.connectionpool (connectionpool.py:292) DEBUG Resetting dropped connection: lichess.org
2024-04-21 11:00:04,449 urllib3.connectionpool (connectionpool.py:549) DEBUG https://lichess.org:443 "GET /api/bot/game/stream/IPPi87y5 HTTP/1.1" 200 None
2024-04-21 11:00:04,450 __mp_main__ (lichess-bot.py:605) DEBUG Initial state: {'id': 'IPPi87y5', 'variant': {'key': 'standard', 'name': 'Standard', 'short': 'Std'}, 'speed': 'blitz', 'perf': {'name': 'Blitz'}, 'rated': False, 'createdAt': 1713711580395, 'white': {'id': 'ks_chessai', 'name': 'KS_ChessAI', 'title': 'BOT', 'rating': 2000, 'provisional': True}, 'black': {'id': 'checkyle', 'name': 'ChecKyle', 'title': None, 'rating': 1410, 'provisional': True}, 'initialFen': 'startpos', 'clock': {'initial': 300000, 'increment': 1000}, 'type': 'gameFull', 'state': {'type': 'gameState', 'moves': '', 'wtime': 300000, 'btime': 300000, 'winc': 1000, 'binc': 1000, 'status': 'started'}}
2024-04-21 11:00:04,452 backoff (_common.py:105) INFO Backing off play_game(...) for 8.7s (ModuleNotFoundError: No module named 'chess_SL_E5_lib')
2024-04-21 11:00:04,452 lib.lichess (lichess.py:63) DEBUG Backing off 8.7 seconds after 6 tries calling function <function play_game at 0x0000017FA1C28680> with args () and kwargs {'li': <lib.lichess.Lichess object at 0x0000017FA1C26950>, 'control_queue': <AutoProxy[Queue] object, typeid 'Queue' at 0x17fa1c80690>, 'user_profile': {'id': 'ks_chessai', 'username': 'KS_ChessAI', 'perfs': {'bullet': {'games': 0, 'rating': 2000, 'rd': 500, 'prog': 0, 'prov': True}, 'blitz': {'games': 0, 'rating': 2000, 'rd': 500, 'prog': 0, 'prov': True}, 'rapid': {'games': 0, 'rating': 2000, 'rd': 500, 'prog': 0, 'prov': True}, 'classical': {'games': 0, 'rating': 2000, 'rd': 500, 'prog': 0, 'prov': True}, 'correspondence': {'games': 0, 'rating': 2000, 'rd': 500, 'prog': 0, 'prov': True}}, 'title': 'BOT', 'createdAt': 1711486329716, 'seenAt': 1713625564792, 'playTime': {'total': 15628, 'tv': 0}, 'url': 'https://lichess.org/@/KS_ChessAI', 'count': {'all': 113, 'rated': 0, 'ai': 0, 'draw': 11, 'drawH': 11, 'loss': 89, 'lossH': 89, 'win': 13, 'winH': 13, 'bookmark': 0, 'playing': 0, 'import': 0, 'me': 0}, 'followable': True, 'following': False, 'blocking': False, 'followsYou': False}, 'config': <lib.config.Configuration object at 0x0000017FA1C81F10>, 'challenge_queue': <ListProxy object, typeid 'list' at 0x17fa1c88550>, 'correspondence_queue': <AutoProxy[Queue] object, typeid 'Queue' at 0x17fa1c88790>, 'logging_queue': <AutoProxy[Queue] object, typeid 'Queue' at 0x17fa1c889d0>, 'game_id': 'IPPi87y5'}
2024-04-21 11:00:04,453 lib.lichess (lichess.py:65) DEBUG Exception: Traceback (most recent call last):
  File "C:\Users\Kyle_Remote\Documents\Programs\DS3ML3_Final_Project\.venv\Lib\site-packages\backoff\_sync.py", line 105, in retry
    ret = target(*args, **kwargs)
          ^^^^^^^^^^^^^^^^^^^^^^^
  File "C:\Users\Kyle_Remote\Documents\Programs\DS3ML3_Final_Project\lichess-bot\lichess-bot.py", line 609, in play_game
    with engine_wrapper.create_engine(config, game) as engine:
         ^^^^^^^^^^^^^^^^^^^^^^^^^^^^^^^^^^^^^^^^^^
  File "C:\Users\Kyle_Remote\Documents\Programs\DS3ML3_Final_Project\lichess-bot\lib\engine_wrapper.py", line 63, in create_engine
    Engine = getHomemadeEngine(cfg.name)
             ^^^^^^^^^^^^^^^^^^^^^^^^^^^
  File "C:\Users\Kyle_Remote\Documents\Programs\DS3ML3_Final_Project\lichess-bot\lib\engine_wrapper.py", line 620, in getHomemadeEngine
    import homemade
  File "C:\Users\Kyle_Remote\Documents\Programs\DS3ML3_Final_Project\lichess-bot\homemade.py", line 27, in <module>
    model_loaded = torch.load('../models_EL/model_E7-2.pth', map_location=device)
                   ^^^^^^^^^^^^^^^^^^^^^^^^^^^^^^^^^^^^^^^^^^^^^^^^^^^^^^^^^^^^^^
  File "C:\Users\Kyle_Remote\Documents\Programs\DS3ML3_Final_Project\.venv\Lib\site-packages\torch\serialization.py", line 1026, in load
    return _load(opened_zipfile,
           ^^^^^^^^^^^^^^^^^^^^^
  File "C:\Users\Kyle_Remote\Documents\Programs\DS3ML3_Final_Project\.venv\Lib\site-packages\torch\serialization.py", line 1438, in _load
    result = unpickler.load()
             ^^^^^^^^^^^^^^^^
  File "C:\Users\Kyle_Remote\Documents\Programs\DS3ML3_Final_Project\.venv\Lib\site-packages\torch\serialization.py", line 1431, in find_class
    return super().find_class(mod_name, name)
           ^^^^^^^^^^^^^^^^^^^^^^^^^^^^^^^^^^
ModuleNotFoundError: No module named 'chess_SL_E5_lib'

2024-04-21 11:00:10,956 __main__ (lichess-bot.py:404) DEBUG Event: {'type': 'correspondence_ping'}
2024-04-21 11:00:13,121 urllib3.connectionpool (connectionpool.py:292) DEBUG Resetting dropped connection: lichess.org
2024-04-21 11:00:13,658 urllib3.connectionpool (connectionpool.py:549) DEBUG https://lichess.org:443 "GET /api/bot/game/stream/IPPi87y5 HTTP/1.1" 200 None
2024-04-21 11:00:13,658 __mp_main__ (lichess-bot.py:605) DEBUG Initial state: {'id': 'IPPi87y5', 'variant': {'key': 'standard', 'name': 'Standard', 'short': 'Std'}, 'speed': 'blitz', 'perf': {'name': 'Blitz'}, 'rated': False, 'createdAt': 1713711580395, 'white': {'id': 'ks_chessai', 'name': 'KS_ChessAI', 'title': 'BOT', 'rating': 2000, 'provisional': True}, 'black': {'id': 'checkyle', 'name': 'ChecKyle', 'title': None, 'rating': 1410, 'provisional': True}, 'initialFen': 'startpos', 'clock': {'initial': 300000, 'increment': 1000}, 'type': 'gameFull', 'state': {'type': 'gameState', 'moves': '', 'wtime': 300000, 'btime': 300000, 'winc': 1000, 'binc': 1000, 'status': 'started'}}
2024-04-21 11:00:13,660 backoff (_common.py:105) INFO Backing off play_game(...) for 44.4s (ModuleNotFoundError: No module named 'chess_SL_E5_lib')
2024-04-21 11:00:13,660 lib.lichess (lichess.py:63) DEBUG Backing off 44.4 seconds after 7 tries calling function <function play_game at 0x0000017FA1C28680> with args () and kwargs {'li': <lib.lichess.Lichess object at 0x0000017FA1C26950>, 'control_queue': <AutoProxy[Queue] object, typeid 'Queue' at 0x17fa1c80690>, 'user_profile': {'id': 'ks_chessai', 'username': 'KS_ChessAI', 'perfs': {'bullet': {'games': 0, 'rating': 2000, 'rd': 500, 'prog': 0, 'prov': True}, 'blitz': {'games': 0, 'rating': 2000, 'rd': 500, 'prog': 0, 'prov': True}, 'rapid': {'games': 0, 'rating': 2000, 'rd': 500, 'prog': 0, 'prov': True}, 'classical': {'games': 0, 'rating': 2000, 'rd': 500, 'prog': 0, 'prov': True}, 'correspondence': {'games': 0, 'rating': 2000, 'rd': 500, 'prog': 0, 'prov': True}}, 'title': 'BOT', 'createdAt': 1711486329716, 'seenAt': 1713625564792, 'playTime': {'total': 15628, 'tv': 0}, 'url': 'https://lichess.org/@/KS_ChessAI', 'count': {'all': 113, 'rated': 0, 'ai': 0, 'draw': 11, 'drawH': 11, 'loss': 89, 'lossH': 89, 'win': 13, 'winH': 13, 'bookmark': 0, 'playing': 0, 'import': 0, 'me': 0}, 'followable': True, 'following': False, 'blocking': False, 'followsYou': False}, 'config': <lib.config.Configuration object at 0x0000017FA1C81F10>, 'challenge_queue': <ListProxy object, typeid 'list' at 0x17fa1c88550>, 'correspondence_queue': <AutoProxy[Queue] object, typeid 'Queue' at 0x17fa1c88790>, 'logging_queue': <AutoProxy[Queue] object, typeid 'Queue' at 0x17fa1c889d0>, 'game_id': 'IPPi87y5'}
2024-04-21 11:00:13,662 lib.lichess (lichess.py:65) DEBUG Exception: Traceback (most recent call last):
  File "C:\Users\Kyle_Remote\Documents\Programs\DS3ML3_Final_Project\.venv\Lib\site-packages\backoff\_sync.py", line 105, in retry
    ret = target(*args, **kwargs)
          ^^^^^^^^^^^^^^^^^^^^^^^
  File "C:\Users\Kyle_Remote\Documents\Programs\DS3ML3_Final_Project\lichess-bot\lichess-bot.py", line 609, in play_game
    with engine_wrapper.create_engine(config, game) as engine:
         ^^^^^^^^^^^^^^^^^^^^^^^^^^^^^^^^^^^^^^^^^^
  File "C:\Users\Kyle_Remote\Documents\Programs\DS3ML3_Final_Project\lichess-bot\lib\engine_wrapper.py", line 63, in create_engine
    Engine = getHomemadeEngine(cfg.name)
             ^^^^^^^^^^^^^^^^^^^^^^^^^^^
  File "C:\Users\Kyle_Remote\Documents\Programs\DS3ML3_Final_Project\lichess-bot\lib\engine_wrapper.py", line 620, in getHomemadeEngine
    import homemade
  File "C:\Users\Kyle_Remote\Documents\Programs\DS3ML3_Final_Project\lichess-bot\homemade.py", line 27, in <module>
    model_loaded = torch.load('../models_EL/model_E7-2.pth', map_location=device)
                   ^^^^^^^^^^^^^^^^^^^^^^^^^^^^^^^^^^^^^^^^^^^^^^^^^^^^^^^^^^^^^^
  File "C:\Users\Kyle_Remote\Documents\Programs\DS3ML3_Final_Project\.venv\Lib\site-packages\torch\serialization.py", line 1026, in load
    return _load(opened_zipfile,
           ^^^^^^^^^^^^^^^^^^^^^
  File "C:\Users\Kyle_Remote\Documents\Programs\DS3ML3_Final_Project\.venv\Lib\site-packages\torch\serialization.py", line 1438, in _load
    result = unpickler.load()
             ^^^^^^^^^^^^^^^^
  File "C:\Users\Kyle_Remote\Documents\Programs\DS3ML3_Final_Project\.venv\Lib\site-packages\torch\serialization.py", line 1431, in find_class
    return super().find_class(mod_name, name)
           ^^^^^^^^^^^^^^^^^^^^^^^^^^^^^^^^^^
ModuleNotFoundError: No module named 'chess_SL_E5_lib'

2024-04-21 11:00:32,390 __main__ (lichess-bot.py:404) DEBUG Event: {'type': 'gameFinish', 'game': {'fullId': 'IPPi87y5tcrF', 'gameId': 'IPPi87y5', 'fen': 'rnbqkbnr/pppppppp/8/8/8/8/PPPPPPPP/RNBQKBNR w KQkq - 0 1', 'color': 'white', 'lastMove': '', 'source': 'friend', 'status': {'id': 25, 'name': 'aborted'}, 'variant': {'key': 'standard', 'name': 'Standard'}, 'speed': 'blitz', 'perf': 'blitz', 'rated': False, 'hasMoved': False, 'opponent': {'id': 'checkyle', 'username': 'ChecKyle', 'rating': 1410}, 'isMyTurn': False, 'secondsLeft': 300, 'compat': {'bot': True, 'board': True}, 'id': 'IPPi87y5'}}
2024-04-21 11:00:33,537 __main__ (lichess-bot.py:404) DEBUG Event: {'type': 'challenge', 'challenge': {'id': 'xNawCt5b', 'url': 'https://lichess.org/xNawCt5b', 'status': 'created', 'challenger': {'id': 'checkyle', 'name': 'ChecKyle', 'rating': 1410, 'title': None, 'provisional': True, 'online': True, 'lag': 4}, 'destUser': {'id': 'ks_chessai', 'name': 'KS_ChessAI', 'rating': 2000, 'title': 'BOT', 'provisional': True, 'online': True}, 'variant': {'key': 'standard', 'name': 'Standard', 'short': 'Std'}, 'rated': False, 'speed': 'blitz', 'timeControl': {'type': 'clock', 'limit': 300, 'increment': 1, 'show': '5+1'}, 'color': 'white', 'finalColor': 'white', 'perf': {'icon': '\ue01d', 'name': 'Blitz'}, 'rematchOf': 'IPPi87y5'}, 'compat': {'bot': True, 'board': True}}
2024-04-21 11:00:33,541 __main__ (lichess-bot.py:455) INFO Accept Blitz casual challenge from ChecKyle (1410?) (xNawCt5b)
2024-04-21 11:00:33,543 urllib3.connectionpool (connectionpool.py:292) DEBUG Resetting dropped connection: lichess.org
2024-04-21 11:00:34,068 urllib3.connectionpool (connectionpool.py:549) DEBUG https://lichess.org:443 "POST /api/challenge/xNawCt5b/accept HTTP/1.1" 200 11
2024-04-21 11:00:34,068 __main__ (lichess-bot.py:274) INFO --- Process Queued. Count: 2. IDs: {'xNawCt5b', 'IPPi87y5'}
2024-04-21 11:00:34,188 __main__ (lichess-bot.py:404) DEBUG Event: {'type': 'gameStart', 'game': {'fullId': 'xNawCt5bay5b', 'gameId': 'xNawCt5b', 'fen': 'rnbqkbnr/pppppppp/8/8/8/8/PPPPPPPP/RNBQKBNR w KQkq - 0 1', 'color': 'black', 'lastMove': '', 'source': 'friend', 'status': {'id': 20, 'name': 'started'}, 'variant': {'key': 'standard', 'name': 'Standard'}, 'speed': 'blitz', 'perf': 'blitz', 'rated': False, 'hasMoved': False, 'opponent': {'id': 'checkyle', 'username': 'ChecKyle', 'rating': 1410}, 'isMyTurn': False, 'secondsLeft': 300, 'compat': {'bot': True, 'board': True}, 'id': 'xNawCt5b'}}
2024-04-21 11:00:34,188 __main__ (lichess-bot.py:274) INFO --- Process Used. Count: 2. IDs: {'xNawCt5b', 'IPPi87y5'}
2024-04-21 11:00:34,282 urllib3.connectionpool (connectionpool.py:1055) DEBUG Starting new HTTPS connection (1): lichess.org:443
2024-04-21 11:00:34,845 urllib3.connectionpool (connectionpool.py:549) DEBUG https://lichess.org:443 "GET /api/bot/game/stream/xNawCt5b HTTP/1.1" 200 None
2024-04-21 11:00:34,846 __mp_main__ (lichess-bot.py:605) DEBUG Initial state: {'id': 'xNawCt5b', 'variant': {'key': 'standard', 'name': 'Standard', 'short': 'Std'}, 'speed': 'blitz', 'perf': {'name': 'Blitz'}, 'rated': False, 'createdAt': 1713711634124, 'white': {'id': 'checkyle', 'name': 'ChecKyle', 'title': None, 'rating': 1410, 'provisional': True}, 'black': {'id': 'ks_chessai', 'name': 'KS_ChessAI', 'title': 'BOT', 'rating': 2000, 'provisional': True}, 'initialFen': 'startpos', 'clock': {'initial': 300000, 'increment': 1000}, 'type': 'gameFull', 'state': {'type': 'gameState', 'moves': '', 'wtime': 300000, 'btime': 300000, 'winc': 1000, 'binc': 1000, 'status': 'started'}}
2024-04-21 11:00:34,994 matplotlib (__init__.py:350) DEBUG matplotlib data path: C:\Users\Kyle_Remote\Documents\Programs\DS3ML3_Final_Project\.venv\Lib\site-packages\matplotlib\mpl-data
2024-04-21 11:00:34,997 matplotlib (__init__.py:350) DEBUG CONFIGDIR=C:\Users\Kyle_Remote\.matplotlib
2024-04-21 11:00:34,999 matplotlib (__init__.py:1511) DEBUG interactive is False
2024-04-21 11:00:34,999 matplotlib (__init__.py:1512) DEBUG platform is win32
2024-04-21 11:00:35,064 matplotlib (__init__.py:350) DEBUG CACHEDIR=C:\Users\Kyle_Remote\.matplotlib
2024-04-21 11:00:35,066 matplotlib.font_manager (font_manager.py:1574) DEBUG Using fontManager instance from C:\Users\Kyle_Remote\.matplotlib\fontlist-v330.json
2024-04-21 11:00:36,884 backoff (_common.py:105) INFO Backing off play_game(...) for 0.0s (ModuleNotFoundError: No module named 'chess_SL_E5_lib')
2024-04-21 11:00:36,884 lib.lichess (lichess.py:63) DEBUG Backing off 0.0 seconds after 1 tries calling function <function play_game at 0x0000020C53F48680> with args () and kwargs {'li': <lib.lichess.Lichess object at 0x0000020C53F46950>, 'control_queue': <AutoProxy[Queue] object, typeid 'Queue' at 0x20c53fa0690>, 'user_profile': {'id': 'ks_chessai', 'username': 'KS_ChessAI', 'perfs': {'bullet': {'games': 0, 'rating': 2000, 'rd': 500, 'prog': 0, 'prov': True}, 'blitz': {'games': 0, 'rating': 2000, 'rd': 500, 'prog': 0, 'prov': True}, 'rapid': {'games': 0, 'rating': 2000, 'rd': 500, 'prog': 0, 'prov': True}, 'classical': {'games': 0, 'rating': 2000, 'rd': 500, 'prog': 0, 'prov': True}, 'correspondence': {'games': 0, 'rating': 2000, 'rd': 500, 'prog': 0, 'prov': True}}, 'title': 'BOT', 'createdAt': 1711486329716, 'seenAt': 1713625564792, 'playTime': {'total': 15628, 'tv': 0}, 'url': 'https://lichess.org/@/KS_ChessAI', 'count': {'all': 113, 'rated': 0, 'ai': 0, 'draw': 11, 'drawH': 11, 'loss': 89, 'lossH': 89, 'win': 13, 'winH': 13, 'bookmark': 0, 'playing': 0, 'import': 0, 'me': 0}, 'followable': True, 'following': False, 'blocking': False, 'followsYou': False}, 'config': <lib.config.Configuration object at 0x0000020C53FA1F10>, 'challenge_queue': <ListProxy object, typeid 'list' at 0x20c53fa8550>, 'correspondence_queue': <AutoProxy[Queue] object, typeid 'Queue' at 0x20c53fa8790>, 'logging_queue': <AutoProxy[Queue] object, typeid 'Queue' at 0x20c53fa89d0>, 'game_id': 'xNawCt5b'}
2024-04-21 11:00:36,885 lib.lichess (lichess.py:65) DEBUG Exception: Traceback (most recent call last):
  File "C:\Users\Kyle_Remote\Documents\Programs\DS3ML3_Final_Project\.venv\Lib\site-packages\backoff\_sync.py", line 105, in retry
    ret = target(*args, **kwargs)
          ^^^^^^^^^^^^^^^^^^^^^^^
  File "C:\Users\Kyle_Remote\Documents\Programs\DS3ML3_Final_Project\lichess-bot\lichess-bot.py", line 609, in play_game
    with engine_wrapper.create_engine(config, game) as engine:
         ^^^^^^^^^^^^^^^^^^^^^^^^^^^^^^^^^^^^^^^^^^
  File "C:\Users\Kyle_Remote\Documents\Programs\DS3ML3_Final_Project\lichess-bot\lib\engine_wrapper.py", line 63, in create_engine
    Engine = getHomemadeEngine(cfg.name)
             ^^^^^^^^^^^^^^^^^^^^^^^^^^^
  File "C:\Users\Kyle_Remote\Documents\Programs\DS3ML3_Final_Project\lichess-bot\lib\engine_wrapper.py", line 620, in getHomemadeEngine
    import homemade
  File "C:\Users\Kyle_Remote\Documents\Programs\DS3ML3_Final_Project\lichess-bot\homemade.py", line 27, in <module>
    model_loaded = torch.load('../models_EL/model_E7-2.pth', map_location=device)
                   ^^^^^^^^^^^^^^^^^^^^^^^^^^^^^^^^^^^^^^^^^^^^^^^^^^^^^^^^^^^^^^
  File "C:\Users\Kyle_Remote\Documents\Programs\DS3ML3_Final_Project\.venv\Lib\site-packages\torch\serialization.py", line 1026, in load
    return _load(opened_zipfile,
           ^^^^^^^^^^^^^^^^^^^^^
  File "C:\Users\Kyle_Remote\Documents\Programs\DS3ML3_Final_Project\.venv\Lib\site-packages\torch\serialization.py", line 1438, in _load
    result = unpickler.load()
             ^^^^^^^^^^^^^^^^
  File "C:\Users\Kyle_Remote\Documents\Programs\DS3ML3_Final_Project\.venv\Lib\site-packages\torch\serialization.py", line 1431, in find_class
    return super().find_class(mod_name, name)
           ^^^^^^^^^^^^^^^^^^^^^^^^^^^^^^^^^^
ModuleNotFoundError: No module named 'chess_SL_E5_lib'

2024-04-21 11:00:36,893 urllib3.connectionpool (connectionpool.py:1055) DEBUG Starting new HTTPS connection (2): lichess.org:443
2024-04-21 11:00:37,425 urllib3.connectionpool (connectionpool.py:549) DEBUG https://lichess.org:443 "GET /api/bot/game/stream/xNawCt5b HTTP/1.1" 200 None
2024-04-21 11:00:37,426 __mp_main__ (lichess-bot.py:605) DEBUG Initial state: {'id': 'xNawCt5b', 'variant': {'key': 'standard', 'name': 'Standard', 'short': 'Std'}, 'speed': 'blitz', 'perf': {'name': 'Blitz'}, 'rated': False, 'createdAt': 1713711634124, 'white': {'id': 'checkyle', 'name': 'ChecKyle', 'title': None, 'rating': 1410, 'provisional': True}, 'black': {'id': 'ks_chessai', 'name': 'KS_ChessAI', 'title': 'BOT', 'rating': 2000, 'provisional': True}, 'initialFen': 'startpos', 'clock': {'initial': 300000, 'increment': 1000}, 'type': 'gameFull', 'state': {'type': 'gameState', 'moves': 'e2e4', 'wtime': 300000, 'btime': 300000, 'winc': 1000, 'binc': 1000, 'status': 'started'}}
2024-04-21 11:00:37,428 backoff (_common.py:105) INFO Backing off play_game(...) for 0.9s (ModuleNotFoundError: No module named 'chess_SL_E5_lib')
2024-04-21 11:00:37,428 lib.lichess (lichess.py:63) DEBUG Backing off 0.9 seconds after 2 tries calling function <function play_game at 0x0000020C53F48680> with args () and kwargs {'li': <lib.lichess.Lichess object at 0x0000020C53F46950>, 'control_queue': <AutoProxy[Queue] object, typeid 'Queue' at 0x20c53fa0690>, 'user_profile': {'id': 'ks_chessai', 'username': 'KS_ChessAI', 'perfs': {'bullet': {'games': 0, 'rating': 2000, 'rd': 500, 'prog': 0, 'prov': True}, 'blitz': {'games': 0, 'rating': 2000, 'rd': 500, 'prog': 0, 'prov': True}, 'rapid': {'games': 0, 'rating': 2000, 'rd': 500, 'prog': 0, 'prov': True}, 'classical': {'games': 0, 'rating': 2000, 'rd': 500, 'prog': 0, 'prov': True}, 'correspondence': {'games': 0, 'rating': 2000, 'rd': 500, 'prog': 0, 'prov': True}}, 'title': 'BOT', 'createdAt': 1711486329716, 'seenAt': 1713625564792, 'playTime': {'total': 15628, 'tv': 0}, 'url': 'https://lichess.org/@/KS_ChessAI', 'count': {'all': 113, 'rated': 0, 'ai': 0, 'draw': 11, 'drawH': 11, 'loss': 89, 'lossH': 89, 'win': 13, 'winH': 13, 'bookmark': 0, 'playing': 0, 'import': 0, 'me': 0}, 'followable': True, 'following': False, 'blocking': False, 'followsYou': False}, 'config': <lib.config.Configuration object at 0x0000020C53FA1F10>, 'challenge_queue': <ListProxy object, typeid 'list' at 0x20c53fa8550>, 'correspondence_queue': <AutoProxy[Queue] object, typeid 'Queue' at 0x20c53fa8790>, 'logging_queue': <AutoProxy[Queue] object, typeid 'Queue' at 0x20c53fa89d0>, 'game_id': 'xNawCt5b'}
2024-04-21 11:00:37,429 lib.lichess (lichess.py:65) DEBUG Exception: Traceback (most recent call last):
  File "C:\Users\Kyle_Remote\Documents\Programs\DS3ML3_Final_Project\.venv\Lib\site-packages\backoff\_sync.py", line 105, in retry
    ret = target(*args, **kwargs)
          ^^^^^^^^^^^^^^^^^^^^^^^
  File "C:\Users\Kyle_Remote\Documents\Programs\DS3ML3_Final_Project\lichess-bot\lichess-bot.py", line 609, in play_game
    with engine_wrapper.create_engine(config, game) as engine:
         ^^^^^^^^^^^^^^^^^^^^^^^^^^^^^^^^^^^^^^^^^^
  File "C:\Users\Kyle_Remote\Documents\Programs\DS3ML3_Final_Project\lichess-bot\lib\engine_wrapper.py", line 63, in create_engine
    Engine = getHomemadeEngine(cfg.name)
             ^^^^^^^^^^^^^^^^^^^^^^^^^^^
  File "C:\Users\Kyle_Remote\Documents\Programs\DS3ML3_Final_Project\lichess-bot\lib\engine_wrapper.py", line 620, in getHomemadeEngine
    import homemade
  File "C:\Users\Kyle_Remote\Documents\Programs\DS3ML3_Final_Project\lichess-bot\homemade.py", line 27, in <module>
    model_loaded = torch.load('../models_EL/model_E7-2.pth', map_location=device)
                   ^^^^^^^^^^^^^^^^^^^^^^^^^^^^^^^^^^^^^^^^^^^^^^^^^^^^^^^^^^^^^^
  File "C:\Users\Kyle_Remote\Documents\Programs\DS3ML3_Final_Project\.venv\Lib\site-packages\torch\serialization.py", line 1026, in load
    return _load(opened_zipfile,
           ^^^^^^^^^^^^^^^^^^^^^
  File "C:\Users\Kyle_Remote\Documents\Programs\DS3ML3_Final_Project\.venv\Lib\site-packages\torch\serialization.py", line 1438, in _load
    result = unpickler.load()
             ^^^^^^^^^^^^^^^^
  File "C:\Users\Kyle_Remote\Documents\Programs\DS3ML3_Final_Project\.venv\Lib\site-packages\torch\serialization.py", line 1431, in find_class
    return super().find_class(mod_name, name)
           ^^^^^^^^^^^^^^^^^^^^^^^^^^^^^^^^^^
ModuleNotFoundError: No module named 'chess_SL_E5_lib'

2024-04-21 11:00:38,334 urllib3.connectionpool (connectionpool.py:292) DEBUG Resetting dropped connection: lichess.org
2024-04-21 11:00:38,873 urllib3.connectionpool (connectionpool.py:549) DEBUG https://lichess.org:443 "GET /api/bot/game/stream/xNawCt5b HTTP/1.1" 200 None
2024-04-21 11:00:38,874 __mp_main__ (lichess-bot.py:605) DEBUG Initial state: {'id': 'xNawCt5b', 'variant': {'key': 'standard', 'name': 'Standard', 'short': 'Std'}, 'speed': 'blitz', 'perf': {'name': 'Blitz'}, 'rated': False, 'createdAt': 1713711634124, 'white': {'id': 'checkyle', 'name': 'ChecKyle', 'title': None, 'rating': 1410, 'provisional': True}, 'black': {'id': 'ks_chessai', 'name': 'KS_ChessAI', 'title': 'BOT', 'rating': 2000, 'provisional': True}, 'initialFen': 'startpos', 'clock': {'initial': 300000, 'increment': 1000}, 'type': 'gameFull', 'state': {'type': 'gameState', 'moves': 'e2e4', 'wtime': 300000, 'btime': 300000, 'winc': 1000, 'binc': 1000, 'status': 'started'}}
2024-04-21 11:00:38,876 backoff (_common.py:105) INFO Backing off play_game(...) for 3.4s (ModuleNotFoundError: No module named 'chess_SL_E5_lib')
2024-04-21 11:00:38,877 lib.lichess (lichess.py:63) DEBUG Backing off 3.4 seconds after 3 tries calling function <function play_game at 0x0000020C53F48680> with args () and kwargs {'li': <lib.lichess.Lichess object at 0x0000020C53F46950>, 'control_queue': <AutoProxy[Queue] object, typeid 'Queue' at 0x20c53fa0690>, 'user_profile': {'id': 'ks_chessai', 'username': 'KS_ChessAI', 'perfs': {'bullet': {'games': 0, 'rating': 2000, 'rd': 500, 'prog': 0, 'prov': True}, 'blitz': {'games': 0, 'rating': 2000, 'rd': 500, 'prog': 0, 'prov': True}, 'rapid': {'games': 0, 'rating': 2000, 'rd': 500, 'prog': 0, 'prov': True}, 'classical': {'games': 0, 'rating': 2000, 'rd': 500, 'prog': 0, 'prov': True}, 'correspondence': {'games': 0, 'rating': 2000, 'rd': 500, 'prog': 0, 'prov': True}}, 'title': 'BOT', 'createdAt': 1711486329716, 'seenAt': 1713625564792, 'playTime': {'total': 15628, 'tv': 0}, 'url': 'https://lichess.org/@/KS_ChessAI', 'count': {'all': 113, 'rated': 0, 'ai': 0, 'draw': 11, 'drawH': 11, 'loss': 89, 'lossH': 89, 'win': 13, 'winH': 13, 'bookmark': 0, 'playing': 0, 'import': 0, 'me': 0}, 'followable': True, 'following': False, 'blocking': False, 'followsYou': False}, 'config': <lib.config.Configuration object at 0x0000020C53FA1F10>, 'challenge_queue': <ListProxy object, typeid 'list' at 0x20c53fa8550>, 'correspondence_queue': <AutoProxy[Queue] object, typeid 'Queue' at 0x20c53fa8790>, 'logging_queue': <AutoProxy[Queue] object, typeid 'Queue' at 0x20c53fa89d0>, 'game_id': 'xNawCt5b'}
2024-04-21 11:00:38,878 lib.lichess (lichess.py:65) DEBUG Exception: Traceback (most recent call last):
  File "C:\Users\Kyle_Remote\Documents\Programs\DS3ML3_Final_Project\.venv\Lib\site-packages\backoff\_sync.py", line 105, in retry
    ret = target(*args, **kwargs)
          ^^^^^^^^^^^^^^^^^^^^^^^
  File "C:\Users\Kyle_Remote\Documents\Programs\DS3ML3_Final_Project\lichess-bot\lichess-bot.py", line 609, in play_game
    with engine_wrapper.create_engine(config, game) as engine:
         ^^^^^^^^^^^^^^^^^^^^^^^^^^^^^^^^^^^^^^^^^^
  File "C:\Users\Kyle_Remote\Documents\Programs\DS3ML3_Final_Project\lichess-bot\lib\engine_wrapper.py", line 63, in create_engine
    Engine = getHomemadeEngine(cfg.name)
             ^^^^^^^^^^^^^^^^^^^^^^^^^^^
  File "C:\Users\Kyle_Remote\Documents\Programs\DS3ML3_Final_Project\lichess-bot\lib\engine_wrapper.py", line 620, in getHomemadeEngine
    import homemade
  File "C:\Users\Kyle_Remote\Documents\Programs\DS3ML3_Final_Project\lichess-bot\homemade.py", line 27, in <module>
    model_loaded = torch.load('../models_EL/model_E7-2.pth', map_location=device)
                   ^^^^^^^^^^^^^^^^^^^^^^^^^^^^^^^^^^^^^^^^^^^^^^^^^^^^^^^^^^^^^^
  File "C:\Users\Kyle_Remote\Documents\Programs\DS3ML3_Final_Project\.venv\Lib\site-packages\torch\serialization.py", line 1026, in load
    return _load(opened_zipfile,
           ^^^^^^^^^^^^^^^^^^^^^
  File "C:\Users\Kyle_Remote\Documents\Programs\DS3ML3_Final_Project\.venv\Lib\site-packages\torch\serialization.py", line 1438, in _load
    result = unpickler.load()
             ^^^^^^^^^^^^^^^^
  File "C:\Users\Kyle_Remote\Documents\Programs\DS3ML3_Final_Project\.venv\Lib\site-packages\torch\serialization.py", line 1431, in find_class
    return super().find_class(mod_name, name)
           ^^^^^^^^^^^^^^^^^^^^^^^^^^^^^^^^^^
ModuleNotFoundError: No module named 'chess_SL_E5_lib'

2024-04-21 11:00:42,246 urllib3.connectionpool (connectionpool.py:292) DEBUG Resetting dropped connection: lichess.org
2024-04-21 11:00:42,767 urllib3.connectionpool (connectionpool.py:549) DEBUG https://lichess.org:443 "GET /api/bot/game/stream/xNawCt5b HTTP/1.1" 200 None
2024-04-21 11:00:42,767 __mp_main__ (lichess-bot.py:605) DEBUG Initial state: {'id': 'xNawCt5b', 'variant': {'key': 'standard', 'name': 'Standard', 'short': 'Std'}, 'speed': 'blitz', 'perf': {'name': 'Blitz'}, 'rated': False, 'createdAt': 1713711634124, 'white': {'id': 'checkyle', 'name': 'ChecKyle', 'title': None, 'rating': 1410, 'provisional': True}, 'black': {'id': 'ks_chessai', 'name': 'KS_ChessAI', 'title': 'BOT', 'rating': 2000, 'provisional': True}, 'initialFen': 'startpos', 'clock': {'initial': 300000, 'increment': 1000}, 'type': 'gameFull', 'state': {'type': 'gameState', 'moves': 'e2e4', 'wtime': 300000, 'btime': 300000, 'winc': 1000, 'binc': 1000, 'status': 'started'}}
2024-04-21 11:00:42,769 backoff (_common.py:105) INFO Backing off play_game(...) for 7.8s (ModuleNotFoundError: No module named 'chess_SL_E5_lib')
2024-04-21 11:00:42,769 lib.lichess (lichess.py:63) DEBUG Backing off 7.8 seconds after 4 tries calling function <function play_game at 0x0000020C53F48680> with args () and kwargs {'li': <lib.lichess.Lichess object at 0x0000020C53F46950>, 'control_queue': <AutoProxy[Queue] object, typeid 'Queue' at 0x20c53fa0690>, 'user_profile': {'id': 'ks_chessai', 'username': 'KS_ChessAI', 'perfs': {'bullet': {'games': 0, 'rating': 2000, 'rd': 500, 'prog': 0, 'prov': True}, 'blitz': {'games': 0, 'rating': 2000, 'rd': 500, 'prog': 0, 'prov': True}, 'rapid': {'games': 0, 'rating': 2000, 'rd': 500, 'prog': 0, 'prov': True}, 'classical': {'games': 0, 'rating': 2000, 'rd': 500, 'prog': 0, 'prov': True}, 'correspondence': {'games': 0, 'rating': 2000, 'rd': 500, 'prog': 0, 'prov': True}}, 'title': 'BOT', 'createdAt': 1711486329716, 'seenAt': 1713625564792, 'playTime': {'total': 15628, 'tv': 0}, 'url': 'https://lichess.org/@/KS_ChessAI', 'count': {'all': 113, 'rated': 0, 'ai': 0, 'draw': 11, 'drawH': 11, 'loss': 89, 'lossH': 89, 'win': 13, 'winH': 13, 'bookmark': 0, 'playing': 0, 'import': 0, 'me': 0}, 'followable': True, 'following': False, 'blocking': False, 'followsYou': False}, 'config': <lib.config.Configuration object at 0x0000020C53FA1F10>, 'challenge_queue': <ListProxy object, typeid 'list' at 0x20c53fa8550>, 'correspondence_queue': <AutoProxy[Queue] object, typeid 'Queue' at 0x20c53fa8790>, 'logging_queue': <AutoProxy[Queue] object, typeid 'Queue' at 0x20c53fa89d0>, 'game_id': 'xNawCt5b'}
2024-04-21 11:00:42,770 lib.lichess (lichess.py:65) DEBUG Exception: Traceback (most recent call last):
  File "C:\Users\Kyle_Remote\Documents\Programs\DS3ML3_Final_Project\.venv\Lib\site-packages\backoff\_sync.py", line 105, in retry
    ret = target(*args, **kwargs)
          ^^^^^^^^^^^^^^^^^^^^^^^
  File "C:\Users\Kyle_Remote\Documents\Programs\DS3ML3_Final_Project\lichess-bot\lichess-bot.py", line 609, in play_game
    with engine_wrapper.create_engine(config, game) as engine:
         ^^^^^^^^^^^^^^^^^^^^^^^^^^^^^^^^^^^^^^^^^^
  File "C:\Users\Kyle_Remote\Documents\Programs\DS3ML3_Final_Project\lichess-bot\lib\engine_wrapper.py", line 63, in create_engine
    Engine = getHomemadeEngine(cfg.name)
             ^^^^^^^^^^^^^^^^^^^^^^^^^^^
  File "C:\Users\Kyle_Remote\Documents\Programs\DS3ML3_Final_Project\lichess-bot\lib\engine_wrapper.py", line 620, in getHomemadeEngine
    import homemade
  File "C:\Users\Kyle_Remote\Documents\Programs\DS3ML3_Final_Project\lichess-bot\homemade.py", line 27, in <module>
    model_loaded = torch.load('../models_EL/model_E7-2.pth', map_location=device)
                   ^^^^^^^^^^^^^^^^^^^^^^^^^^^^^^^^^^^^^^^^^^^^^^^^^^^^^^^^^^^^^^
  File "C:\Users\Kyle_Remote\Documents\Programs\DS3ML3_Final_Project\.venv\Lib\site-packages\torch\serialization.py", line 1026, in load
    return _load(opened_zipfile,
           ^^^^^^^^^^^^^^^^^^^^^
  File "C:\Users\Kyle_Remote\Documents\Programs\DS3ML3_Final_Project\.venv\Lib\site-packages\torch\serialization.py", line 1438, in _load
    result = unpickler.load()
             ^^^^^^^^^^^^^^^^
  File "C:\Users\Kyle_Remote\Documents\Programs\DS3ML3_Final_Project\.venv\Lib\site-packages\torch\serialization.py", line 1431, in find_class
    return super().find_class(mod_name, name)
           ^^^^^^^^^^^^^^^^^^^^^^^^^^^^^^^^^^
ModuleNotFoundError: No module named 'chess_SL_E5_lib'

2024-04-21 11:00:50,527 urllib3.connectionpool (connectionpool.py:292) DEBUG Resetting dropped connection: lichess.org
2024-04-21 11:00:51,099 urllib3.connectionpool (connectionpool.py:549) DEBUG https://lichess.org:443 "GET /api/bot/game/stream/xNawCt5b HTTP/1.1" 200 None
2024-04-21 11:00:51,099 __mp_main__ (lichess-bot.py:605) DEBUG Initial state: {'id': 'xNawCt5b', 'variant': {'key': 'standard', 'name': 'Standard', 'short': 'Std'}, 'speed': 'blitz', 'perf': {'name': 'Blitz'}, 'rated': False, 'createdAt': 1713711634124, 'white': {'id': 'checkyle', 'name': 'ChecKyle', 'title': None, 'rating': 1410, 'provisional': True}, 'black': {'id': 'ks_chessai', 'name': 'KS_ChessAI', 'title': 'BOT', 'rating': 2000, 'provisional': True}, 'initialFen': 'startpos', 'clock': {'initial': 300000, 'increment': 1000}, 'type': 'gameFull', 'state': {'type': 'gameState', 'moves': 'e2e4', 'wtime': 300000, 'btime': 300000, 'winc': 1000, 'binc': 1000, 'status': 'started'}}
2024-04-21 11:00:51,101 backoff (_common.py:105) INFO Backing off play_game(...) for 14.4s (ModuleNotFoundError: No module named 'chess_SL_E5_lib')
2024-04-21 11:00:51,101 lib.lichess (lichess.py:63) DEBUG Backing off 14.4 seconds after 5 tries calling function <function play_game at 0x0000020C53F48680> with args () and kwargs {'li': <lib.lichess.Lichess object at 0x0000020C53F46950>, 'control_queue': <AutoProxy[Queue] object, typeid 'Queue' at 0x20c53fa0690>, 'user_profile': {'id': 'ks_chessai', 'username': 'KS_ChessAI', 'perfs': {'bullet': {'games': 0, 'rating': 2000, 'rd': 500, 'prog': 0, 'prov': True}, 'blitz': {'games': 0, 'rating': 2000, 'rd': 500, 'prog': 0, 'prov': True}, 'rapid': {'games': 0, 'rating': 2000, 'rd': 500, 'prog': 0, 'prov': True}, 'classical': {'games': 0, 'rating': 2000, 'rd': 500, 'prog': 0, 'prov': True}, 'correspondence': {'games': 0, 'rating': 2000, 'rd': 500, 'prog': 0, 'prov': True}}, 'title': 'BOT', 'createdAt': 1711486329716, 'seenAt': 1713625564792, 'playTime': {'total': 15628, 'tv': 0}, 'url': 'https://lichess.org/@/KS_ChessAI', 'count': {'all': 113, 'rated': 0, 'ai': 0, 'draw': 11, 'drawH': 11, 'loss': 89, 'lossH': 89, 'win': 13, 'winH': 13, 'bookmark': 0, 'playing': 0, 'import': 0, 'me': 0}, 'followable': True, 'following': False, 'blocking': False, 'followsYou': False}, 'config': <lib.config.Configuration object at 0x0000020C53FA1F10>, 'challenge_queue': <ListProxy object, typeid 'list' at 0x20c53fa8550>, 'correspondence_queue': <AutoProxy[Queue] object, typeid 'Queue' at 0x20c53fa8790>, 'logging_queue': <AutoProxy[Queue] object, typeid 'Queue' at 0x20c53fa89d0>, 'game_id': 'xNawCt5b'}
2024-04-21 11:00:51,102 lib.lichess (lichess.py:65) DEBUG Exception: Traceback (most recent call last):
  File "C:\Users\Kyle_Remote\Documents\Programs\DS3ML3_Final_Project\.venv\Lib\site-packages\backoff\_sync.py", line 105, in retry
    ret = target(*args, **kwargs)
          ^^^^^^^^^^^^^^^^^^^^^^^
  File "C:\Users\Kyle_Remote\Documents\Programs\DS3ML3_Final_Project\lichess-bot\lichess-bot.py", line 609, in play_game
    with engine_wrapper.create_engine(config, game) as engine:
         ^^^^^^^^^^^^^^^^^^^^^^^^^^^^^^^^^^^^^^^^^^
  File "C:\Users\Kyle_Remote\Documents\Programs\DS3ML3_Final_Project\lichess-bot\lib\engine_wrapper.py", line 63, in create_engine
    Engine = getHomemadeEngine(cfg.name)
             ^^^^^^^^^^^^^^^^^^^^^^^^^^^
  File "C:\Users\Kyle_Remote\Documents\Programs\DS3ML3_Final_Project\lichess-bot\lib\engine_wrapper.py", line 620, in getHomemadeEngine
    import homemade
  File "C:\Users\Kyle_Remote\Documents\Programs\DS3ML3_Final_Project\lichess-bot\homemade.py", line 27, in <module>
    model_loaded = torch.load('../models_EL/model_E7-2.pth', map_location=device)
                   ^^^^^^^^^^^^^^^^^^^^^^^^^^^^^^^^^^^^^^^^^^^^^^^^^^^^^^^^^^^^^^
  File "C:\Users\Kyle_Remote\Documents\Programs\DS3ML3_Final_Project\.venv\Lib\site-packages\torch\serialization.py", line 1026, in load
    return _load(opened_zipfile,
           ^^^^^^^^^^^^^^^^^^^^^
  File "C:\Users\Kyle_Remote\Documents\Programs\DS3ML3_Final_Project\.venv\Lib\site-packages\torch\serialization.py", line 1438, in _load
    result = unpickler.load()
             ^^^^^^^^^^^^^^^^
  File "C:\Users\Kyle_Remote\Documents\Programs\DS3ML3_Final_Project\.venv\Lib\site-packages\torch\serialization.py", line 1431, in find_class
    return super().find_class(mod_name, name)
           ^^^^^^^^^^^^^^^^^^^^^^^^^^^^^^^^^^
ModuleNotFoundError: No module named 'chess_SL_E5_lib'

2024-04-21 11:00:58,115 urllib3.connectionpool (connectionpool.py:292) DEBUG Resetting dropped connection: lichess.org
2024-04-21 11:00:58,680 urllib3.connectionpool (connectionpool.py:549) DEBUG https://lichess.org:443 "GET /api/bot/game/stream/IPPi87y5 HTTP/1.1" 200 None
2024-04-21 11:00:58,680 __mp_main__ (lichess-bot.py:605) DEBUG Initial state: {'id': 'IPPi87y5', 'variant': {'key': 'standard', 'name': 'Standard', 'short': 'Std'}, 'speed': 'blitz', 'perf': {'name': 'Blitz'}, 'rated': False, 'createdAt': 1713711580395, 'white': {'id': 'ks_chessai', 'name': 'KS_ChessAI', 'title': 'BOT', 'rating': 2000, 'provisional': True}, 'black': {'id': 'checkyle', 'name': 'ChecKyle', 'title': None, 'rating': 1410, 'provisional': True}, 'initialFen': 'startpos', 'clock': {'initial': 300000, 'increment': 1000}, 'type': 'gameFull', 'state': {'type': 'gameState', 'moves': '', 'wtime': 300000, 'btime': 300000, 'winc': 1000, 'binc': 1000, 'status': 'aborted', 'rematch': 'xNawCt5b'}}
2024-04-21 11:00:58,682 backoff (_common.py:105) INFO Backing off play_game(...) for 81.5s (ModuleNotFoundError: No module named 'chess_SL_E5_lib')
2024-04-21 11:00:58,682 lib.lichess (lichess.py:63) DEBUG Backing off 81.5 seconds after 8 tries calling function <function play_game at 0x0000017FA1C28680> with args () and kwargs {'li': <lib.lichess.Lichess object at 0x0000017FA1C26950>, 'control_queue': <AutoProxy[Queue] object, typeid 'Queue' at 0x17fa1c80690>, 'user_profile': {'id': 'ks_chessai', 'username': 'KS_ChessAI', 'perfs': {'bullet': {'games': 0, 'rating': 2000, 'rd': 500, 'prog': 0, 'prov': True}, 'blitz': {'games': 0, 'rating': 2000, 'rd': 500, 'prog': 0, 'prov': True}, 'rapid': {'games': 0, 'rating': 2000, 'rd': 500, 'prog': 0, 'prov': True}, 'classical': {'games': 0, 'rating': 2000, 'rd': 500, 'prog': 0, 'prov': True}, 'correspondence': {'games': 0, 'rating': 2000, 'rd': 500, 'prog': 0, 'prov': True}}, 'title': 'BOT', 'createdAt': 1711486329716, 'seenAt': 1713625564792, 'playTime': {'total': 15628, 'tv': 0}, 'url': 'https://lichess.org/@/KS_ChessAI', 'count': {'all': 113, 'rated': 0, 'ai': 0, 'draw': 11, 'drawH': 11, 'loss': 89, 'lossH': 89, 'win': 13, 'winH': 13, 'bookmark': 0, 'playing': 0, 'import': 0, 'me': 0}, 'followable': True, 'following': False, 'blocking': False, 'followsYou': False}, 'config': <lib.config.Configuration object at 0x0000017FA1C81F10>, 'challenge_queue': <ListProxy object, typeid 'list' at 0x17fa1c88550>, 'correspondence_queue': <AutoProxy[Queue] object, typeid 'Queue' at 0x17fa1c88790>, 'logging_queue': <AutoProxy[Queue] object, typeid 'Queue' at 0x17fa1c889d0>, 'game_id': 'IPPi87y5'}
2024-04-21 11:00:58,683 lib.lichess (lichess.py:65) DEBUG Exception: Traceback (most recent call last):
  File "C:\Users\Kyle_Remote\Documents\Programs\DS3ML3_Final_Project\.venv\Lib\site-packages\backoff\_sync.py", line 105, in retry
    ret = target(*args, **kwargs)
          ^^^^^^^^^^^^^^^^^^^^^^^
  File "C:\Users\Kyle_Remote\Documents\Programs\DS3ML3_Final_Project\lichess-bot\lichess-bot.py", line 609, in play_game
    with engine_wrapper.create_engine(config, game) as engine:
         ^^^^^^^^^^^^^^^^^^^^^^^^^^^^^^^^^^^^^^^^^^
  File "C:\Users\Kyle_Remote\Documents\Programs\DS3ML3_Final_Project\lichess-bot\lib\engine_wrapper.py", line 63, in create_engine
    Engine = getHomemadeEngine(cfg.name)
             ^^^^^^^^^^^^^^^^^^^^^^^^^^^
  File "C:\Users\Kyle_Remote\Documents\Programs\DS3ML3_Final_Project\lichess-bot\lib\engine_wrapper.py", line 620, in getHomemadeEngine
    import homemade
  File "C:\Users\Kyle_Remote\Documents\Programs\DS3ML3_Final_Project\lichess-bot\homemade.py", line 27, in <module>
    model_loaded = torch.load('../models_EL/model_E7-2.pth', map_location=device)
                   ^^^^^^^^^^^^^^^^^^^^^^^^^^^^^^^^^^^^^^^^^^^^^^^^^^^^^^^^^^^^^^
  File "C:\Users\Kyle_Remote\Documents\Programs\DS3ML3_Final_Project\.venv\Lib\site-packages\torch\serialization.py", line 1026, in load
    return _load(opened_zipfile,
           ^^^^^^^^^^^^^^^^^^^^^
  File "C:\Users\Kyle_Remote\Documents\Programs\DS3ML3_Final_Project\.venv\Lib\site-packages\torch\serialization.py", line 1438, in _load
    result = unpickler.load()
             ^^^^^^^^^^^^^^^^
  File "C:\Users\Kyle_Remote\Documents\Programs\DS3ML3_Final_Project\.venv\Lib\site-packages\torch\serialization.py", line 1431, in find_class
    return super().find_class(mod_name, name)
           ^^^^^^^^^^^^^^^^^^^^^^^^^^^^^^^^^^
ModuleNotFoundError: No module named 'chess_SL_E5_lib'

2024-04-21 11:01:05,538 urllib3.connectionpool (connectionpool.py:292) DEBUG Resetting dropped connection: lichess.org
2024-04-21 11:01:06,103 urllib3.connectionpool (connectionpool.py:549) DEBUG https://lichess.org:443 "GET /api/bot/game/stream/xNawCt5b HTTP/1.1" 200 None
2024-04-21 11:01:06,103 __mp_main__ (lichess-bot.py:605) DEBUG Initial state: {'id': 'xNawCt5b', 'variant': {'key': 'standard', 'name': 'Standard', 'short': 'Std'}, 'speed': 'blitz', 'perf': {'name': 'Blitz'}, 'rated': False, 'createdAt': 1713711634124, 'white': {'id': 'checkyle', 'name': 'ChecKyle', 'title': None, 'rating': 1410, 'provisional': True}, 'black': {'id': 'ks_chessai', 'name': 'KS_ChessAI', 'title': 'BOT', 'rating': 2000, 'provisional': True}, 'initialFen': 'startpos', 'clock': {'initial': 300000, 'increment': 1000}, 'type': 'gameFull', 'state': {'type': 'gameState', 'moves': 'e2e4', 'wtime': 300000, 'btime': 300000, 'winc': 1000, 'binc': 1000, 'status': 'started'}}
2024-04-21 11:01:06,105 backoff (_common.py:105) INFO Backing off play_game(...) for 6.3s (ModuleNotFoundError: No module named 'chess_SL_E5_lib')
2024-04-21 11:01:06,106 lib.lichess (lichess.py:63) DEBUG Backing off 6.3 seconds after 6 tries calling function <function play_game at 0x0000020C53F48680> with args () and kwargs {'li': <lib.lichess.Lichess object at 0x0000020C53F46950>, 'control_queue': <AutoProxy[Queue] object, typeid 'Queue' at 0x20c53fa0690>, 'user_profile': {'id': 'ks_chessai', 'username': 'KS_ChessAI', 'perfs': {'bullet': {'games': 0, 'rating': 2000, 'rd': 500, 'prog': 0, 'prov': True}, 'blitz': {'games': 0, 'rating': 2000, 'rd': 500, 'prog': 0, 'prov': True}, 'rapid': {'games': 0, 'rating': 2000, 'rd': 500, 'prog': 0, 'prov': True}, 'classical': {'games': 0, 'rating': 2000, 'rd': 500, 'prog': 0, 'prov': True}, 'correspondence': {'games': 0, 'rating': 2000, 'rd': 500, 'prog': 0, 'prov': True}}, 'title': 'BOT', 'createdAt': 1711486329716, 'seenAt': 1713625564792, 'playTime': {'total': 15628, 'tv': 0}, 'url': 'https://lichess.org/@/KS_ChessAI', 'count': {'all': 113, 'rated': 0, 'ai': 0, 'draw': 11, 'drawH': 11, 'loss': 89, 'lossH': 89, 'win': 13, 'winH': 13, 'bookmark': 0, 'playing': 0, 'import': 0, 'me': 0}, 'followable': True, 'following': False, 'blocking': False, 'followsYou': False}, 'config': <lib.config.Configuration object at 0x0000020C53FA1F10>, 'challenge_queue': <ListProxy object, typeid 'list' at 0x20c53fa8550>, 'correspondence_queue': <AutoProxy[Queue] object, typeid 'Queue' at 0x20c53fa8790>, 'logging_queue': <AutoProxy[Queue] object, typeid 'Queue' at 0x20c53fa89d0>, 'game_id': 'xNawCt5b'}
2024-04-21 11:01:06,107 lib.lichess (lichess.py:65) DEBUG Exception: Traceback (most recent call last):
  File "C:\Users\Kyle_Remote\Documents\Programs\DS3ML3_Final_Project\.venv\Lib\site-packages\backoff\_sync.py", line 105, in retry
    ret = target(*args, **kwargs)
          ^^^^^^^^^^^^^^^^^^^^^^^
  File "C:\Users\Kyle_Remote\Documents\Programs\DS3ML3_Final_Project\lichess-bot\lichess-bot.py", line 609, in play_game
    with engine_wrapper.create_engine(config, game) as engine:
         ^^^^^^^^^^^^^^^^^^^^^^^^^^^^^^^^^^^^^^^^^^
  File "C:\Users\Kyle_Remote\Documents\Programs\DS3ML3_Final_Project\lichess-bot\lib\engine_wrapper.py", line 63, in create_engine
    Engine = getHomemadeEngine(cfg.name)
             ^^^^^^^^^^^^^^^^^^^^^^^^^^^
  File "C:\Users\Kyle_Remote\Documents\Programs\DS3ML3_Final_Project\lichess-bot\lib\engine_wrapper.py", line 620, in getHomemadeEngine
    import homemade
  File "C:\Users\Kyle_Remote\Documents\Programs\DS3ML3_Final_Project\lichess-bot\homemade.py", line 27, in <module>
    model_loaded = torch.load('../models_EL/model_E7-2.pth', map_location=device)
                   ^^^^^^^^^^^^^^^^^^^^^^^^^^^^^^^^^^^^^^^^^^^^^^^^^^^^^^^^^^^^^^
  File "C:\Users\Kyle_Remote\Documents\Programs\DS3ML3_Final_Project\.venv\Lib\site-packages\torch\serialization.py", line 1026, in load
    return _load(opened_zipfile,
           ^^^^^^^^^^^^^^^^^^^^^
  File "C:\Users\Kyle_Remote\Documents\Programs\DS3ML3_Final_Project\.venv\Lib\site-packages\torch\serialization.py", line 1438, in _load
    result = unpickler.load()
             ^^^^^^^^^^^^^^^^
  File "C:\Users\Kyle_Remote\Documents\Programs\DS3ML3_Final_Project\.venv\Lib\site-packages\torch\serialization.py", line 1431, in find_class
    return super().find_class(mod_name, name)
           ^^^^^^^^^^^^^^^^^^^^^^^^^^^^^^^^^^
ModuleNotFoundError: No module named 'chess_SL_E5_lib'

2024-04-21 11:01:12,364 urllib3.connectionpool (connectionpool.py:292) DEBUG Resetting dropped connection: lichess.org
2024-04-21 11:01:12,914 urllib3.connectionpool (connectionpool.py:549) DEBUG https://lichess.org:443 "GET /api/bot/game/stream/xNawCt5b HTTP/1.1" 200 None
2024-04-21 11:01:12,914 __mp_main__ (lichess-bot.py:605) DEBUG Initial state: {'id': 'xNawCt5b', 'variant': {'key': 'standard', 'name': 'Standard', 'short': 'Std'}, 'speed': 'blitz', 'perf': {'name': 'Blitz'}, 'rated': False, 'createdAt': 1713711634124, 'white': {'id': 'checkyle', 'name': 'ChecKyle', 'title': None, 'rating': 1410, 'provisional': True}, 'black': {'id': 'ks_chessai', 'name': 'KS_ChessAI', 'title': 'BOT', 'rating': 2000, 'provisional': True}, 'initialFen': 'startpos', 'clock': {'initial': 300000, 'increment': 1000}, 'type': 'gameFull', 'state': {'type': 'gameState', 'moves': 'e2e4', 'wtime': 300000, 'btime': 300000, 'winc': 1000, 'binc': 1000, 'status': 'started'}}
2024-04-21 11:01:12,916 backoff (_common.py:105) INFO Backing off play_game(...) for 0.8s (ModuleNotFoundError: No module named 'chess_SL_E5_lib')
2024-04-21 11:01:12,916 lib.lichess (lichess.py:63) DEBUG Backing off 0.8 seconds after 7 tries calling function <function play_game at 0x0000020C53F48680> with args () and kwargs {'li': <lib.lichess.Lichess object at 0x0000020C53F46950>, 'control_queue': <AutoProxy[Queue] object, typeid 'Queue' at 0x20c53fa0690>, 'user_profile': {'id': 'ks_chessai', 'username': 'KS_ChessAI', 'perfs': {'bullet': {'games': 0, 'rating': 2000, 'rd': 500, 'prog': 0, 'prov': True}, 'blitz': {'games': 0, 'rating': 2000, 'rd': 500, 'prog': 0, 'prov': True}, 'rapid': {'games': 0, 'rating': 2000, 'rd': 500, 'prog': 0, 'prov': True}, 'classical': {'games': 0, 'rating': 2000, 'rd': 500, 'prog': 0, 'prov': True}, 'correspondence': {'games': 0, 'rating': 2000, 'rd': 500, 'prog': 0, 'prov': True}}, 'title': 'BOT', 'createdAt': 1711486329716, 'seenAt': 1713625564792, 'playTime': {'total': 15628, 'tv': 0}, 'url': 'https://lichess.org/@/KS_ChessAI', 'count': {'all': 113, 'rated': 0, 'ai': 0, 'draw': 11, 'drawH': 11, 'loss': 89, 'lossH': 89, 'win': 13, 'winH': 13, 'bookmark': 0, 'playing': 0, 'import': 0, 'me': 0}, 'followable': True, 'following': False, 'blocking': False, 'followsYou': False}, 'config': <lib.config.Configuration object at 0x0000020C53FA1F10>, 'challenge_queue': <ListProxy object, typeid 'list' at 0x20c53fa8550>, 'correspondence_queue': <AutoProxy[Queue] object, typeid 'Queue' at 0x20c53fa8790>, 'logging_queue': <AutoProxy[Queue] object, typeid 'Queue' at 0x20c53fa89d0>, 'game_id': 'xNawCt5b'}
2024-04-21 11:01:12,917 lib.lichess (lichess.py:65) DEBUG Exception: Traceback (most recent call last):
  File "C:\Users\Kyle_Remote\Documents\Programs\DS3ML3_Final_Project\.venv\Lib\site-packages\backoff\_sync.py", line 105, in retry
    ret = target(*args, **kwargs)
          ^^^^^^^^^^^^^^^^^^^^^^^
  File "C:\Users\Kyle_Remote\Documents\Programs\DS3ML3_Final_Project\lichess-bot\lichess-bot.py", line 609, in play_game
    with engine_wrapper.create_engine(config, game) as engine:
         ^^^^^^^^^^^^^^^^^^^^^^^^^^^^^^^^^^^^^^^^^^
  File "C:\Users\Kyle_Remote\Documents\Programs\DS3ML3_Final_Project\lichess-bot\lib\engine_wrapper.py", line 63, in create_engine
    Engine = getHomemadeEngine(cfg.name)
             ^^^^^^^^^^^^^^^^^^^^^^^^^^^
  File "C:\Users\Kyle_Remote\Documents\Programs\DS3ML3_Final_Project\lichess-bot\lib\engine_wrapper.py", line 620, in getHomemadeEngine
    import homemade
  File "C:\Users\Kyle_Remote\Documents\Programs\DS3ML3_Final_Project\lichess-bot\homemade.py", line 27, in <module>
    model_loaded = torch.load('../models_EL/model_E7-2.pth', map_location=device)
                   ^^^^^^^^^^^^^^^^^^^^^^^^^^^^^^^^^^^^^^^^^^^^^^^^^^^^^^^^^^^^^^
  File "C:\Users\Kyle_Remote\Documents\Programs\DS3ML3_Final_Project\.venv\Lib\site-packages\torch\serialization.py", line 1026, in load
    return _load(opened_zipfile,
           ^^^^^^^^^^^^^^^^^^^^^
  File "C:\Users\Kyle_Remote\Documents\Programs\DS3ML3_Final_Project\.venv\Lib\site-packages\torch\serialization.py", line 1438, in _load
    result = unpickler.load()
             ^^^^^^^^^^^^^^^^
  File "C:\Users\Kyle_Remote\Documents\Programs\DS3ML3_Final_Project\.venv\Lib\site-packages\torch\serialization.py", line 1431, in find_class
    return super().find_class(mod_name, name)
           ^^^^^^^^^^^^^^^^^^^^^^^^^^^^^^^^^^
ModuleNotFoundError: No module named 'chess_SL_E5_lib'

2024-04-21 11:01:13,712 urllib3.connectionpool (connectionpool.py:292) DEBUG Resetting dropped connection: lichess.org
2024-04-21 11:01:14,247 urllib3.connectionpool (connectionpool.py:549) DEBUG https://lichess.org:443 "GET /api/bot/game/stream/xNawCt5b HTTP/1.1" 200 None
2024-04-21 11:01:14,248 __mp_main__ (lichess-bot.py:605) DEBUG Initial state: {'id': 'xNawCt5b', 'variant': {'key': 'standard', 'name': 'Standard', 'short': 'Std'}, 'speed': 'blitz', 'perf': {'name': 'Blitz'}, 'rated': False, 'createdAt': 1713711634124, 'white': {'id': 'checkyle', 'name': 'ChecKyle', 'title': None, 'rating': 1410, 'provisional': True}, 'black': {'id': 'ks_chessai', 'name': 'KS_ChessAI', 'title': 'BOT', 'rating': 2000, 'provisional': True}, 'initialFen': 'startpos', 'clock': {'initial': 300000, 'increment': 1000}, 'type': 'gameFull', 'state': {'type': 'gameState', 'moves': 'e2e4', 'wtime': 300000, 'btime': 300000, 'winc': 1000, 'binc': 1000, 'status': 'started'}}
2024-04-21 11:01:14,249 backoff (_common.py:105) INFO Backing off play_game(...) for 107.4s (ModuleNotFoundError: No module named 'chess_SL_E5_lib')
2024-04-21 11:01:14,250 lib.lichess (lichess.py:63) DEBUG Backing off 107.4 seconds after 8 tries calling function <function play_game at 0x0000020C53F48680> with args () and kwargs {'li': <lib.lichess.Lichess object at 0x0000020C53F46950>, 'control_queue': <AutoProxy[Queue] object, typeid 'Queue' at 0x20c53fa0690>, 'user_profile': {'id': 'ks_chessai', 'username': 'KS_ChessAI', 'perfs': {'bullet': {'games': 0, 'rating': 2000, 'rd': 500, 'prog': 0, 'prov': True}, 'blitz': {'games': 0, 'rating': 2000, 'rd': 500, 'prog': 0, 'prov': True}, 'rapid': {'games': 0, 'rating': 2000, 'rd': 500, 'prog': 0, 'prov': True}, 'classical': {'games': 0, 'rating': 2000, 'rd': 500, 'prog': 0, 'prov': True}, 'correspondence': {'games': 0, 'rating': 2000, 'rd': 500, 'prog': 0, 'prov': True}}, 'title': 'BOT', 'createdAt': 1711486329716, 'seenAt': 1713625564792, 'playTime': {'total': 15628, 'tv': 0}, 'url': 'https://lichess.org/@/KS_ChessAI', 'count': {'all': 113, 'rated': 0, 'ai': 0, 'draw': 11, 'drawH': 11, 'loss': 89, 'lossH': 89, 'win': 13, 'winH': 13, 'bookmark': 0, 'playing': 0, 'import': 0, 'me': 0}, 'followable': True, 'following': False, 'blocking': False, 'followsYou': False}, 'config': <lib.config.Configuration object at 0x0000020C53FA1F10>, 'challenge_queue': <ListProxy object, typeid 'list' at 0x20c53fa8550>, 'correspondence_queue': <AutoProxy[Queue] object, typeid 'Queue' at 0x20c53fa8790>, 'logging_queue': <AutoProxy[Queue] object, typeid 'Queue' at 0x20c53fa89d0>, 'game_id': 'xNawCt5b'}
2024-04-21 11:01:14,250 lib.lichess (lichess.py:65) DEBUG Exception: Traceback (most recent call last):
  File "C:\Users\Kyle_Remote\Documents\Programs\DS3ML3_Final_Project\.venv\Lib\site-packages\backoff\_sync.py", line 105, in retry
    ret = target(*args, **kwargs)
          ^^^^^^^^^^^^^^^^^^^^^^^
  File "C:\Users\Kyle_Remote\Documents\Programs\DS3ML3_Final_Project\lichess-bot\lichess-bot.py", line 609, in play_game
    with engine_wrapper.create_engine(config, game) as engine:
         ^^^^^^^^^^^^^^^^^^^^^^^^^^^^^^^^^^^^^^^^^^
  File "C:\Users\Kyle_Remote\Documents\Programs\DS3ML3_Final_Project\lichess-bot\lib\engine_wrapper.py", line 63, in create_engine
    Engine = getHomemadeEngine(cfg.name)
             ^^^^^^^^^^^^^^^^^^^^^^^^^^^
  File "C:\Users\Kyle_Remote\Documents\Programs\DS3ML3_Final_Project\lichess-bot\lib\engine_wrapper.py", line 620, in getHomemadeEngine
    import homemade
  File "C:\Users\Kyle_Remote\Documents\Programs\DS3ML3_Final_Project\lichess-bot\homemade.py", line 27, in <module>
    model_loaded = torch.load('../models_EL/model_E7-2.pth', map_location=device)
                   ^^^^^^^^^^^^^^^^^^^^^^^^^^^^^^^^^^^^^^^^^^^^^^^^^^^^^^^^^^^^^^
  File "C:\Users\Kyle_Remote\Documents\Programs\DS3ML3_Final_Project\.venv\Lib\site-packages\torch\serialization.py", line 1026, in load
    return _load(opened_zipfile,
           ^^^^^^^^^^^^^^^^^^^^^
  File "C:\Users\Kyle_Remote\Documents\Programs\DS3ML3_Final_Project\.venv\Lib\site-packages\torch\serialization.py", line 1438, in _load
    result = unpickler.load()
             ^^^^^^^^^^^^^^^^
  File "C:\Users\Kyle_Remote\Documents\Programs\DS3ML3_Final_Project\.venv\Lib\site-packages\torch\serialization.py", line 1431, in find_class
    return super().find_class(mod_name, name)
           ^^^^^^^^^^^^^^^^^^^^^^^^^^^^^^^^^^
ModuleNotFoundError: No module named 'chess_SL_E5_lib'

2024-04-21 11:02:20,185 urllib3.connectionpool (connectionpool.py:292) DEBUG Resetting dropped connection: lichess.org
2024-04-21 11:02:20,729 urllib3.connectionpool (connectionpool.py:549) DEBUG https://lichess.org:443 "GET /api/bot/game/stream/IPPi87y5 HTTP/1.1" 200 None
2024-04-21 11:02:20,729 __mp_main__ (lichess-bot.py:605) DEBUG Initial state: {'id': 'IPPi87y5', 'variant': {'key': 'standard', 'name': 'Standard', 'short': 'Std'}, 'speed': 'blitz', 'perf': {'name': 'Blitz'}, 'rated': False, 'createdAt': 1713711580395, 'white': {'id': 'ks_chessai', 'name': 'KS_ChessAI', 'title': 'BOT', 'rating': 2000, 'provisional': True}, 'black': {'id': 'checkyle', 'name': 'ChecKyle', 'title': None, 'rating': 1410, 'provisional': True}, 'initialFen': 'startpos', 'clock': {'initial': 300000, 'increment': 1000}, 'type': 'gameFull', 'state': {'type': 'gameState', 'moves': '', 'wtime': 300000, 'btime': 300000, 'winc': 1000, 'binc': 1000, 'status': 'aborted', 'rematch': 'xNawCt5b'}}
2024-04-21 11:02:20,731 backoff (_common.py:105) INFO Backing off play_game(...) for 242.0s (ModuleNotFoundError: No module named 'chess_SL_E5_lib')
2024-04-21 11:02:20,731 lib.lichess (lichess.py:63) DEBUG Backing off 242.0 seconds after 9 tries calling function <function play_game at 0x0000017FA1C28680> with args () and kwargs {'li': <lib.lichess.Lichess object at 0x0000017FA1C26950>, 'control_queue': <AutoProxy[Queue] object, typeid 'Queue' at 0x17fa1c80690>, 'user_profile': {'id': 'ks_chessai', 'username': 'KS_ChessAI', 'perfs': {'bullet': {'games': 0, 'rating': 2000, 'rd': 500, 'prog': 0, 'prov': True}, 'blitz': {'games': 0, 'rating': 2000, 'rd': 500, 'prog': 0, 'prov': True}, 'rapid': {'games': 0, 'rating': 2000, 'rd': 500, 'prog': 0, 'prov': True}, 'classical': {'games': 0, 'rating': 2000, 'rd': 500, 'prog': 0, 'prov': True}, 'correspondence': {'games': 0, 'rating': 2000, 'rd': 500, 'prog': 0, 'prov': True}}, 'title': 'BOT', 'createdAt': 1711486329716, 'seenAt': 1713625564792, 'playTime': {'total': 15628, 'tv': 0}, 'url': 'https://lichess.org/@/KS_ChessAI', 'count': {'all': 113, 'rated': 0, 'ai': 0, 'draw': 11, 'drawH': 11, 'loss': 89, 'lossH': 89, 'win': 13, 'winH': 13, 'bookmark': 0, 'playing': 0, 'import': 0, 'me': 0}, 'followable': True, 'following': False, 'blocking': False, 'followsYou': False}, 'config': <lib.config.Configuration object at 0x0000017FA1C81F10>, 'challenge_queue': <ListProxy object, typeid 'list' at 0x17fa1c88550>, 'correspondence_queue': <AutoProxy[Queue] object, typeid 'Queue' at 0x17fa1c88790>, 'logging_queue': <AutoProxy[Queue] object, typeid 'Queue' at 0x17fa1c889d0>, 'game_id': 'IPPi87y5'}
2024-04-21 11:02:20,732 lib.lichess (lichess.py:65) DEBUG Exception: Traceback (most recent call last):
  File "C:\Users\Kyle_Remote\Documents\Programs\DS3ML3_Final_Project\.venv\Lib\site-packages\backoff\_sync.py", line 105, in retry
    ret = target(*args, **kwargs)
          ^^^^^^^^^^^^^^^^^^^^^^^
  File "C:\Users\Kyle_Remote\Documents\Programs\DS3ML3_Final_Project\lichess-bot\lichess-bot.py", line 609, in play_game
    with engine_wrapper.create_engine(config, game) as engine:
         ^^^^^^^^^^^^^^^^^^^^^^^^^^^^^^^^^^^^^^^^^^
  File "C:\Users\Kyle_Remote\Documents\Programs\DS3ML3_Final_Project\lichess-bot\lib\engine_wrapper.py", line 63, in create_engine
    Engine = getHomemadeEngine(cfg.name)
             ^^^^^^^^^^^^^^^^^^^^^^^^^^^
  File "C:\Users\Kyle_Remote\Documents\Programs\DS3ML3_Final_Project\lichess-bot\lib\engine_wrapper.py", line 620, in getHomemadeEngine
    import homemade
  File "C:\Users\Kyle_Remote\Documents\Programs\DS3ML3_Final_Project\lichess-bot\homemade.py", line 27, in <module>
    model_loaded = torch.load('../models_EL/model_E7-2.pth', map_location=device)
                   ^^^^^^^^^^^^^^^^^^^^^^^^^^^^^^^^^^^^^^^^^^^^^^^^^^^^^^^^^^^^^^
  File "C:\Users\Kyle_Remote\Documents\Programs\DS3ML3_Final_Project\.venv\Lib\site-packages\torch\serialization.py", line 1026, in load
    return _load(opened_zipfile,
           ^^^^^^^^^^^^^^^^^^^^^
  File "C:\Users\Kyle_Remote\Documents\Programs\DS3ML3_Final_Project\.venv\Lib\site-packages\torch\serialization.py", line 1438, in _load
    result = unpickler.load()
             ^^^^^^^^^^^^^^^^
  File "C:\Users\Kyle_Remote\Documents\Programs\DS3ML3_Final_Project\.venv\Lib\site-packages\torch\serialization.py", line 1431, in find_class
    return super().find_class(mod_name, name)
           ^^^^^^^^^^^^^^^^^^^^^^^^^^^^^^^^^^
ModuleNotFoundError: No module named 'chess_SL_E5_lib'

2024-04-21 11:03:01,628 urllib3.connectionpool (connectionpool.py:292) DEBUG Resetting dropped connection: lichess.org
2024-04-21 11:03:02,212 urllib3.connectionpool (connectionpool.py:549) DEBUG https://lichess.org:443 "GET /api/bot/game/stream/xNawCt5b HTTP/1.1" 200 None
2024-04-21 11:03:02,212 __mp_main__ (lichess-bot.py:605) DEBUG Initial state: {'id': 'xNawCt5b', 'variant': {'key': 'standard', 'name': 'Standard', 'short': 'Std'}, 'speed': 'blitz', 'perf': {'name': 'Blitz'}, 'rated': False, 'createdAt': 1713711634124, 'white': {'id': 'checkyle', 'name': 'ChecKyle', 'title': None, 'rating': 1410, 'provisional': True}, 'black': {'id': 'ks_chessai', 'name': 'KS_ChessAI', 'title': 'BOT', 'rating': 2000, 'provisional': True}, 'initialFen': 'startpos', 'clock': {'initial': 300000, 'increment': 1000}, 'type': 'gameFull', 'state': {'type': 'gameState', 'moves': 'e2e4', 'wtime': 300000, 'btime': 300000, 'winc': 1000, 'binc': 1000, 'status': 'started'}}
2024-04-21 11:03:02,214 backoff (_common.py:105) INFO Backing off play_game(...) for 220.6s (ModuleNotFoundError: No module named 'chess_SL_E5_lib')
2024-04-21 11:03:02,214 lib.lichess (lichess.py:63) DEBUG Backing off 220.6 seconds after 9 tries calling function <function play_game at 0x0000020C53F48680> with args () and kwargs {'li': <lib.lichess.Lichess object at 0x0000020C53F46950>, 'control_queue': <AutoProxy[Queue] object, typeid 'Queue' at 0x20c53fa0690>, 'user_profile': {'id': 'ks_chessai', 'username': 'KS_ChessAI', 'perfs': {'bullet': {'games': 0, 'rating': 2000, 'rd': 500, 'prog': 0, 'prov': True}, 'blitz': {'games': 0, 'rating': 2000, 'rd': 500, 'prog': 0, 'prov': True}, 'rapid': {'games': 0, 'rating': 2000, 'rd': 500, 'prog': 0, 'prov': True}, 'classical': {'games': 0, 'rating': 2000, 'rd': 500, 'prog': 0, 'prov': True}, 'correspondence': {'games': 0, 'rating': 2000, 'rd': 500, 'prog': 0, 'prov': True}}, 'title': 'BOT', 'createdAt': 1711486329716, 'seenAt': 1713625564792, 'playTime': {'total': 15628, 'tv': 0}, 'url': 'https://lichess.org/@/KS_ChessAI', 'count': {'all': 113, 'rated': 0, 'ai': 0, 'draw': 11, 'drawH': 11, 'loss': 89, 'lossH': 89, 'win': 13, 'winH': 13, 'bookmark': 0, 'playing': 0, 'import': 0, 'me': 0}, 'followable': True, 'following': False, 'blocking': False, 'followsYou': False}, 'config': <lib.config.Configuration object at 0x0000020C53FA1F10>, 'challenge_queue': <ListProxy object, typeid 'list' at 0x20c53fa8550>, 'correspondence_queue': <AutoProxy[Queue] object, typeid 'Queue' at 0x20c53fa8790>, 'logging_queue': <AutoProxy[Queue] object, typeid 'Queue' at 0x20c53fa89d0>, 'game_id': 'xNawCt5b'}
2024-04-21 11:03:02,215 lib.lichess (lichess.py:65) DEBUG Exception: Traceback (most recent call last):
  File "C:\Users\Kyle_Remote\Documents\Programs\DS3ML3_Final_Project\.venv\Lib\site-packages\backoff\_sync.py", line 105, in retry
    ret = target(*args, **kwargs)
          ^^^^^^^^^^^^^^^^^^^^^^^
  File "C:\Users\Kyle_Remote\Documents\Programs\DS3ML3_Final_Project\lichess-bot\lichess-bot.py", line 609, in play_game
    with engine_wrapper.create_engine(config, game) as engine:
         ^^^^^^^^^^^^^^^^^^^^^^^^^^^^^^^^^^^^^^^^^^
  File "C:\Users\Kyle_Remote\Documents\Programs\DS3ML3_Final_Project\lichess-bot\lib\engine_wrapper.py", line 63, in create_engine
    Engine = getHomemadeEngine(cfg.name)
             ^^^^^^^^^^^^^^^^^^^^^^^^^^^
  File "C:\Users\Kyle_Remote\Documents\Programs\DS3ML3_Final_Project\lichess-bot\lib\engine_wrapper.py", line 620, in getHomemadeEngine
    import homemade
  File "C:\Users\Kyle_Remote\Documents\Programs\DS3ML3_Final_Project\lichess-bot\homemade.py", line 27, in <module>
    model_loaded = torch.load('../models_EL/model_E7-2.pth', map_location=device)
                   ^^^^^^^^^^^^^^^^^^^^^^^^^^^^^^^^^^^^^^^^^^^^^^^^^^^^^^^^^^^^^^
  File "C:\Users\Kyle_Remote\Documents\Programs\DS3ML3_Final_Project\.venv\Lib\site-packages\torch\serialization.py", line 1026, in load
    return _load(opened_zipfile,
           ^^^^^^^^^^^^^^^^^^^^^
  File "C:\Users\Kyle_Remote\Documents\Programs\DS3ML3_Final_Project\.venv\Lib\site-packages\torch\serialization.py", line 1438, in _load
    result = unpickler.load()
             ^^^^^^^^^^^^^^^^
  File "C:\Users\Kyle_Remote\Documents\Programs\DS3ML3_Final_Project\.venv\Lib\site-packages\torch\serialization.py", line 1431, in find_class
    return super().find_class(mod_name, name)
           ^^^^^^^^^^^^^^^^^^^^^^^^^^^^^^^^^^
ModuleNotFoundError: No module named 'chess_SL_E5_lib'

2024-04-21 11:05:10,956 __main__ (lichess-bot.py:404) DEBUG Event: {'type': 'correspondence_ping'}
2024-04-21 11:06:22,783 urllib3.connectionpool (connectionpool.py:292) DEBUG Resetting dropped connection: lichess.org
2024-04-21 11:06:23,330 urllib3.connectionpool (connectionpool.py:549) DEBUG https://lichess.org:443 "GET /api/bot/game/stream/IPPi87y5 HTTP/1.1" 200 None
2024-04-21 11:06:23,330 __mp_main__ (lichess-bot.py:605) DEBUG Initial state: {'id': 'IPPi87y5', 'variant': {'key': 'standard', 'name': 'Standard', 'short': 'Std'}, 'speed': 'blitz', 'perf': {'name': 'Blitz'}, 'rated': False, 'createdAt': 1713711580395, 'white': {'id': 'ks_chessai', 'name': 'KS_ChessAI', 'title': 'BOT', 'rating': 2000, 'provisional': True}, 'black': {'id': 'checkyle', 'name': 'ChecKyle', 'title': None, 'rating': 1410, 'provisional': True}, 'initialFen': 'startpos', 'clock': {'initial': 300000, 'increment': 1000}, 'type': 'gameFull', 'state': {'type': 'gameState', 'moves': '', 'wtime': 300000, 'btime': 300000, 'winc': 1000, 'binc': 1000, 'status': 'aborted', 'rematch': 'xNawCt5b'}}
2024-04-21 11:06:23,332 backoff (_common.py:105) INFO Backing off play_game(...) for 197.9s (ModuleNotFoundError: No module named 'chess_SL_E5_lib')
2024-04-21 11:06:23,332 lib.lichess (lichess.py:63) DEBUG Backing off 197.9 seconds after 10 tries calling function <function play_game at 0x0000017FA1C28680> with args () and kwargs {'li': <lib.lichess.Lichess object at 0x0000017FA1C26950>, 'control_queue': <AutoProxy[Queue] object, typeid 'Queue' at 0x17fa1c80690>, 'user_profile': {'id': 'ks_chessai', 'username': 'KS_ChessAI', 'perfs': {'bullet': {'games': 0, 'rating': 2000, 'rd': 500, 'prog': 0, 'prov': True}, 'blitz': {'games': 0, 'rating': 2000, 'rd': 500, 'prog': 0, 'prov': True}, 'rapid': {'games': 0, 'rating': 2000, 'rd': 500, 'prog': 0, 'prov': True}, 'classical': {'games': 0, 'rating': 2000, 'rd': 500, 'prog': 0, 'prov': True}, 'correspondence': {'games': 0, 'rating': 2000, 'rd': 500, 'prog': 0, 'prov': True}}, 'title': 'BOT', 'createdAt': 1711486329716, 'seenAt': 1713625564792, 'playTime': {'total': 15628, 'tv': 0}, 'url': 'https://lichess.org/@/KS_ChessAI', 'count': {'all': 113, 'rated': 0, 'ai': 0, 'draw': 11, 'drawH': 11, 'loss': 89, 'lossH': 89, 'win': 13, 'winH': 13, 'bookmark': 0, 'playing': 0, 'import': 0, 'me': 0}, 'followable': True, 'following': False, 'blocking': False, 'followsYou': False}, 'config': <lib.config.Configuration object at 0x0000017FA1C81F10>, 'challenge_queue': <ListProxy object, typeid 'list' at 0x17fa1c88550>, 'correspondence_queue': <AutoProxy[Queue] object, typeid 'Queue' at 0x17fa1c88790>, 'logging_queue': <AutoProxy[Queue] object, typeid 'Queue' at 0x17fa1c889d0>, 'game_id': 'IPPi87y5'}
2024-04-21 11:06:23,333 lib.lichess (lichess.py:65) DEBUG Exception: Traceback (most recent call last):
  File "C:\Users\Kyle_Remote\Documents\Programs\DS3ML3_Final_Project\.venv\Lib\site-packages\backoff\_sync.py", line 105, in retry
    ret = target(*args, **kwargs)
          ^^^^^^^^^^^^^^^^^^^^^^^
  File "C:\Users\Kyle_Remote\Documents\Programs\DS3ML3_Final_Project\lichess-bot\lichess-bot.py", line 609, in play_game
    with engine_wrapper.create_engine(config, game) as engine:
         ^^^^^^^^^^^^^^^^^^^^^^^^^^^^^^^^^^^^^^^^^^
  File "C:\Users\Kyle_Remote\Documents\Programs\DS3ML3_Final_Project\lichess-bot\lib\engine_wrapper.py", line 63, in create_engine
    Engine = getHomemadeEngine(cfg.name)
             ^^^^^^^^^^^^^^^^^^^^^^^^^^^
  File "C:\Users\Kyle_Remote\Documents\Programs\DS3ML3_Final_Project\lichess-bot\lib\engine_wrapper.py", line 620, in getHomemadeEngine
    import homemade
  File "C:\Users\Kyle_Remote\Documents\Programs\DS3ML3_Final_Project\lichess-bot\homemade.py", line 27, in <module>
    model_loaded = torch.load('../models_EL/model_E7-2.pth', map_location=device)
                   ^^^^^^^^^^^^^^^^^^^^^^^^^^^^^^^^^^^^^^^^^^^^^^^^^^^^^^^^^^^^^^
  File "C:\Users\Kyle_Remote\Documents\Programs\DS3ML3_Final_Project\.venv\Lib\site-packages\torch\serialization.py", line 1026, in load
    return _load(opened_zipfile,
           ^^^^^^^^^^^^^^^^^^^^^
  File "C:\Users\Kyle_Remote\Documents\Programs\DS3ML3_Final_Project\.venv\Lib\site-packages\torch\serialization.py", line 1438, in _load
    result = unpickler.load()
             ^^^^^^^^^^^^^^^^
  File "C:\Users\Kyle_Remote\Documents\Programs\DS3ML3_Final_Project\.venv\Lib\site-packages\torch\serialization.py", line 1431, in find_class
    return super().find_class(mod_name, name)
           ^^^^^^^^^^^^^^^^^^^^^^^^^^^^^^^^^^
ModuleNotFoundError: No module named 'chess_SL_E5_lib'

2024-04-21 11:06:42,853 urllib3.connectionpool (connectionpool.py:292) DEBUG Resetting dropped connection: lichess.org
2024-04-21 11:06:43,379 urllib3.connectionpool (connectionpool.py:549) DEBUG https://lichess.org:443 "GET /api/bot/game/stream/xNawCt5b HTTP/1.1" 200 None
2024-04-21 11:06:43,380 __mp_main__ (lichess-bot.py:605) DEBUG Initial state: {'id': 'xNawCt5b', 'variant': {'key': 'standard', 'name': 'Standard', 'short': 'Std'}, 'speed': 'blitz', 'perf': {'name': 'Blitz'}, 'rated': False, 'createdAt': 1713711634124, 'white': {'id': 'checkyle', 'name': 'ChecKyle', 'title': None, 'rating': 1410, 'provisional': True}, 'black': {'id': 'ks_chessai', 'name': 'KS_ChessAI', 'title': 'BOT', 'rating': 2000, 'provisional': True}, 'initialFen': 'startpos', 'clock': {'initial': 300000, 'increment': 1000}, 'type': 'gameFull', 'state': {'type': 'gameState', 'moves': 'e2e4', 'wtime': 300000, 'btime': 300000, 'winc': 1000, 'binc': 1000, 'status': 'started'}}
2024-04-21 11:06:43,382 backoff (_common.py:105) INFO Backing off play_game(...) for 206.8s (ModuleNotFoundError: No module named 'chess_SL_E5_lib')
2024-04-21 11:06:43,382 lib.lichess (lichess.py:63) DEBUG Backing off 206.8 seconds after 10 tries calling function <function play_game at 0x0000020C53F48680> with args () and kwargs {'li': <lib.lichess.Lichess object at 0x0000020C53F46950>, 'control_queue': <AutoProxy[Queue] object, typeid 'Queue' at 0x20c53fa0690>, 'user_profile': {'id': 'ks_chessai', 'username': 'KS_ChessAI', 'perfs': {'bullet': {'games': 0, 'rating': 2000, 'rd': 500, 'prog': 0, 'prov': True}, 'blitz': {'games': 0, 'rating': 2000, 'rd': 500, 'prog': 0, 'prov': True}, 'rapid': {'games': 0, 'rating': 2000, 'rd': 500, 'prog': 0, 'prov': True}, 'classical': {'games': 0, 'rating': 2000, 'rd': 500, 'prog': 0, 'prov': True}, 'correspondence': {'games': 0, 'rating': 2000, 'rd': 500, 'prog': 0, 'prov': True}}, 'title': 'BOT', 'createdAt': 1711486329716, 'seenAt': 1713625564792, 'playTime': {'total': 15628, 'tv': 0}, 'url': 'https://lichess.org/@/KS_ChessAI', 'count': {'all': 113, 'rated': 0, 'ai': 0, 'draw': 11, 'drawH': 11, 'loss': 89, 'lossH': 89, 'win': 13, 'winH': 13, 'bookmark': 0, 'playing': 0, 'import': 0, 'me': 0}, 'followable': True, 'following': False, 'blocking': False, 'followsYou': False}, 'config': <lib.config.Configuration object at 0x0000020C53FA1F10>, 'challenge_queue': <ListProxy object, typeid 'list' at 0x20c53fa8550>, 'correspondence_queue': <AutoProxy[Queue] object, typeid 'Queue' at 0x20c53fa8790>, 'logging_queue': <AutoProxy[Queue] object, typeid 'Queue' at 0x20c53fa89d0>, 'game_id': 'xNawCt5b'}
2024-04-21 11:06:43,383 lib.lichess (lichess.py:65) DEBUG Exception: Traceback (most recent call last):
  File "C:\Users\Kyle_Remote\Documents\Programs\DS3ML3_Final_Project\.venv\Lib\site-packages\backoff\_sync.py", line 105, in retry
    ret = target(*args, **kwargs)
          ^^^^^^^^^^^^^^^^^^^^^^^
  File "C:\Users\Kyle_Remote\Documents\Programs\DS3ML3_Final_Project\lichess-bot\lichess-bot.py", line 609, in play_game
    with engine_wrapper.create_engine(config, game) as engine:
         ^^^^^^^^^^^^^^^^^^^^^^^^^^^^^^^^^^^^^^^^^^
  File "C:\Users\Kyle_Remote\Documents\Programs\DS3ML3_Final_Project\lichess-bot\lib\engine_wrapper.py", line 63, in create_engine
    Engine = getHomemadeEngine(cfg.name)
             ^^^^^^^^^^^^^^^^^^^^^^^^^^^
  File "C:\Users\Kyle_Remote\Documents\Programs\DS3ML3_Final_Project\lichess-bot\lib\engine_wrapper.py", line 620, in getHomemadeEngine
    import homemade
  File "C:\Users\Kyle_Remote\Documents\Programs\DS3ML3_Final_Project\lichess-bot\homemade.py", line 27, in <module>
    model_loaded = torch.load('../models_EL/model_E7-2.pth', map_location=device)
                   ^^^^^^^^^^^^^^^^^^^^^^^^^^^^^^^^^^^^^^^^^^^^^^^^^^^^^^^^^^^^^^
  File "C:\Users\Kyle_Remote\Documents\Programs\DS3ML3_Final_Project\.venv\Lib\site-packages\torch\serialization.py", line 1026, in load
    return _load(opened_zipfile,
           ^^^^^^^^^^^^^^^^^^^^^
  File "C:\Users\Kyle_Remote\Documents\Programs\DS3ML3_Final_Project\.venv\Lib\site-packages\torch\serialization.py", line 1438, in _load
    result = unpickler.load()
             ^^^^^^^^^^^^^^^^
  File "C:\Users\Kyle_Remote\Documents\Programs\DS3ML3_Final_Project\.venv\Lib\site-packages\torch\serialization.py", line 1431, in find_class
    return super().find_class(mod_name, name)
           ^^^^^^^^^^^^^^^^^^^^^^^^^^^^^^^^^^
ModuleNotFoundError: No module named 'chess_SL_E5_lib'

2024-04-21 11:09:41,228 urllib3.connectionpool (connectionpool.py:292) DEBUG Resetting dropped connection: lichess.org
2024-04-21 11:09:41,754 urllib3.connectionpool (connectionpool.py:549) DEBUG https://lichess.org:443 "GET /api/bot/game/stream/IPPi87y5 HTTP/1.1" 200 None
2024-04-21 11:09:41,755 __mp_main__ (lichess-bot.py:605) DEBUG Initial state: {'id': 'IPPi87y5', 'variant': {'key': 'standard', 'name': 'Standard', 'short': 'Std'}, 'speed': 'blitz', 'perf': {'name': 'Blitz'}, 'rated': False, 'createdAt': 1713711580395, 'white': {'id': 'ks_chessai', 'name': 'KS_ChessAI', 'title': 'BOT', 'rating': 2000, 'provisional': True}, 'black': {'id': 'checkyle', 'name': 'ChecKyle', 'title': None, 'rating': 1410, 'provisional': True}, 'initialFen': 'startpos', 'clock': {'initial': 300000, 'increment': 1000}, 'type': 'gameFull', 'state': {'type': 'gameState', 'moves': '', 'wtime': 300000, 'btime': 300000, 'winc': 1000, 'binc': 1000, 'status': 'aborted', 'rematch': 'xNawCt5b'}}
2024-04-21 11:09:41,757 backoff (_common.py:120) ERROR Giving up play_game(...) after 11 tries (ModuleNotFoundError: No module named 'chess_SL_E5_lib')
2024-04-21 11:09:41,770 __main__ (lichess-bot.py:503) ERROR Game ended due to error:
multiprocessing.pool.RemoteTraceback: 
"""
Traceback (most recent call last):
  File "C:\Users\Kyle_Remote\AppData\Local\Programs\Python\Python311\Lib\multiprocessing\pool.py", line 125, in worker
    result = (True, func(*args, **kwds))
                    ^^^^^^^^^^^^^^^^^^^
  File "C:\Users\Kyle_Remote\Documents\Programs\DS3ML3_Final_Project\.venv\Lib\site-packages\backoff\_sync.py", line 105, in retry
    ret = target(*args, **kwargs)
          ^^^^^^^^^^^^^^^^^^^^^^^
  File "C:\Users\Kyle_Remote\Documents\Programs\DS3ML3_Final_Project\lichess-bot\lichess-bot.py", line 609, in play_game
    with engine_wrapper.create_engine(config, game) as engine:
         ^^^^^^^^^^^^^^^^^^^^^^^^^^^^^^^^^^^^^^^^^^
  File "C:\Users\Kyle_Remote\Documents\Programs\DS3ML3_Final_Project\lichess-bot\lib\engine_wrapper.py", line 63, in create_engine
    Engine = getHomemadeEngine(cfg.name)
             ^^^^^^^^^^^^^^^^^^^^^^^^^^^
  File "C:\Users\Kyle_Remote\Documents\Programs\DS3ML3_Final_Project\lichess-bot\lib\engine_wrapper.py", line 620, in getHomemadeEngine
    import homemade
  File "C:\Users\Kyle_Remote\Documents\Programs\DS3ML3_Final_Project\lichess-bot\homemade.py", line 27, in <module>
    model_loaded = torch.load('../models_EL/model_E7-2.pth', map_location=device)
                   ^^^^^^^^^^^^^^^^^^^^^^^^^^^^^^^^^^^^^^^^^^^^^^^^^^^^^^^^^^^^^^
  File "C:\Users\Kyle_Remote\Documents\Programs\DS3ML3_Final_Project\.venv\Lib\site-packages\torch\serialization.py", line 1026, in load
    return _load(opened_zipfile,
           ^^^^^^^^^^^^^^^^^^^^^
  File "C:\Users\Kyle_Remote\Documents\Programs\DS3ML3_Final_Project\.venv\Lib\site-packages\torch\serialization.py", line 1438, in _load
    result = unpickler.load()
             ^^^^^^^^^^^^^^^^
  File "C:\Users\Kyle_Remote\Documents\Programs\DS3ML3_Final_Project\.venv\Lib\site-packages\torch\serialization.py", line 1431, in find_class
    return super().find_class(mod_name, name)
           ^^^^^^^^^^^^^^^^^^^^^^^^^^^^^^^^^^
ModuleNotFoundError: No module named 'chess_SL_E5_lib'
"""

The above exception was the direct cause of the following exception:

ModuleNotFoundError: No module named 'chess_SL_E5_lib'
2024-04-21 11:09:41,815 urllib3.connectionpool (connectionpool.py:292) DEBUG Resetting dropped connection: lichess.org
2024-04-21 11:09:42,365 urllib3.connectionpool (connectionpool.py:549) DEBUG https://lichess.org:443 "GET /game/export/IPPi87y5 HTTP/1.1" 200 337
2024-04-21 11:09:42,471 urllib3.connectionpool (connectionpool.py:549) DEBUG https://lichess.org:443 "GET /api/account/playing HTTP/1.1" 200 None
2024-04-21 11:09:42,475 __main__ (lichess-bot.py:404) DEBUG Event: {'type': 'local_game_done', 'game': {'id': 'IPPi87y5', 'pgn': '[Event "Casual blitz game"]\n[Site "https://lichess.org/IPPi87y5"]\n[Date "2024.04.21"]\n[White "KS_ChessAI"]\n[Black "ChecKyle"]\n[Result "*"]\n[UTCDate "2024.04.21"]\n[UTCTime "14:59:40"]\n[WhiteElo "2000"]\n[BlackElo "1410"]\n[WhiteTitle "BOT"]\n[Variant "Standard"]\n[TimeControl "300+1"]\n[ECO "?"]\n[Opening "?"]\n[Termination "Abandoned"]\n\n *\n\n\n', 'complete': True}}
2024-04-21 11:09:42,477 __main__ (lichess-bot.py:274) INFO +++ Process Freed. Count: 1. IDs: {'xNawCt5b'}
2024-04-21 11:10:10,229 urllib3.connectionpool (connectionpool.py:292) DEBUG Resetting dropped connection: lichess.org
2024-04-21 11:10:10,769 urllib3.connectionpool (connectionpool.py:549) DEBUG https://lichess.org:443 "GET /api/bot/game/stream/xNawCt5b HTTP/1.1" 200 None
2024-04-21 11:10:10,769 __mp_main__ (lichess-bot.py:605) DEBUG Initial state: {'id': 'xNawCt5b', 'variant': {'key': 'standard', 'name': 'Standard', 'short': 'Std'}, 'speed': 'blitz', 'perf': {'name': 'Blitz'}, 'rated': False, 'createdAt': 1713711634124, 'white': {'id': 'checkyle', 'name': 'ChecKyle', 'title': None, 'rating': 1410, 'provisional': True}, 'black': {'id': 'ks_chessai', 'name': 'KS_ChessAI', 'title': 'BOT', 'rating': 2000, 'provisional': True}, 'initialFen': 'startpos', 'clock': {'initial': 300000, 'increment': 1000}, 'type': 'gameFull', 'state': {'type': 'gameState', 'moves': 'e2e4', 'wtime': 300000, 'btime': 300000, 'winc': 1000, 'binc': 1000, 'status': 'started'}}
2024-04-21 11:10:10,771 backoff (_common.py:105) INFO Backing off play_game(...) for 24.0s (ModuleNotFoundError: No module named 'chess_SL_E5_lib')
2024-04-21 11:10:10,771 lib.lichess (lichess.py:63) DEBUG Backing off 24.0 seconds after 11 tries calling function <function play_game at 0x0000020C53F48680> with args () and kwargs {'li': <lib.lichess.Lichess object at 0x0000020C53F46950>, 'control_queue': <AutoProxy[Queue] object, typeid 'Queue' at 0x20c53fa0690>, 'user_profile': {'id': 'ks_chessai', 'username': 'KS_ChessAI', 'perfs': {'bullet': {'games': 0, 'rating': 2000, 'rd': 500, 'prog': 0, 'prov': True}, 'blitz': {'games': 0, 'rating': 2000, 'rd': 500, 'prog': 0, 'prov': True}, 'rapid': {'games': 0, 'rating': 2000, 'rd': 500, 'prog': 0, 'prov': True}, 'classical': {'games': 0, 'rating': 2000, 'rd': 500, 'prog': 0, 'prov': True}, 'correspondence': {'games': 0, 'rating': 2000, 'rd': 500, 'prog': 0, 'prov': True}}, 'title': 'BOT', 'createdAt': 1711486329716, 'seenAt': 1713625564792, 'playTime': {'total': 15628, 'tv': 0}, 'url': 'https://lichess.org/@/KS_ChessAI', 'count': {'all': 113, 'rated': 0, 'ai': 0, 'draw': 11, 'drawH': 11, 'loss': 89, 'lossH': 89, 'win': 13, 'winH': 13, 'bookmark': 0, 'playing': 0, 'import': 0, 'me': 0}, 'followable': True, 'following': False, 'blocking': False, 'followsYou': False}, 'config': <lib.config.Configuration object at 0x0000020C53FA1F10>, 'challenge_queue': <ListProxy object, typeid 'list' at 0x20c53fa8550>, 'correspondence_queue': <AutoProxy[Queue] object, typeid 'Queue' at 0x20c53fa8790>, 'logging_queue': <AutoProxy[Queue] object, typeid 'Queue' at 0x20c53fa89d0>, 'game_id': 'xNawCt5b'}
2024-04-21 11:10:10,772 lib.lichess (lichess.py:65) DEBUG Exception: Traceback (most recent call last):
  File "C:\Users\Kyle_Remote\Documents\Programs\DS3ML3_Final_Project\.venv\Lib\site-packages\backoff\_sync.py", line 105, in retry
    ret = target(*args, **kwargs)
          ^^^^^^^^^^^^^^^^^^^^^^^
  File "C:\Users\Kyle_Remote\Documents\Programs\DS3ML3_Final_Project\lichess-bot\lichess-bot.py", line 609, in play_game
    with engine_wrapper.create_engine(config, game) as engine:
         ^^^^^^^^^^^^^^^^^^^^^^^^^^^^^^^^^^^^^^^^^^
  File "C:\Users\Kyle_Remote\Documents\Programs\DS3ML3_Final_Project\lichess-bot\lib\engine_wrapper.py", line 63, in create_engine
    Engine = getHomemadeEngine(cfg.name)
             ^^^^^^^^^^^^^^^^^^^^^^^^^^^
  File "C:\Users\Kyle_Remote\Documents\Programs\DS3ML3_Final_Project\lichess-bot\lib\engine_wrapper.py", line 620, in getHomemadeEngine
    import homemade
  File "C:\Users\Kyle_Remote\Documents\Programs\DS3ML3_Final_Project\lichess-bot\homemade.py", line 27, in <module>
    model_loaded = torch.load('../models_EL/model_E7-2.pth', map_location=device)
                   ^^^^^^^^^^^^^^^^^^^^^^^^^^^^^^^^^^^^^^^^^^^^^^^^^^^^^^^^^^^^^^
  File "C:\Users\Kyle_Remote\Documents\Programs\DS3ML3_Final_Project\.venv\Lib\site-packages\torch\serialization.py", line 1026, in load
    return _load(opened_zipfile,
           ^^^^^^^^^^^^^^^^^^^^^
  File "C:\Users\Kyle_Remote\Documents\Programs\DS3ML3_Final_Project\.venv\Lib\site-packages\torch\serialization.py", line 1438, in _load
    result = unpickler.load()
             ^^^^^^^^^^^^^^^^
  File "C:\Users\Kyle_Remote\Documents\Programs\DS3ML3_Final_Project\.venv\Lib\site-packages\torch\serialization.py", line 1431, in find_class
    return super().find_class(mod_name, name)
           ^^^^^^^^^^^^^^^^^^^^^^^^^^^^^^^^^^
ModuleNotFoundError: No module named 'chess_SL_E5_lib'

2024-04-21 11:10:10,957 __main__ (lichess-bot.py:404) DEBUG Event: {'type': 'correspondence_ping'}
2024-04-21 11:10:34,821 urllib3.connectionpool (connectionpool.py:292) DEBUG Resetting dropped connection: lichess.org
2024-04-21 11:10:35,346 urllib3.connectionpool (connectionpool.py:549) DEBUG https://lichess.org:443 "GET /api/bot/game/stream/xNawCt5b HTTP/1.1" 200 None
2024-04-21 11:10:35,347 __mp_main__ (lichess-bot.py:605) DEBUG Initial state: {'id': 'xNawCt5b', 'variant': {'key': 'standard', 'name': 'Standard', 'short': 'Std'}, 'speed': 'blitz', 'perf': {'name': 'Blitz'}, 'rated': False, 'createdAt': 1713711634124, 'white': {'id': 'checkyle', 'name': 'ChecKyle', 'title': None, 'rating': 1410, 'provisional': True}, 'black': {'id': 'ks_chessai', 'name': 'KS_ChessAI', 'title': 'BOT', 'rating': 2000, 'provisional': True}, 'initialFen': 'startpos', 'clock': {'initial': 300000, 'increment': 1000}, 'type': 'gameFull', 'state': {'type': 'gameState', 'moves': 'e2e4', 'wtime': 300000, 'btime': 300000, 'winc': 1000, 'binc': 1000, 'status': 'started'}}
2024-04-21 11:10:35,349 backoff (_common.py:120) ERROR Giving up play_game(...) after 12 tries (ModuleNotFoundError: No module named 'chess_SL_E5_lib')
2024-04-21 11:10:35,350 __main__ (lichess-bot.py:503) ERROR Game ended due to error:
multiprocessing.pool.RemoteTraceback: 
"""
Traceback (most recent call last):
  File "C:\Users\Kyle_Remote\AppData\Local\Programs\Python\Python311\Lib\multiprocessing\pool.py", line 125, in worker
    result = (True, func(*args, **kwds))
                    ^^^^^^^^^^^^^^^^^^^
  File "C:\Users\Kyle_Remote\Documents\Programs\DS3ML3_Final_Project\.venv\Lib\site-packages\backoff\_sync.py", line 105, in retry
    ret = target(*args, **kwargs)
          ^^^^^^^^^^^^^^^^^^^^^^^
  File "C:\Users\Kyle_Remote\Documents\Programs\DS3ML3_Final_Project\lichess-bot\lichess-bot.py", line 609, in play_game
    with engine_wrapper.create_engine(config, game) as engine:
         ^^^^^^^^^^^^^^^^^^^^^^^^^^^^^^^^^^^^^^^^^^
  File "C:\Users\Kyle_Remote\Documents\Programs\DS3ML3_Final_Project\lichess-bot\lib\engine_wrapper.py", line 63, in create_engine
    Engine = getHomemadeEngine(cfg.name)
             ^^^^^^^^^^^^^^^^^^^^^^^^^^^
  File "C:\Users\Kyle_Remote\Documents\Programs\DS3ML3_Final_Project\lichess-bot\lib\engine_wrapper.py", line 620, in getHomemadeEngine
    import homemade
  File "C:\Users\Kyle_Remote\Documents\Programs\DS3ML3_Final_Project\lichess-bot\homemade.py", line 27, in <module>
    model_loaded = torch.load('../models_EL/model_E7-2.pth', map_location=device)
                   ^^^^^^^^^^^^^^^^^^^^^^^^^^^^^^^^^^^^^^^^^^^^^^^^^^^^^^^^^^^^^^
  File "C:\Users\Kyle_Remote\Documents\Programs\DS3ML3_Final_Project\.venv\Lib\site-packages\torch\serialization.py", line 1026, in load
    return _load(opened_zipfile,
           ^^^^^^^^^^^^^^^^^^^^^
  File "C:\Users\Kyle_Remote\Documents\Programs\DS3ML3_Final_Project\.venv\Lib\site-packages\torch\serialization.py", line 1438, in _load
    result = unpickler.load()
             ^^^^^^^^^^^^^^^^
  File "C:\Users\Kyle_Remote\Documents\Programs\DS3ML3_Final_Project\.venv\Lib\site-packages\torch\serialization.py", line 1431, in find_class
    return super().find_class(mod_name, name)
           ^^^^^^^^^^^^^^^^^^^^^^^^^^^^^^^^^^
ModuleNotFoundError: No module named 'chess_SL_E5_lib'
"""

The above exception was the direct cause of the following exception:

ModuleNotFoundError: No module named 'chess_SL_E5_lib'
2024-04-21 11:10:35,354 urllib3.connectionpool (connectionpool.py:292) DEBUG Resetting dropped connection: lichess.org
2024-04-21 11:10:35,894 urllib3.connectionpool (connectionpool.py:549) DEBUG https://lichess.org:443 "GET /game/export/xNawCt5b HTTP/1.1" 200 381
2024-04-21 11:10:35,995 urllib3.connectionpool (connectionpool.py:549) DEBUG https://lichess.org:443 "GET /api/account/playing HTTP/1.1" 200 None
2024-04-21 11:10:35,997 __main__ (lichess-bot.py:404) DEBUG Event: {'type': 'local_game_done', 'game': {'id': 'xNawCt5b', 'pgn': '[Event "Casual blitz game"]\n[Site "https://lichess.org/xNawCt5b"]\n[Date "2024.04.21"]\n[White "ChecKyle"]\n[Black "KS_ChessAI"]\n[Result "*"]\n[UTCDate "2024.04.21"]\n[UTCTime "15:00:34"]\n[WhiteElo "1410"]\n[BlackElo "2000"]\n[BlackTitle "BOT"]\n[Variant "Standard"]\n[TimeControl "300+1"]\n[ECO "B00"]\n[Opening "King\'s Pawn Game"]\n[Termination "Unterminated"]\n\n1. e4 { [%clk 0:05:00] } *\n\n\n', 'complete': False}}
2024-04-21 11:10:35,998 __main__ (lichess-bot.py:274) INFO +++ Process Freed. Count: 0. IDs: None
2024-04-21 11:15:10,957 __main__ (lichess-bot.py:404) DEBUG Event: {'type': 'correspondence_ping'}
2024-04-21 11:20:10,957 __main__ (lichess-bot.py:404) DEBUG Event: {'type': 'correspondence_ping'}
2024-04-21 11:21:41,909 urllib3.connectionpool (connectionpool.py:292) DEBUG Resetting dropped connection: lichess.org
2024-04-21 11:21:42,474 urllib3.connectionpool (connectionpool.py:549) DEBUG https://lichess.org:443 "GET /api/users/status?ids=ks_chessai HTTP/1.1" 200 None
2024-04-21 11:25:10,957 __main__ (lichess-bot.py:404) DEBUG Event: {'type': 'correspondence_ping'}
2024-04-21 11:30:10,958 __main__ (lichess-bot.py:404) DEBUG Event: {'type': 'correspondence_ping'}
2024-04-21 11:31:48,614 __main__ (lichess-bot.py:404) DEBUG Event: {'type': 'challenge', 'challenge': {'id': 'uDhc2Mkh', 'url': 'https://lichess.org/uDhc2Mkh', 'status': 'created', 'challenger': {'id': 'checkyle', 'name': 'ChecKyle', 'rating': 1410, 'title': None, 'provisional': True, 'online': True, 'lag': 4}, 'destUser': {'id': 'ks_chessai', 'name': 'KS_ChessAI', 'rating': 2000, 'title': 'BOT', 'provisional': True, 'online': True}, 'variant': {'key': 'standard', 'name': 'Standard', 'short': 'Std'}, 'rated': False, 'speed': 'blitz', 'timeControl': {'type': 'clock', 'limit': 300, 'increment': 1, 'show': '5+1'}, 'color': 'random', 'finalColor': 'black', 'perf': {'icon': '\ue01d', 'name': 'Blitz'}}, 'compat': {'bot': True, 'board': True}}
2024-04-21 11:31:48,616 __main__ (lichess-bot.py:455) INFO Accept Blitz casual challenge from ChecKyle (1410?) (uDhc2Mkh)
2024-04-21 11:31:48,618 urllib3.connectionpool (connectionpool.py:292) DEBUG Resetting dropped connection: lichess.org
2024-04-21 11:31:49,223 urllib3.connectionpool (connectionpool.py:549) DEBUG https://lichess.org:443 "POST /api/challenge/uDhc2Mkh/accept HTTP/1.1" 200 11
2024-04-21 11:31:49,224 __main__ (lichess-bot.py:274) INFO --- Process Queued. Count: 1. IDs: {'uDhc2Mkh'}
2024-04-21 11:31:49,224 __main__ (lichess-bot.py:404) DEBUG Event: {'type': 'gameStart', 'game': {'fullId': 'uDhc2MkhLc2J', 'gameId': 'uDhc2Mkh', 'fen': 'rnbqkbnr/pppppppp/8/8/8/8/PPPPPPPP/RNBQKBNR w KQkq - 0 1', 'color': 'white', 'lastMove': '', 'source': 'friend', 'status': {'id': 20, 'name': 'started'}, 'variant': {'key': 'standard', 'name': 'Standard'}, 'speed': 'blitz', 'perf': 'blitz', 'rated': False, 'hasMoved': False, 'opponent': {'id': 'checkyle', 'username': 'ChecKyle', 'rating': 1410}, 'isMyTurn': True, 'secondsLeft': 300, 'compat': {'bot': True, 'board': True}, 'id': 'uDhc2Mkh'}}
2024-04-21 11:31:49,225 __main__ (lichess-bot.py:274) INFO --- Process Used. Count: 1. IDs: {'uDhc2Mkh'}
2024-04-21 11:31:49,336 urllib3.connectionpool (connectionpool.py:1055) DEBUG Starting new HTTPS connection (1): lichess.org:443
2024-04-21 11:31:49,897 urllib3.connectionpool (connectionpool.py:549) DEBUG https://lichess.org:443 "GET /api/bot/game/stream/uDhc2Mkh HTTP/1.1" 200 None
2024-04-21 11:31:49,898 __mp_main__ (lichess-bot.py:605) DEBUG Initial state: {'id': 'uDhc2Mkh', 'variant': {'key': 'standard', 'name': 'Standard', 'short': 'Std'}, 'speed': 'blitz', 'perf': {'name': 'Blitz'}, 'rated': False, 'createdAt': 1713713509154, 'white': {'id': 'ks_chessai', 'name': 'KS_ChessAI', 'title': 'BOT', 'rating': 2000, 'provisional': True}, 'black': {'id': 'checkyle', 'name': 'ChecKyle', 'title': None, 'rating': 1410, 'provisional': True}, 'initialFen': 'startpos', 'clock': {'initial': 300000, 'increment': 1000}, 'type': 'gameFull', 'state': {'type': 'gameState', 'moves': '', 'wtime': 300000, 'btime': 300000, 'winc': 1000, 'binc': 1000, 'status': 'started'}}
2024-04-21 11:31:50,117 matplotlib (__init__.py:350) DEBUG matplotlib data path: C:\Users\Kyle_Remote\Documents\Programs\DS3ML3_Final_Project\.venv\Lib\site-packages\matplotlib\mpl-data
2024-04-21 11:31:50,122 matplotlib (__init__.py:350) DEBUG CONFIGDIR=C:\Users\Kyle_Remote\.matplotlib
2024-04-21 11:31:50,123 matplotlib (__init__.py:1511) DEBUG interactive is False
2024-04-21 11:31:50,124 matplotlib (__init__.py:1512) DEBUG platform is win32
2024-04-21 11:31:50,172 matplotlib (__init__.py:350) DEBUG CACHEDIR=C:\Users\Kyle_Remote\.matplotlib
2024-04-21 11:31:50,175 matplotlib.font_manager (font_manager.py:1574) DEBUG Using fontManager instance from C:\Users\Kyle_Remote\.matplotlib\fontlist-v330.json
2024-04-21 11:31:52,459 backoff (_common.py:105) INFO Backing off play_game(...) for 0.4s (ModuleNotFoundError: No module named 'chess_SL_E5_lib')
2024-04-21 11:31:52,459 lib.lichess (lichess.py:63) DEBUG Backing off 0.4 seconds after 1 tries calling function <function play_game at 0x000002A322428680> with args () and kwargs {'li': <lib.lichess.Lichess object at 0x000002A322426950>, 'control_queue': <AutoProxy[Queue] object, typeid 'Queue' at 0x2a322480790>, 'user_profile': {'id': 'ks_chessai', 'username': 'KS_ChessAI', 'perfs': {'bullet': {'games': 0, 'rating': 2000, 'rd': 500, 'prog': 0, 'prov': True}, 'blitz': {'games': 0, 'rating': 2000, 'rd': 500, 'prog': 0, 'prov': True}, 'rapid': {'games': 0, 'rating': 2000, 'rd': 500, 'prog': 0, 'prov': True}, 'classical': {'games': 0, 'rating': 2000, 'rd': 500, 'prog': 0, 'prov': True}, 'correspondence': {'games': 0, 'rating': 2000, 'rd': 500, 'prog': 0, 'prov': True}}, 'title': 'BOT', 'createdAt': 1711486329716, 'seenAt': 1713625564792, 'playTime': {'total': 15628, 'tv': 0}, 'url': 'https://lichess.org/@/KS_ChessAI', 'count': {'all': 113, 'rated': 0, 'ai': 0, 'draw': 11, 'drawH': 11, 'loss': 89, 'lossH': 89, 'win': 13, 'winH': 13, 'bookmark': 0, 'playing': 0, 'import': 0, 'me': 0}, 'followable': True, 'following': False, 'blocking': False, 'followsYou': False}, 'config': <lib.config.Configuration object at 0x000002A322481FD0>, 'challenge_queue': <ListProxy object, typeid 'list' at 0x2a322488610>, 'correspondence_queue': <AutoProxy[Queue] object, typeid 'Queue' at 0x2a322488850>, 'logging_queue': <AutoProxy[Queue] object, typeid 'Queue' at 0x2a322488a90>, 'game_id': 'uDhc2Mkh'}
2024-04-21 11:31:52,461 lib.lichess (lichess.py:65) DEBUG Exception: Traceback (most recent call last):
  File "C:\Users\Kyle_Remote\Documents\Programs\DS3ML3_Final_Project\.venv\Lib\site-packages\backoff\_sync.py", line 105, in retry
    ret = target(*args, **kwargs)
          ^^^^^^^^^^^^^^^^^^^^^^^
  File "C:\Users\Kyle_Remote\Documents\Programs\DS3ML3_Final_Project\lichess-bot\lichess-bot.py", line 609, in play_game
    with engine_wrapper.create_engine(config, game) as engine:
         ^^^^^^^^^^^^^^^^^^^^^^^^^^^^^^^^^^^^^^^^^^
  File "C:\Users\Kyle_Remote\Documents\Programs\DS3ML3_Final_Project\lichess-bot\lib\engine_wrapper.py", line 63, in create_engine
    Engine = getHomemadeEngine(cfg.name)
             ^^^^^^^^^^^^^^^^^^^^^^^^^^^
  File "C:\Users\Kyle_Remote\Documents\Programs\DS3ML3_Final_Project\lichess-bot\lib\engine_wrapper.py", line 620, in getHomemadeEngine
    import homemade
  File "C:\Users\Kyle_Remote\Documents\Programs\DS3ML3_Final_Project\lichess-bot\homemade.py", line 27, in <module>
    model_loaded = torch.load('../models_EL/model_E7-2.pth', map_location=device)
                   ^^^^^^^^^^^^^^^^^^^^^^^^^^^^^^^^^^^^^^^^^^^^^^^^^^^^^^^^^^^^^^
  File "C:\Users\Kyle_Remote\Documents\Programs\DS3ML3_Final_Project\.venv\Lib\site-packages\torch\serialization.py", line 1026, in load
    return _load(opened_zipfile,
           ^^^^^^^^^^^^^^^^^^^^^
  File "C:\Users\Kyle_Remote\Documents\Programs\DS3ML3_Final_Project\.venv\Lib\site-packages\torch\serialization.py", line 1438, in _load
    result = unpickler.load()
             ^^^^^^^^^^^^^^^^
  File "C:\Users\Kyle_Remote\Documents\Programs\DS3ML3_Final_Project\.venv\Lib\site-packages\torch\serialization.py", line 1431, in find_class
    return super().find_class(mod_name, name)
           ^^^^^^^^^^^^^^^^^^^^^^^^^^^^^^^^^^
ModuleNotFoundError: No module named 'chess_SL_E5_lib'

2024-04-21 11:31:52,827 urllib3.connectionpool (connectionpool.py:1055) DEBUG Starting new HTTPS connection (2): lichess.org:443
2024-04-21 11:31:53,370 urllib3.connectionpool (connectionpool.py:549) DEBUG https://lichess.org:443 "GET /api/bot/game/stream/uDhc2Mkh HTTP/1.1" 200 None
2024-04-21 11:31:53,371 __mp_main__ (lichess-bot.py:605) DEBUG Initial state: {'id': 'uDhc2Mkh', 'variant': {'key': 'standard', 'name': 'Standard', 'short': 'Std'}, 'speed': 'blitz', 'perf': {'name': 'Blitz'}, 'rated': False, 'createdAt': 1713713509154, 'white': {'id': 'ks_chessai', 'name': 'KS_ChessAI', 'title': 'BOT', 'rating': 2000, 'provisional': True}, 'black': {'id': 'checkyle', 'name': 'ChecKyle', 'title': None, 'rating': 1410, 'provisional': True}, 'initialFen': 'startpos', 'clock': {'initial': 300000, 'increment': 1000}, 'type': 'gameFull', 'state': {'type': 'gameState', 'moves': '', 'wtime': 300000, 'btime': 300000, 'winc': 1000, 'binc': 1000, 'status': 'started'}}
2024-04-21 11:31:53,374 backoff (_common.py:105) INFO Backing off play_game(...) for 1.8s (ModuleNotFoundError: No module named 'chess_SL_E5_lib')
2024-04-21 11:31:53,374 lib.lichess (lichess.py:63) DEBUG Backing off 1.8 seconds after 2 tries calling function <function play_game at 0x000002A322428680> with args () and kwargs {'li': <lib.lichess.Lichess object at 0x000002A322426950>, 'control_queue': <AutoProxy[Queue] object, typeid 'Queue' at 0x2a322480790>, 'user_profile': {'id': 'ks_chessai', 'username': 'KS_ChessAI', 'perfs': {'bullet': {'games': 0, 'rating': 2000, 'rd': 500, 'prog': 0, 'prov': True}, 'blitz': {'games': 0, 'rating': 2000, 'rd': 500, 'prog': 0, 'prov': True}, 'rapid': {'games': 0, 'rating': 2000, 'rd': 500, 'prog': 0, 'prov': True}, 'classical': {'games': 0, 'rating': 2000, 'rd': 500, 'prog': 0, 'prov': True}, 'correspondence': {'games': 0, 'rating': 2000, 'rd': 500, 'prog': 0, 'prov': True}}, 'title': 'BOT', 'createdAt': 1711486329716, 'seenAt': 1713625564792, 'playTime': {'total': 15628, 'tv': 0}, 'url': 'https://lichess.org/@/KS_ChessAI', 'count': {'all': 113, 'rated': 0, 'ai': 0, 'draw': 11, 'drawH': 11, 'loss': 89, 'lossH': 89, 'win': 13, 'winH': 13, 'bookmark': 0, 'playing': 0, 'import': 0, 'me': 0}, 'followable': True, 'following': False, 'blocking': False, 'followsYou': False}, 'config': <lib.config.Configuration object at 0x000002A322481FD0>, 'challenge_queue': <ListProxy object, typeid 'list' at 0x2a322488610>, 'correspondence_queue': <AutoProxy[Queue] object, typeid 'Queue' at 0x2a322488850>, 'logging_queue': <AutoProxy[Queue] object, typeid 'Queue' at 0x2a322488a90>, 'game_id': 'uDhc2Mkh'}
2024-04-21 11:31:53,376 lib.lichess (lichess.py:65) DEBUG Exception: Traceback (most recent call last):
  File "C:\Users\Kyle_Remote\Documents\Programs\DS3ML3_Final_Project\.venv\Lib\site-packages\backoff\_sync.py", line 105, in retry
    ret = target(*args, **kwargs)
          ^^^^^^^^^^^^^^^^^^^^^^^
  File "C:\Users\Kyle_Remote\Documents\Programs\DS3ML3_Final_Project\lichess-bot\lichess-bot.py", line 609, in play_game
    with engine_wrapper.create_engine(config, game) as engine:
         ^^^^^^^^^^^^^^^^^^^^^^^^^^^^^^^^^^^^^^^^^^
  File "C:\Users\Kyle_Remote\Documents\Programs\DS3ML3_Final_Project\lichess-bot\lib\engine_wrapper.py", line 63, in create_engine
    Engine = getHomemadeEngine(cfg.name)
             ^^^^^^^^^^^^^^^^^^^^^^^^^^^
  File "C:\Users\Kyle_Remote\Documents\Programs\DS3ML3_Final_Project\lichess-bot\lib\engine_wrapper.py", line 620, in getHomemadeEngine
    import homemade
  File "C:\Users\Kyle_Remote\Documents\Programs\DS3ML3_Final_Project\lichess-bot\homemade.py", line 27, in <module>
    model_loaded = torch.load('../models_EL/model_E7-2.pth', map_location=device)
                   ^^^^^^^^^^^^^^^^^^^^^^^^^^^^^^^^^^^^^^^^^^^^^^^^^^^^^^^^^^^^^^
  File "C:\Users\Kyle_Remote\Documents\Programs\DS3ML3_Final_Project\.venv\Lib\site-packages\torch\serialization.py", line 1026, in load
    return _load(opened_zipfile,
           ^^^^^^^^^^^^^^^^^^^^^
  File "C:\Users\Kyle_Remote\Documents\Programs\DS3ML3_Final_Project\.venv\Lib\site-packages\torch\serialization.py", line 1438, in _load
    result = unpickler.load()
             ^^^^^^^^^^^^^^^^
  File "C:\Users\Kyle_Remote\Documents\Programs\DS3ML3_Final_Project\.venv\Lib\site-packages\torch\serialization.py", line 1431, in find_class
    return super().find_class(mod_name, name)
           ^^^^^^^^^^^^^^^^^^^^^^^^^^^^^^^^^^
ModuleNotFoundError: No module named 'chess_SL_E5_lib'

2024-04-21 11:31:55,148 urllib3.connectionpool (connectionpool.py:292) DEBUG Resetting dropped connection: lichess.org
2024-04-21 11:31:55,712 urllib3.connectionpool (connectionpool.py:549) DEBUG https://lichess.org:443 "GET /api/bot/game/stream/uDhc2Mkh HTTP/1.1" 200 None
2024-04-21 11:31:55,713 __mp_main__ (lichess-bot.py:605) DEBUG Initial state: {'id': 'uDhc2Mkh', 'variant': {'key': 'standard', 'name': 'Standard', 'short': 'Std'}, 'speed': 'blitz', 'perf': {'name': 'Blitz'}, 'rated': False, 'createdAt': 1713713509154, 'white': {'id': 'ks_chessai', 'name': 'KS_ChessAI', 'title': 'BOT', 'rating': 2000, 'provisional': True}, 'black': {'id': 'checkyle', 'name': 'ChecKyle', 'title': None, 'rating': 1410, 'provisional': True}, 'initialFen': 'startpos', 'clock': {'initial': 300000, 'increment': 1000}, 'type': 'gameFull', 'state': {'type': 'gameState', 'moves': '', 'wtime': 300000, 'btime': 300000, 'winc': 1000, 'binc': 1000, 'status': 'started'}}
2024-04-21 11:31:55,714 backoff (_common.py:105) INFO Backing off play_game(...) for 3.4s (ModuleNotFoundError: No module named 'chess_SL_E5_lib')
2024-04-21 11:31:55,715 lib.lichess (lichess.py:63) DEBUG Backing off 3.4 seconds after 3 tries calling function <function play_game at 0x000002A322428680> with args () and kwargs {'li': <lib.lichess.Lichess object at 0x000002A322426950>, 'control_queue': <AutoProxy[Queue] object, typeid 'Queue' at 0x2a322480790>, 'user_profile': {'id': 'ks_chessai', 'username': 'KS_ChessAI', 'perfs': {'bullet': {'games': 0, 'rating': 2000, 'rd': 500, 'prog': 0, 'prov': True}, 'blitz': {'games': 0, 'rating': 2000, 'rd': 500, 'prog': 0, 'prov': True}, 'rapid': {'games': 0, 'rating': 2000, 'rd': 500, 'prog': 0, 'prov': True}, 'classical': {'games': 0, 'rating': 2000, 'rd': 500, 'prog': 0, 'prov': True}, 'correspondence': {'games': 0, 'rating': 2000, 'rd': 500, 'prog': 0, 'prov': True}}, 'title': 'BOT', 'createdAt': 1711486329716, 'seenAt': 1713625564792, 'playTime': {'total': 15628, 'tv': 0}, 'url': 'https://lichess.org/@/KS_ChessAI', 'count': {'all': 113, 'rated': 0, 'ai': 0, 'draw': 11, 'drawH': 11, 'loss': 89, 'lossH': 89, 'win': 13, 'winH': 13, 'bookmark': 0, 'playing': 0, 'import': 0, 'me': 0}, 'followable': True, 'following': False, 'blocking': False, 'followsYou': False}, 'config': <lib.config.Configuration object at 0x000002A322481FD0>, 'challenge_queue': <ListProxy object, typeid 'list' at 0x2a322488610>, 'correspondence_queue': <AutoProxy[Queue] object, typeid 'Queue' at 0x2a322488850>, 'logging_queue': <AutoProxy[Queue] object, typeid 'Queue' at 0x2a322488a90>, 'game_id': 'uDhc2Mkh'}
2024-04-21 11:31:55,715 lib.lichess (lichess.py:65) DEBUG Exception: Traceback (most recent call last):
  File "C:\Users\Kyle_Remote\Documents\Programs\DS3ML3_Final_Project\.venv\Lib\site-packages\backoff\_sync.py", line 105, in retry
    ret = target(*args, **kwargs)
          ^^^^^^^^^^^^^^^^^^^^^^^
  File "C:\Users\Kyle_Remote\Documents\Programs\DS3ML3_Final_Project\lichess-bot\lichess-bot.py", line 609, in play_game
    with engine_wrapper.create_engine(config, game) as engine:
         ^^^^^^^^^^^^^^^^^^^^^^^^^^^^^^^^^^^^^^^^^^
  File "C:\Users\Kyle_Remote\Documents\Programs\DS3ML3_Final_Project\lichess-bot\lib\engine_wrapper.py", line 63, in create_engine
    Engine = getHomemadeEngine(cfg.name)
             ^^^^^^^^^^^^^^^^^^^^^^^^^^^
  File "C:\Users\Kyle_Remote\Documents\Programs\DS3ML3_Final_Project\lichess-bot\lib\engine_wrapper.py", line 620, in getHomemadeEngine
    import homemade
  File "C:\Users\Kyle_Remote\Documents\Programs\DS3ML3_Final_Project\lichess-bot\homemade.py", line 27, in <module>
    model_loaded = torch.load('../models_EL/model_E7-2.pth', map_location=device)
                   ^^^^^^^^^^^^^^^^^^^^^^^^^^^^^^^^^^^^^^^^^^^^^^^^^^^^^^^^^^^^^^
  File "C:\Users\Kyle_Remote\Documents\Programs\DS3ML3_Final_Project\.venv\Lib\site-packages\torch\serialization.py", line 1026, in load
    return _load(opened_zipfile,
           ^^^^^^^^^^^^^^^^^^^^^
  File "C:\Users\Kyle_Remote\Documents\Programs\DS3ML3_Final_Project\.venv\Lib\site-packages\torch\serialization.py", line 1438, in _load
    result = unpickler.load()
             ^^^^^^^^^^^^^^^^
  File "C:\Users\Kyle_Remote\Documents\Programs\DS3ML3_Final_Project\.venv\Lib\site-packages\torch\serialization.py", line 1431, in find_class
    return super().find_class(mod_name, name)
           ^^^^^^^^^^^^^^^^^^^^^^^^^^^^^^^^^^
ModuleNotFoundError: No module named 'chess_SL_E5_lib'

2024-04-21 11:31:59,133 urllib3.connectionpool (connectionpool.py:292) DEBUG Resetting dropped connection: lichess.org
2024-04-21 11:31:59,685 urllib3.connectionpool (connectionpool.py:549) DEBUG https://lichess.org:443 "GET /api/bot/game/stream/uDhc2Mkh HTTP/1.1" 200 None
2024-04-21 11:31:59,686 __mp_main__ (lichess-bot.py:605) DEBUG Initial state: {'id': 'uDhc2Mkh', 'variant': {'key': 'standard', 'name': 'Standard', 'short': 'Std'}, 'speed': 'blitz', 'perf': {'name': 'Blitz'}, 'rated': False, 'createdAt': 1713713509154, 'white': {'id': 'ks_chessai', 'name': 'KS_ChessAI', 'title': 'BOT', 'rating': 2000, 'provisional': True}, 'black': {'id': 'checkyle', 'name': 'ChecKyle', 'title': None, 'rating': 1410, 'provisional': True}, 'initialFen': 'startpos', 'clock': {'initial': 300000, 'increment': 1000}, 'type': 'gameFull', 'state': {'type': 'gameState', 'moves': '', 'wtime': 300000, 'btime': 300000, 'winc': 1000, 'binc': 1000, 'status': 'started'}}
2024-04-21 11:31:59,687 backoff (_common.py:105) INFO Backing off play_game(...) for 2.1s (ModuleNotFoundError: No module named 'chess_SL_E5_lib')
2024-04-21 11:31:59,688 lib.lichess (lichess.py:63) DEBUG Backing off 2.1 seconds after 4 tries calling function <function play_game at 0x000002A322428680> with args () and kwargs {'li': <lib.lichess.Lichess object at 0x000002A322426950>, 'control_queue': <AutoProxy[Queue] object, typeid 'Queue' at 0x2a322480790>, 'user_profile': {'id': 'ks_chessai', 'username': 'KS_ChessAI', 'perfs': {'bullet': {'games': 0, 'rating': 2000, 'rd': 500, 'prog': 0, 'prov': True}, 'blitz': {'games': 0, 'rating': 2000, 'rd': 500, 'prog': 0, 'prov': True}, 'rapid': {'games': 0, 'rating': 2000, 'rd': 500, 'prog': 0, 'prov': True}, 'classical': {'games': 0, 'rating': 2000, 'rd': 500, 'prog': 0, 'prov': True}, 'correspondence': {'games': 0, 'rating': 2000, 'rd': 500, 'prog': 0, 'prov': True}}, 'title': 'BOT', 'createdAt': 1711486329716, 'seenAt': 1713625564792, 'playTime': {'total': 15628, 'tv': 0}, 'url': 'https://lichess.org/@/KS_ChessAI', 'count': {'all': 113, 'rated': 0, 'ai': 0, 'draw': 11, 'drawH': 11, 'loss': 89, 'lossH': 89, 'win': 13, 'winH': 13, 'bookmark': 0, 'playing': 0, 'import': 0, 'me': 0}, 'followable': True, 'following': False, 'blocking': False, 'followsYou': False}, 'config': <lib.config.Configuration object at 0x000002A322481FD0>, 'challenge_queue': <ListProxy object, typeid 'list' at 0x2a322488610>, 'correspondence_queue': <AutoProxy[Queue] object, typeid 'Queue' at 0x2a322488850>, 'logging_queue': <AutoProxy[Queue] object, typeid 'Queue' at 0x2a322488a90>, 'game_id': 'uDhc2Mkh'}
2024-04-21 11:31:59,688 lib.lichess (lichess.py:65) DEBUG Exception: Traceback (most recent call last):
  File "C:\Users\Kyle_Remote\Documents\Programs\DS3ML3_Final_Project\.venv\Lib\site-packages\backoff\_sync.py", line 105, in retry
    ret = target(*args, **kwargs)
          ^^^^^^^^^^^^^^^^^^^^^^^
  File "C:\Users\Kyle_Remote\Documents\Programs\DS3ML3_Final_Project\lichess-bot\lichess-bot.py", line 609, in play_game
    with engine_wrapper.create_engine(config, game) as engine:
         ^^^^^^^^^^^^^^^^^^^^^^^^^^^^^^^^^^^^^^^^^^
  File "C:\Users\Kyle_Remote\Documents\Programs\DS3ML3_Final_Project\lichess-bot\lib\engine_wrapper.py", line 63, in create_engine
    Engine = getHomemadeEngine(cfg.name)
             ^^^^^^^^^^^^^^^^^^^^^^^^^^^
  File "C:\Users\Kyle_Remote\Documents\Programs\DS3ML3_Final_Project\lichess-bot\lib\engine_wrapper.py", line 620, in getHomemadeEngine
    import homemade
  File "C:\Users\Kyle_Remote\Documents\Programs\DS3ML3_Final_Project\lichess-bot\homemade.py", line 27, in <module>
    model_loaded = torch.load('../models_EL/model_E7-2.pth', map_location=device)
                   ^^^^^^^^^^^^^^^^^^^^^^^^^^^^^^^^^^^^^^^^^^^^^^^^^^^^^^^^^^^^^^
  File "C:\Users\Kyle_Remote\Documents\Programs\DS3ML3_Final_Project\.venv\Lib\site-packages\torch\serialization.py", line 1026, in load
    return _load(opened_zipfile,
           ^^^^^^^^^^^^^^^^^^^^^
  File "C:\Users\Kyle_Remote\Documents\Programs\DS3ML3_Final_Project\.venv\Lib\site-packages\torch\serialization.py", line 1438, in _load
    result = unpickler.load()
             ^^^^^^^^^^^^^^^^
  File "C:\Users\Kyle_Remote\Documents\Programs\DS3ML3_Final_Project\.venv\Lib\site-packages\torch\serialization.py", line 1431, in find_class
    return super().find_class(mod_name, name)
           ^^^^^^^^^^^^^^^^^^^^^^^^^^^^^^^^^^
ModuleNotFoundError: No module named 'chess_SL_E5_lib'

2024-04-21 11:32:01,767 urllib3.connectionpool (connectionpool.py:292) DEBUG Resetting dropped connection: lichess.org
2024-04-21 11:32:02,303 urllib3.connectionpool (connectionpool.py:549) DEBUG https://lichess.org:443 "GET /api/bot/game/stream/uDhc2Mkh HTTP/1.1" 200 None
2024-04-21 11:32:02,304 __mp_main__ (lichess-bot.py:605) DEBUG Initial state: {'id': 'uDhc2Mkh', 'variant': {'key': 'standard', 'name': 'Standard', 'short': 'Std'}, 'speed': 'blitz', 'perf': {'name': 'Blitz'}, 'rated': False, 'createdAt': 1713713509154, 'white': {'id': 'ks_chessai', 'name': 'KS_ChessAI', 'title': 'BOT', 'rating': 2000, 'provisional': True}, 'black': {'id': 'checkyle', 'name': 'ChecKyle', 'title': None, 'rating': 1410, 'provisional': True}, 'initialFen': 'startpos', 'clock': {'initial': 300000, 'increment': 1000}, 'type': 'gameFull', 'state': {'type': 'gameState', 'moves': '', 'wtime': 300000, 'btime': 300000, 'winc': 1000, 'binc': 1000, 'status': 'started'}}
2024-04-21 11:32:02,306 backoff (_common.py:105) INFO Backing off play_game(...) for 14.8s (ModuleNotFoundError: No module named 'chess_SL_E5_lib')
2024-04-21 11:32:02,307 lib.lichess (lichess.py:63) DEBUG Backing off 14.8 seconds after 5 tries calling function <function play_game at 0x000002A322428680> with args () and kwargs {'li': <lib.lichess.Lichess object at 0x000002A322426950>, 'control_queue': <AutoProxy[Queue] object, typeid 'Queue' at 0x2a322480790>, 'user_profile': {'id': 'ks_chessai', 'username': 'KS_ChessAI', 'perfs': {'bullet': {'games': 0, 'rating': 2000, 'rd': 500, 'prog': 0, 'prov': True}, 'blitz': {'games': 0, 'rating': 2000, 'rd': 500, 'prog': 0, 'prov': True}, 'rapid': {'games': 0, 'rating': 2000, 'rd': 500, 'prog': 0, 'prov': True}, 'classical': {'games': 0, 'rating': 2000, 'rd': 500, 'prog': 0, 'prov': True}, 'correspondence': {'games': 0, 'rating': 2000, 'rd': 500, 'prog': 0, 'prov': True}}, 'title': 'BOT', 'createdAt': 1711486329716, 'seenAt': 1713625564792, 'playTime': {'total': 15628, 'tv': 0}, 'url': 'https://lichess.org/@/KS_ChessAI', 'count': {'all': 113, 'rated': 0, 'ai': 0, 'draw': 11, 'drawH': 11, 'loss': 89, 'lossH': 89, 'win': 13, 'winH': 13, 'bookmark': 0, 'playing': 0, 'import': 0, 'me': 0}, 'followable': True, 'following': False, 'blocking': False, 'followsYou': False}, 'config': <lib.config.Configuration object at 0x000002A322481FD0>, 'challenge_queue': <ListProxy object, typeid 'list' at 0x2a322488610>, 'correspondence_queue': <AutoProxy[Queue] object, typeid 'Queue' at 0x2a322488850>, 'logging_queue': <AutoProxy[Queue] object, typeid 'Queue' at 0x2a322488a90>, 'game_id': 'uDhc2Mkh'}
2024-04-21 11:32:02,308 lib.lichess (lichess.py:65) DEBUG Exception: Traceback (most recent call last):
  File "C:\Users\Kyle_Remote\Documents\Programs\DS3ML3_Final_Project\.venv\Lib\site-packages\backoff\_sync.py", line 105, in retry
    ret = target(*args, **kwargs)
          ^^^^^^^^^^^^^^^^^^^^^^^
  File "C:\Users\Kyle_Remote\Documents\Programs\DS3ML3_Final_Project\lichess-bot\lichess-bot.py", line 609, in play_game
    with engine_wrapper.create_engine(config, game) as engine:
         ^^^^^^^^^^^^^^^^^^^^^^^^^^^^^^^^^^^^^^^^^^
  File "C:\Users\Kyle_Remote\Documents\Programs\DS3ML3_Final_Project\lichess-bot\lib\engine_wrapper.py", line 63, in create_engine
    Engine = getHomemadeEngine(cfg.name)
             ^^^^^^^^^^^^^^^^^^^^^^^^^^^
  File "C:\Users\Kyle_Remote\Documents\Programs\DS3ML3_Final_Project\lichess-bot\lib\engine_wrapper.py", line 620, in getHomemadeEngine
    import homemade
  File "C:\Users\Kyle_Remote\Documents\Programs\DS3ML3_Final_Project\lichess-bot\homemade.py", line 27, in <module>
    model_loaded = torch.load('../models_EL/model_E7-2.pth', map_location=device)
                   ^^^^^^^^^^^^^^^^^^^^^^^^^^^^^^^^^^^^^^^^^^^^^^^^^^^^^^^^^^^^^^
  File "C:\Users\Kyle_Remote\Documents\Programs\DS3ML3_Final_Project\.venv\Lib\site-packages\torch\serialization.py", line 1026, in load
    return _load(opened_zipfile,
           ^^^^^^^^^^^^^^^^^^^^^
  File "C:\Users\Kyle_Remote\Documents\Programs\DS3ML3_Final_Project\.venv\Lib\site-packages\torch\serialization.py", line 1438, in _load
    result = unpickler.load()
             ^^^^^^^^^^^^^^^^
  File "C:\Users\Kyle_Remote\Documents\Programs\DS3ML3_Final_Project\.venv\Lib\site-packages\torch\serialization.py", line 1431, in find_class
    return super().find_class(mod_name, name)
           ^^^^^^^^^^^^^^^^^^^^^^^^^^^^^^^^^^
ModuleNotFoundError: No module named 'chess_SL_E5_lib'

2024-04-21 11:32:17,067 urllib3.connectionpool (connectionpool.py:292) DEBUG Resetting dropped connection: lichess.org
2024-04-21 11:32:17,634 urllib3.connectionpool (connectionpool.py:549) DEBUG https://lichess.org:443 "GET /api/bot/game/stream/uDhc2Mkh HTTP/1.1" 200 None
2024-04-21 11:32:17,635 __mp_main__ (lichess-bot.py:605) DEBUG Initial state: {'id': 'uDhc2Mkh', 'variant': {'key': 'standard', 'name': 'Standard', 'short': 'Std'}, 'speed': 'blitz', 'perf': {'name': 'Blitz'}, 'rated': False, 'createdAt': 1713713509154, 'white': {'id': 'ks_chessai', 'name': 'KS_ChessAI', 'title': 'BOT', 'rating': 2000, 'provisional': True}, 'black': {'id': 'checkyle', 'name': 'ChecKyle', 'title': None, 'rating': 1410, 'provisional': True}, 'initialFen': 'startpos', 'clock': {'initial': 300000, 'increment': 1000}, 'type': 'gameFull', 'state': {'type': 'gameState', 'moves': '', 'wtime': 300000, 'btime': 300000, 'winc': 1000, 'binc': 1000, 'status': 'started'}}
2024-04-21 11:32:17,637 backoff (_common.py:105) INFO Backing off play_game(...) for 17.4s (ModuleNotFoundError: No module named 'chess_SL_E5_lib')
2024-04-21 11:32:17,638 lib.lichess (lichess.py:63) DEBUG Backing off 17.4 seconds after 6 tries calling function <function play_game at 0x000002A322428680> with args () and kwargs {'li': <lib.lichess.Lichess object at 0x000002A322426950>, 'control_queue': <AutoProxy[Queue] object, typeid 'Queue' at 0x2a322480790>, 'user_profile': {'id': 'ks_chessai', 'username': 'KS_ChessAI', 'perfs': {'bullet': {'games': 0, 'rating': 2000, 'rd': 500, 'prog': 0, 'prov': True}, 'blitz': {'games': 0, 'rating': 2000, 'rd': 500, 'prog': 0, 'prov': True}, 'rapid': {'games': 0, 'rating': 2000, 'rd': 500, 'prog': 0, 'prov': True}, 'classical': {'games': 0, 'rating': 2000, 'rd': 500, 'prog': 0, 'prov': True}, 'correspondence': {'games': 0, 'rating': 2000, 'rd': 500, 'prog': 0, 'prov': True}}, 'title': 'BOT', 'createdAt': 1711486329716, 'seenAt': 1713625564792, 'playTime': {'total': 15628, 'tv': 0}, 'url': 'https://lichess.org/@/KS_ChessAI', 'count': {'all': 113, 'rated': 0, 'ai': 0, 'draw': 11, 'drawH': 11, 'loss': 89, 'lossH': 89, 'win': 13, 'winH': 13, 'bookmark': 0, 'playing': 0, 'import': 0, 'me': 0}, 'followable': True, 'following': False, 'blocking': False, 'followsYou': False}, 'config': <lib.config.Configuration object at 0x000002A322481FD0>, 'challenge_queue': <ListProxy object, typeid 'list' at 0x2a322488610>, 'correspondence_queue': <AutoProxy[Queue] object, typeid 'Queue' at 0x2a322488850>, 'logging_queue': <AutoProxy[Queue] object, typeid 'Queue' at 0x2a322488a90>, 'game_id': 'uDhc2Mkh'}
2024-04-21 11:32:17,639 lib.lichess (lichess.py:65) DEBUG Exception: Traceback (most recent call last):
  File "C:\Users\Kyle_Remote\Documents\Programs\DS3ML3_Final_Project\.venv\Lib\site-packages\backoff\_sync.py", line 105, in retry
    ret = target(*args, **kwargs)
          ^^^^^^^^^^^^^^^^^^^^^^^
  File "C:\Users\Kyle_Remote\Documents\Programs\DS3ML3_Final_Project\lichess-bot\lichess-bot.py", line 609, in play_game
    with engine_wrapper.create_engine(config, game) as engine:
         ^^^^^^^^^^^^^^^^^^^^^^^^^^^^^^^^^^^^^^^^^^
  File "C:\Users\Kyle_Remote\Documents\Programs\DS3ML3_Final_Project\lichess-bot\lib\engine_wrapper.py", line 63, in create_engine
    Engine = getHomemadeEngine(cfg.name)
             ^^^^^^^^^^^^^^^^^^^^^^^^^^^
  File "C:\Users\Kyle_Remote\Documents\Programs\DS3ML3_Final_Project\lichess-bot\lib\engine_wrapper.py", line 620, in getHomemadeEngine
    import homemade
  File "C:\Users\Kyle_Remote\Documents\Programs\DS3ML3_Final_Project\lichess-bot\homemade.py", line 27, in <module>
    model_loaded = torch.load('../models_EL/model_E7-2.pth', map_location=device)
                   ^^^^^^^^^^^^^^^^^^^^^^^^^^^^^^^^^^^^^^^^^^^^^^^^^^^^^^^^^^^^^^
  File "C:\Users\Kyle_Remote\Documents\Programs\DS3ML3_Final_Project\.venv\Lib\site-packages\torch\serialization.py", line 1026, in load
    return _load(opened_zipfile,
           ^^^^^^^^^^^^^^^^^^^^^
  File "C:\Users\Kyle_Remote\Documents\Programs\DS3ML3_Final_Project\.venv\Lib\site-packages\torch\serialization.py", line 1438, in _load
    result = unpickler.load()
             ^^^^^^^^^^^^^^^^
  File "C:\Users\Kyle_Remote\Documents\Programs\DS3ML3_Final_Project\.venv\Lib\site-packages\torch\serialization.py", line 1431, in find_class
    return super().find_class(mod_name, name)
           ^^^^^^^^^^^^^^^^^^^^^^^^^^^^^^^^^^
ModuleNotFoundError: No module named 'chess_SL_E5_lib'

2024-04-21 11:32:19,571 __main__ (lichess-bot.py:71) DEBUG Received SIGINT. Terminating client.
