2024-04-09 04:04:12,544 __main__ (lichess-bot.py:1051) INFO 
    .   _/|
    .  // o\
    .  || ._)  lichess-bot 2024.3.21.1
    .  //__\
    .  )___(   Play on Lichess with a bot
    
2024-04-09 04:04:12,571 lib.config (config.py:262) DEBUG Config:
token: logger
url: https://lichess.org/
engine:
  dir: ./engines/
  name: ExampleEngine
  working_dir: ''
  protocol: homemade
  ponder: true
  polyglot:
    enabled: false
    book:
      standard:
      - engines/book1.bin
      - engines/book2.bin
    min_weight: 1
    selection: weighted_random
    max_depth: 20
  draw_or_resign:
    resign_enabled: false
    resign_score: -1000
    resign_for_egtb_minus_two: true
    resign_moves: 3
    offer_draw_enabled: true
    offer_draw_score: 0
    offer_draw_for_egtb_zero: true
    offer_draw_moves: 10
    offer_draw_pieces: 10
  online_moves:
    max_out_of_book_moves: 10
    max_retries: 2
    chessdb_book:
      enabled: false
      min_time: 20
      move_quality: good
      min_depth: 20
    lichess_cloud_analysis:
      enabled: false
      min_time: 20
      move_quality: best
      max_score_difference: 50
      min_depth: 20
      min_knodes: 0
    lichess_opening_explorer:
      enabled: false
      min_time: 20
      source: masters
      player_name: ''
      sort: winrate
      min_games: 10
    online_egtb:
      enabled: false
      min_time: 20
      max_pieces: 7
      source: lichess
      move_quality: best
  lichess_bot_tbs:
    syzygy:
      enabled: false
      paths:
      - engines/syzygy
      max_pieces: 7
      move_quality: best
    gaviota:
      enabled: false
      paths:
      - engines/gaviota
      max_pieces: 5
      min_dtm_to_consider_as_wdl_1: 120
      move_quality: best
  homemade_options: null
  uci_options:
    Move Overhead: 100
    Threads: 4
    Hash: 512
    SyzygyPath: ./syzygy/
    UCI_ShowWDL: true
  silence_stderr: false
abort_time: 30
fake_think_time: false
rate_limiting_delay: 0
move_overhead: 2000
quit_after_all_games_finish: false
correspondence:
  move_time: 60
  checkin_period: 300
  disconnect_time: 150
  ponder: false
challenge:
  concurrency: 5
  sort_by: first
  accept_bot: true
  only_bot: false
  max_increment: 20
  min_increment: 0
  max_base: 1800
  min_base: 0
  max_days: 14
  min_days: 1
  variants:
  - standard
  time_controls:
  - bullet
  - blitz
  - rapid
  - classical
  modes:
  - casual
  - rated
  bullet_requires_increment: false
greeting:
  hello: Hi! I'm {me}. Good luck! Type !help for a list of commands I can respond
    to.
  goodbye: Good game!
  hello_spectators: Hi! I'm {me}. Type !help for a list of commands I can respond
    to.
  goodbye_spectators: Thanks for watching!
matchmaking:
  allow_matchmaking: false
  allow_during_games: false
  challenge_variant: random
  challenge_timeout: 30
  challenge_initial_time:
  - 60
  - 180
  challenge_increment:
  - 1
  - 2
  rating_preference: none
  opponent_allow_tos_violation: false
  challenge_mode: random
  challenge_filter: none

2024-04-09 04:04:12,571 lib.config (config.py:263) DEBUG ====================
2024-04-09 04:04:12,574 lib.config (config.py:262) DEBUG Config:
token: logger
url: https://lichess.org/
engine:
  dir: ./engines/
  name: ExampleEngine
  working_dir: C:\Users\Kyle_Remote\Documents\Programs\DS3ML3_Final_Project\lichess-bot
  protocol: homemade
  ponder: true
  polyglot:
    enabled: false
    book:
      standard:
      - engines/book1.bin
      - engines/book2.bin
    min_weight: 1
    selection: weighted_random
    max_depth: 20
  draw_or_resign:
    resign_enabled: false
    resign_score: -1000
    resign_for_egtb_minus_two: true
    resign_moves: 3
    offer_draw_enabled: true
    offer_draw_score: 0
    offer_draw_for_egtb_zero: true
    offer_draw_moves: 10
    offer_draw_pieces: 10
  online_moves:
    max_out_of_book_moves: 10
    max_retries: 2
    chessdb_book:
      enabled: false
      min_time: 20
      move_quality: good
      min_depth: 20
    lichess_cloud_analysis:
      enabled: false
      min_time: 20
      move_quality: best
      max_score_difference: 50
      min_depth: 20
      min_knodes: 0
    lichess_opening_explorer:
      enabled: false
      min_time: 20
      source: masters
      player_name: ''
      sort: winrate
      min_games: 10
    online_egtb:
      enabled: false
      min_time: 20
      max_pieces: 7
      source: lichess
      move_quality: best
    max_depth: .inf
  lichess_bot_tbs:
    syzygy:
      enabled: false
      paths:
      - engines/syzygy
      max_pieces: 7
      move_quality: best
    gaviota:
      enabled: false
      paths:
      - engines/gaviota
      max_pieces: 5
      min_dtm_to_consider_as_wdl_1: 120
      move_quality: best
  homemade_options: null
  uci_options:
    Move Overhead: 100
    Threads: 4
    Hash: 512
    SyzygyPath: ./syzygy/
    UCI_ShowWDL: true
  silence_stderr: false
  uci_ponder: false
abort_time: 30
fake_think_time: false
rate_limiting_delay: 0
move_overhead: 2000
quit_after_all_games_finish: false
correspondence:
  move_time: 60
  checkin_period: 300
  disconnect_time: 150
  ponder: false
  uci_ponder: false
challenge:
  concurrency: 5
  sort_by: first
  accept_bot: true
  only_bot: false
  max_increment: 20
  min_increment: 0
  max_base: 1800
  min_base: 0
  max_days: 14
  min_days: 1
  variants:
  - standard
  time_controls:
  - bullet
  - blitz
  - rapid
  - classical
  modes:
  - casual
  - rated
  bullet_requires_increment: false
  block_list: []
  allow_list: []
greeting:
  hello: Hi! I'm {me}. Good luck! Type !help for a list of commands I can respond
    to.
  goodbye: Good game!
  hello_spectators: Hi! I'm {me}. Type !help for a list of commands I can respond
    to.
  goodbye_spectators: Thanks for watching!
matchmaking:
  allow_matchmaking: false
  allow_during_games: false
  challenge_variant: random
  challenge_timeout: 30
  challenge_initial_time:
  - 60
  - 180
  challenge_increment:
  - 1
  - 2
  rating_preference: none
  opponent_allow_tos_violation: false
  challenge_mode: random
  challenge_filter: none
  block_list: []
  challenge_days:
  - null
  opponent_min_rating: 600
  opponent_max_rating: 4000
  overrides: {}
pgn_file_grouping: game

2024-04-09 04:04:12,574 lib.config (config.py:263) DEBUG ====================
2024-04-09 04:04:12,575 __main__ (lichess-bot.py:1054) INFO Checking engine configuration ...
2024-04-09 04:04:12,578 lib.engine_wrapper (engine_wrapper.py:68) DEBUG Starting engine: ['C:\\Users\\Kyle_Remote\\Documents\\Programs\\DS3ML3_Final_Project\\lichess-bot\\engines\\ExampleEngine']
2024-04-09 04:04:12,578 __main__ (lichess-bot.py:1057) INFO Engine configuration OK
2024-04-09 04:04:12,582 urllib3.connectionpool (connectionpool.py:1055) DEBUG Starting new HTTPS connection (1): lichess.org:443
2024-04-09 04:04:14,934 urllib3.connectionpool (connectionpool.py:549) DEBUG https://lichess.org:443 "POST /api/token/test HTTP/1.1" 200 None
2024-04-09 04:04:16,947 lib.lichess (lichess.py:63) DEBUG Backing off 0.0 seconds after 1 tries calling function <function Lichess.api_get at 0x0000014D98F53880> with args (<lib.lichess.Lichess object at 0x0000014DBB209C90>, 'profile') and kwargs {'params': None}
2024-04-09 04:04:16,949 lib.lichess (lichess.py:65) DEBUG Exception: Traceback (most recent call last):
  File "C:\Users\Kyle_Remote\Documents\Programs\DS3ML3_Final_Project\.venv\Lib\site-packages\urllib3\connectionpool.py", line 537, in _make_request
    response = conn.getresponse()
               ^^^^^^^^^^^^^^^^^^
  File "C:\Users\Kyle_Remote\Documents\Programs\DS3ML3_Final_Project\.venv\Lib\site-packages\urllib3\connection.py", line 466, in getresponse
    httplib_response = super().getresponse()
                       ^^^^^^^^^^^^^^^^^^^^^
  File "C:\Users\Kyle_Remote\AppData\Local\Programs\Python\Python311\Lib\http\client.py", line 1378, in getresponse
    response.begin()
  File "C:\Users\Kyle_Remote\AppData\Local\Programs\Python\Python311\Lib\http\client.py", line 318, in begin
    version, status, reason = self._read_status()
                              ^^^^^^^^^^^^^^^^^^^
  File "C:\Users\Kyle_Remote\AppData\Local\Programs\Python\Python311\Lib\http\client.py", line 279, in _read_status
    line = str(self.fp.readline(_MAXLINE + 1), "iso-8859-1")
               ^^^^^^^^^^^^^^^^^^^^^^^^^^^^^^
  File "C:\Users\Kyle_Remote\AppData\Local\Programs\Python\Python311\Lib\socket.py", line 706, in readinto
    return self._sock.recv_into(b)
           ^^^^^^^^^^^^^^^^^^^^^^^
  File "C:\Users\Kyle_Remote\AppData\Local\Programs\Python\Python311\Lib\ssl.py", line 1311, in recv_into
    return self.read(nbytes, buffer)
           ^^^^^^^^^^^^^^^^^^^^^^^^^
  File "C:\Users\Kyle_Remote\AppData\Local\Programs\Python\Python311\Lib\ssl.py", line 1167, in read
    return self._sslobj.read(len, buffer)
           ^^^^^^^^^^^^^^^^^^^^^^^^^^^^^^
TimeoutError: The read operation timed out

The above exception was the direct cause of the following exception:

Traceback (most recent call last):
  File "C:\Users\Kyle_Remote\Documents\Programs\DS3ML3_Final_Project\.venv\Lib\site-packages\requests\adapters.py", line 486, in send
    resp = conn.urlopen(
           ^^^^^^^^^^^^^
  File "C:\Users\Kyle_Remote\Documents\Programs\DS3ML3_Final_Project\.venv\Lib\site-packages\urllib3\connectionpool.py", line 847, in urlopen
    retries = retries.increment(
              ^^^^^^^^^^^^^^^^^^
  File "C:\Users\Kyle_Remote\Documents\Programs\DS3ML3_Final_Project\.venv\Lib\site-packages\urllib3\util\retry.py", line 470, in increment
    raise reraise(type(error), error, _stacktrace)
          ^^^^^^^^^^^^^^^^^^^^^^^^^^^^^^^^^^^^^^^^
  File "C:\Users\Kyle_Remote\Documents\Programs\DS3ML3_Final_Project\.venv\Lib\site-packages\urllib3\util\util.py", line 39, in reraise
    raise value
  File "C:\Users\Kyle_Remote\Documents\Programs\DS3ML3_Final_Project\.venv\Lib\site-packages\urllib3\connectionpool.py", line 793, in urlopen
    response = self._make_request(
               ^^^^^^^^^^^^^^^^^^^
  File "C:\Users\Kyle_Remote\Documents\Programs\DS3ML3_Final_Project\.venv\Lib\site-packages\urllib3\connectionpool.py", line 539, in _make_request
    self._raise_timeout(err=e, url=url, timeout_value=read_timeout)
  File "C:\Users\Kyle_Remote\Documents\Programs\DS3ML3_Final_Project\.venv\Lib\site-packages\urllib3\connectionpool.py", line 370, in _raise_timeout
    raise ReadTimeoutError(
urllib3.exceptions.ReadTimeoutError: HTTPSConnectionPool(host='lichess.org', port=443): Read timed out. (read timeout=2)

During handling of the above exception, another exception occurred:

Traceback (most recent call last):
  File "C:\Users\Kyle_Remote\Documents\Programs\DS3ML3_Final_Project\.venv\Lib\site-packages\backoff\_sync.py", line 105, in retry
    ret = target(*args, **kwargs)
          ^^^^^^^^^^^^^^^^^^^^^^^
  File "C:\Users\Kyle_Remote\Documents\Programs\DS3ML3_Final_Project\lichess-bot\lib\lichess.py", line 132, in api_get
    response = self.session.get(url, params=params, timeout=timeout, stream=stream)
               ^^^^^^^^^^^^^^^^^^^^^^^^^^^^^^^^^^^^^^^^^^^^^^^^^^^^^^^^^^^^^^^^^^^^
  File "C:\Users\Kyle_Remote\Documents\Programs\DS3ML3_Final_Project\.venv\Lib\site-packages\requests\sessions.py", line 602, in get
    return self.request("GET", url, **kwargs)
           ^^^^^^^^^^^^^^^^^^^^^^^^^^^^^^^^^^
  File "C:\Users\Kyle_Remote\Documents\Programs\DS3ML3_Final_Project\.venv\Lib\site-packages\requests\sessions.py", line 589, in request
    resp = self.send(prep, **send_kwargs)
           ^^^^^^^^^^^^^^^^^^^^^^^^^^^^^^
  File "C:\Users\Kyle_Remote\Documents\Programs\DS3ML3_Final_Project\.venv\Lib\site-packages\requests\sessions.py", line 703, in send
    r = adapter.send(request, **kwargs)
        ^^^^^^^^^^^^^^^^^^^^^^^^^^^^^^^
  File "C:\Users\Kyle_Remote\Documents\Programs\DS3ML3_Final_Project\.venv\Lib\site-packages\requests\adapters.py", line 532, in send
    raise ReadTimeout(e, request=request)
requests.exceptions.ReadTimeout: HTTPSConnectionPool(host='lichess.org', port=443): Read timed out. (read timeout=2)

2024-04-09 04:04:16,952 urllib3.connectionpool (connectionpool.py:1055) DEBUG Starting new HTTPS connection (2): lichess.org:443
2024-04-09 04:04:19,437 lib.lichess (lichess.py:63) DEBUG Backing off 0.0 seconds after 2 tries calling function <function Lichess.api_get at 0x0000014D98F53880> with args (<lib.lichess.Lichess object at 0x0000014DBB209C90>, 'profile') and kwargs {'params': None}
2024-04-09 04:04:19,438 lib.lichess (lichess.py:65) DEBUG Exception: Traceback (most recent call last):
  File "C:\Users\Kyle_Remote\Documents\Programs\DS3ML3_Final_Project\.venv\Lib\site-packages\urllib3\connectionpool.py", line 537, in _make_request
    response = conn.getresponse()
               ^^^^^^^^^^^^^^^^^^
  File "C:\Users\Kyle_Remote\Documents\Programs\DS3ML3_Final_Project\.venv\Lib\site-packages\urllib3\connection.py", line 466, in getresponse
    httplib_response = super().getresponse()
                       ^^^^^^^^^^^^^^^^^^^^^
  File "C:\Users\Kyle_Remote\AppData\Local\Programs\Python\Python311\Lib\http\client.py", line 1378, in getresponse
    response.begin()
  File "C:\Users\Kyle_Remote\AppData\Local\Programs\Python\Python311\Lib\http\client.py", line 318, in begin
    version, status, reason = self._read_status()
                              ^^^^^^^^^^^^^^^^^^^
  File "C:\Users\Kyle_Remote\AppData\Local\Programs\Python\Python311\Lib\http\client.py", line 279, in _read_status
    line = str(self.fp.readline(_MAXLINE + 1), "iso-8859-1")
               ^^^^^^^^^^^^^^^^^^^^^^^^^^^^^^
  File "C:\Users\Kyle_Remote\AppData\Local\Programs\Python\Python311\Lib\socket.py", line 706, in readinto
    return self._sock.recv_into(b)
           ^^^^^^^^^^^^^^^^^^^^^^^
  File "C:\Users\Kyle_Remote\AppData\Local\Programs\Python\Python311\Lib\ssl.py", line 1311, in recv_into
    return self.read(nbytes, buffer)
           ^^^^^^^^^^^^^^^^^^^^^^^^^
  File "C:\Users\Kyle_Remote\AppData\Local\Programs\Python\Python311\Lib\ssl.py", line 1167, in read
    return self._sslobj.read(len, buffer)
           ^^^^^^^^^^^^^^^^^^^^^^^^^^^^^^
TimeoutError: The read operation timed out

The above exception was the direct cause of the following exception:

Traceback (most recent call last):
  File "C:\Users\Kyle_Remote\Documents\Programs\DS3ML3_Final_Project\.venv\Lib\site-packages\requests\adapters.py", line 486, in send
    resp = conn.urlopen(
           ^^^^^^^^^^^^^
  File "C:\Users\Kyle_Remote\Documents\Programs\DS3ML3_Final_Project\.venv\Lib\site-packages\urllib3\connectionpool.py", line 847, in urlopen
    retries = retries.increment(
              ^^^^^^^^^^^^^^^^^^
  File "C:\Users\Kyle_Remote\Documents\Programs\DS3ML3_Final_Project\.venv\Lib\site-packages\urllib3\util\retry.py", line 470, in increment
    raise reraise(type(error), error, _stacktrace)
          ^^^^^^^^^^^^^^^^^^^^^^^^^^^^^^^^^^^^^^^^
  File "C:\Users\Kyle_Remote\Documents\Programs\DS3ML3_Final_Project\.venv\Lib\site-packages\urllib3\util\util.py", line 39, in reraise
    raise value
  File "C:\Users\Kyle_Remote\Documents\Programs\DS3ML3_Final_Project\.venv\Lib\site-packages\urllib3\connectionpool.py", line 793, in urlopen
    response = self._make_request(
               ^^^^^^^^^^^^^^^^^^^
  File "C:\Users\Kyle_Remote\Documents\Programs\DS3ML3_Final_Project\.venv\Lib\site-packages\urllib3\connectionpool.py", line 539, in _make_request
    self._raise_timeout(err=e, url=url, timeout_value=read_timeout)
  File "C:\Users\Kyle_Remote\Documents\Programs\DS3ML3_Final_Project\.venv\Lib\site-packages\urllib3\connectionpool.py", line 370, in _raise_timeout
    raise ReadTimeoutError(
urllib3.exceptions.ReadTimeoutError: HTTPSConnectionPool(host='lichess.org', port=443): Read timed out. (read timeout=2)

During handling of the above exception, another exception occurred:

Traceback (most recent call last):
  File "C:\Users\Kyle_Remote\Documents\Programs\DS3ML3_Final_Project\.venv\Lib\site-packages\backoff\_sync.py", line 105, in retry
    ret = target(*args, **kwargs)
          ^^^^^^^^^^^^^^^^^^^^^^^
  File "C:\Users\Kyle_Remote\Documents\Programs\DS3ML3_Final_Project\lichess-bot\lib\lichess.py", line 132, in api_get
    response = self.session.get(url, params=params, timeout=timeout, stream=stream)
               ^^^^^^^^^^^^^^^^^^^^^^^^^^^^^^^^^^^^^^^^^^^^^^^^^^^^^^^^^^^^^^^^^^^^
  File "C:\Users\Kyle_Remote\Documents\Programs\DS3ML3_Final_Project\.venv\Lib\site-packages\requests\sessions.py", line 602, in get
    return self.request("GET", url, **kwargs)
           ^^^^^^^^^^^^^^^^^^^^^^^^^^^^^^^^^^
  File "C:\Users\Kyle_Remote\Documents\Programs\DS3ML3_Final_Project\.venv\Lib\site-packages\requests\sessions.py", line 589, in request
    resp = self.send(prep, **send_kwargs)
           ^^^^^^^^^^^^^^^^^^^^^^^^^^^^^^
  File "C:\Users\Kyle_Remote\Documents\Programs\DS3ML3_Final_Project\.venv\Lib\site-packages\requests\sessions.py", line 703, in send
    r = adapter.send(request, **kwargs)
        ^^^^^^^^^^^^^^^^^^^^^^^^^^^^^^^
  File "C:\Users\Kyle_Remote\Documents\Programs\DS3ML3_Final_Project\.venv\Lib\site-packages\requests\adapters.py", line 532, in send
    raise ReadTimeout(e, request=request)
requests.exceptions.ReadTimeout: HTTPSConnectionPool(host='lichess.org', port=443): Read timed out. (read timeout=2)

2024-04-09 04:04:19,487 urllib3.connectionpool (connectionpool.py:1055) DEBUG Starting new HTTPS connection (3): lichess.org:443
2024-04-09 04:04:21,958 lib.lichess (lichess.py:63) DEBUG Backing off 0.0 seconds after 3 tries calling function <function Lichess.api_get at 0x0000014D98F53880> with args (<lib.lichess.Lichess object at 0x0000014DBB209C90>, 'profile') and kwargs {'params': None}
2024-04-09 04:04:21,960 lib.lichess (lichess.py:65) DEBUG Exception: Traceback (most recent call last):
  File "C:\Users\Kyle_Remote\Documents\Programs\DS3ML3_Final_Project\.venv\Lib\site-packages\urllib3\connectionpool.py", line 537, in _make_request
    response = conn.getresponse()
               ^^^^^^^^^^^^^^^^^^
  File "C:\Users\Kyle_Remote\Documents\Programs\DS3ML3_Final_Project\.venv\Lib\site-packages\urllib3\connection.py", line 466, in getresponse
    httplib_response = super().getresponse()
                       ^^^^^^^^^^^^^^^^^^^^^
  File "C:\Users\Kyle_Remote\AppData\Local\Programs\Python\Python311\Lib\http\client.py", line 1378, in getresponse
    response.begin()
  File "C:\Users\Kyle_Remote\AppData\Local\Programs\Python\Python311\Lib\http\client.py", line 318, in begin
    version, status, reason = self._read_status()
                              ^^^^^^^^^^^^^^^^^^^
  File "C:\Users\Kyle_Remote\AppData\Local\Programs\Python\Python311\Lib\http\client.py", line 279, in _read_status
    line = str(self.fp.readline(_MAXLINE + 1), "iso-8859-1")
               ^^^^^^^^^^^^^^^^^^^^^^^^^^^^^^
  File "C:\Users\Kyle_Remote\AppData\Local\Programs\Python\Python311\Lib\socket.py", line 706, in readinto
    return self._sock.recv_into(b)
           ^^^^^^^^^^^^^^^^^^^^^^^
  File "C:\Users\Kyle_Remote\AppData\Local\Programs\Python\Python311\Lib\ssl.py", line 1311, in recv_into
    return self.read(nbytes, buffer)
           ^^^^^^^^^^^^^^^^^^^^^^^^^
  File "C:\Users\Kyle_Remote\AppData\Local\Programs\Python\Python311\Lib\ssl.py", line 1167, in read
    return self._sslobj.read(len, buffer)
           ^^^^^^^^^^^^^^^^^^^^^^^^^^^^^^
TimeoutError: The read operation timed out

The above exception was the direct cause of the following exception:

Traceback (most recent call last):
  File "C:\Users\Kyle_Remote\Documents\Programs\DS3ML3_Final_Project\.venv\Lib\site-packages\requests\adapters.py", line 486, in send
    resp = conn.urlopen(
           ^^^^^^^^^^^^^
  File "C:\Users\Kyle_Remote\Documents\Programs\DS3ML3_Final_Project\.venv\Lib\site-packages\urllib3\connectionpool.py", line 847, in urlopen
    retries = retries.increment(
              ^^^^^^^^^^^^^^^^^^
  File "C:\Users\Kyle_Remote\Documents\Programs\DS3ML3_Final_Project\.venv\Lib\site-packages\urllib3\util\retry.py", line 470, in increment
    raise reraise(type(error), error, _stacktrace)
          ^^^^^^^^^^^^^^^^^^^^^^^^^^^^^^^^^^^^^^^^
  File "C:\Users\Kyle_Remote\Documents\Programs\DS3ML3_Final_Project\.venv\Lib\site-packages\urllib3\util\util.py", line 39, in reraise
    raise value
  File "C:\Users\Kyle_Remote\Documents\Programs\DS3ML3_Final_Project\.venv\Lib\site-packages\urllib3\connectionpool.py", line 793, in urlopen
    response = self._make_request(
               ^^^^^^^^^^^^^^^^^^^
  File "C:\Users\Kyle_Remote\Documents\Programs\DS3ML3_Final_Project\.venv\Lib\site-packages\urllib3\connectionpool.py", line 539, in _make_request
    self._raise_timeout(err=e, url=url, timeout_value=read_timeout)
  File "C:\Users\Kyle_Remote\Documents\Programs\DS3ML3_Final_Project\.venv\Lib\site-packages\urllib3\connectionpool.py", line 370, in _raise_timeout
    raise ReadTimeoutError(
urllib3.exceptions.ReadTimeoutError: HTTPSConnectionPool(host='lichess.org', port=443): Read timed out. (read timeout=2)

During handling of the above exception, another exception occurred:

Traceback (most recent call last):
  File "C:\Users\Kyle_Remote\Documents\Programs\DS3ML3_Final_Project\.venv\Lib\site-packages\backoff\_sync.py", line 105, in retry
    ret = target(*args, **kwargs)
          ^^^^^^^^^^^^^^^^^^^^^^^
  File "C:\Users\Kyle_Remote\Documents\Programs\DS3ML3_Final_Project\lichess-bot\lib\lichess.py", line 132, in api_get
    response = self.session.get(url, params=params, timeout=timeout, stream=stream)
               ^^^^^^^^^^^^^^^^^^^^^^^^^^^^^^^^^^^^^^^^^^^^^^^^^^^^^^^^^^^^^^^^^^^^
  File "C:\Users\Kyle_Remote\Documents\Programs\DS3ML3_Final_Project\.venv\Lib\site-packages\requests\sessions.py", line 602, in get
    return self.request("GET", url, **kwargs)
           ^^^^^^^^^^^^^^^^^^^^^^^^^^^^^^^^^^
  File "C:\Users\Kyle_Remote\Documents\Programs\DS3ML3_Final_Project\.venv\Lib\site-packages\requests\sessions.py", line 589, in request
    resp = self.send(prep, **send_kwargs)
           ^^^^^^^^^^^^^^^^^^^^^^^^^^^^^^
  File "C:\Users\Kyle_Remote\Documents\Programs\DS3ML3_Final_Project\.venv\Lib\site-packages\requests\sessions.py", line 703, in send
    r = adapter.send(request, **kwargs)
        ^^^^^^^^^^^^^^^^^^^^^^^^^^^^^^^
  File "C:\Users\Kyle_Remote\Documents\Programs\DS3ML3_Final_Project\.venv\Lib\site-packages\requests\adapters.py", line 532, in send
    raise ReadTimeout(e, request=request)
requests.exceptions.ReadTimeout: HTTPSConnectionPool(host='lichess.org', port=443): Read timed out. (read timeout=2)

2024-04-09 04:04:21,997 urllib3.connectionpool (connectionpool.py:1055) DEBUG Starting new HTTPS connection (4): lichess.org:443
2024-04-09 04:04:23,506 urllib3.connectionpool (connectionpool.py:549) DEBUG https://lichess.org:443 "GET /api/account HTTP/1.1" 200 None
2024-04-09 04:04:23,506 __main__ (lichess-bot.py:1066) INFO Welcome KS_ChessAI!
2024-04-09 04:04:23,509 __main__ (lichess-bot.py:225) INFO You're now connected to https://lichess.org/ and awaiting challenges.
